[23-01-26 17:47:16] [gateway.py WARNING] Can't keep up, shard ID None websocket is 10.5s behind.
[23-01-26 19:31:38] [client.py ERROR] Attempting a reconnect in 2.00s
Traceback (most recent call last):
  File "C:\Users\Михаил\PycharmProjects\football_discordBot\venv\lib\site-packages\aiohttp\connector.py", line 1152, in _create_direct_connection
    hosts = await asyncio.shield(host_resolved)
  File "C:\Users\Михаил\PycharmProjects\football_discordBot\venv\lib\site-packages\aiohttp\connector.py", line 874, in _resolve_host
    addrs = await self._resolver.resolve(host, port, family=self._family)
  File "C:\Users\Михаил\PycharmProjects\football_discordBot\venv\lib\site-packages\aiohttp\resolver.py", line 33, in resolve
    infos = await self._loop.getaddrinfo(
  File "C:\Users\Михаил\AppData\Local\Programs\Python\Python310\lib\asyncio\base_events.py", line 860, in getaddrinfo
    return await self.run_in_executor(
  File "C:\Users\Михаил\AppData\Local\Programs\Python\Python310\lib\concurrent\futures\thread.py", line 58, in run
    result = self.fn(*self.args, **self.kwargs)
  File "C:\Users\Михаил\AppData\Local\Programs\Python\Python310\lib\socket.py", line 955, in getaddrinfo
    for res in _socket.getaddrinfo(host, port, family, type, proto, flags):
socket.gaierror: [Errno 11004] getaddrinfo failed

The above exception was the direct cause of the following exception:

Traceback (most recent call last):
  File "C:\Users\Михаил\PycharmProjects\football_discordBot\venv\lib\site-packages\nextcord\client.py", line 708, in connect
    self.ws = await asyncio.wait_for(coro, timeout=60.0)
  File "C:\Users\Михаил\AppData\Local\Programs\Python\Python310\lib\asyncio\tasks.py", line 445, in wait_for
    return fut.result()
  File "C:\Users\Михаил\PycharmProjects\football_discordBot\venv\lib\site-packages\nextcord\gateway.py", line 365, in from_client
    socket = await client.http.ws_connect(gateway)
  File "C:\Users\Михаил\PycharmProjects\football_discordBot\venv\lib\site-packages\nextcord\http.py", line 250, in ws_connect
    return await self.__session.ws_connect(url, **kwargs)
  File "C:\Users\Михаил\PycharmProjects\football_discordBot\venv\lib\site-packages\aiohttp\client.py", line 779, in _ws_connect
    resp = await self.request(
  File "C:\Users\Михаил\PycharmProjects\football_discordBot\venv\lib\site-packages\aiohttp\client.py", line 536, in _request
    conn = await self._connector.connect(
  File "C:\Users\Михаил\PycharmProjects\football_discordBot\venv\lib\site-packages\aiohttp\connector.py", line 540, in connect
    proto = await self._create_connection(req, traces, timeout)
  File "C:\Users\Михаил\PycharmProjects\football_discordBot\venv\lib\site-packages\aiohttp\connector.py", line 901, in _create_connection
    _, proto = await self._create_direct_connection(req, traces, timeout)
  File "C:\Users\Михаил\PycharmProjects\football_discordBot\venv\lib\site-packages\aiohttp\connector.py", line 1166, in _create_direct_connection
    raise ClientConnectorError(req.connection_key, exc) from exc
aiohttp.client_exceptions.ClientConnectorError: Cannot connect to host gateway-us-east1-b.discord.gg:443 ssl:default [getaddrinfo failed]
[23-01-26 19:31:40] [client.py ERROR] Attempting a reconnect in 2.84s
Traceback (most recent call last):
  File "C:\Users\Михаил\PycharmProjects\football_discordBot\venv\lib\site-packages\aiohttp\connector.py", line 1152, in _create_direct_connection
    hosts = await asyncio.shield(host_resolved)
  File "C:\Users\Михаил\PycharmProjects\football_discordBot\venv\lib\site-packages\aiohttp\connector.py", line 874, in _resolve_host
    addrs = await self._resolver.resolve(host, port, family=self._family)
  File "C:\Users\Михаил\PycharmProjects\football_discordBot\venv\lib\site-packages\aiohttp\resolver.py", line 33, in resolve
    infos = await self._loop.getaddrinfo(
  File "C:\Users\Михаил\AppData\Local\Programs\Python\Python310\lib\asyncio\base_events.py", line 860, in getaddrinfo
    return await self.run_in_executor(
  File "C:\Users\Михаил\AppData\Local\Programs\Python\Python310\lib\concurrent\futures\thread.py", line 58, in run
    result = self.fn(*self.args, **self.kwargs)
  File "C:\Users\Михаил\AppData\Local\Programs\Python\Python310\lib\socket.py", line 955, in getaddrinfo
    for res in _socket.getaddrinfo(host, port, family, type, proto, flags):
socket.gaierror: [Errno 11004] getaddrinfo failed

The above exception was the direct cause of the following exception:

Traceback (most recent call last):
  File "C:\Users\Михаил\PycharmProjects\football_discordBot\venv\lib\site-packages\nextcord\client.py", line 708, in connect
    self.ws = await asyncio.wait_for(coro, timeout=60.0)
  File "C:\Users\Михаил\AppData\Local\Programs\Python\Python310\lib\asyncio\tasks.py", line 445, in wait_for
    return fut.result()
  File "C:\Users\Михаил\PycharmProjects\football_discordBot\venv\lib\site-packages\nextcord\gateway.py", line 365, in from_client
    socket = await client.http.ws_connect(gateway)
  File "C:\Users\Михаил\PycharmProjects\football_discordBot\venv\lib\site-packages\nextcord\http.py", line 250, in ws_connect
    return await self.__session.ws_connect(url, **kwargs)
  File "C:\Users\Михаил\PycharmProjects\football_discordBot\venv\lib\site-packages\aiohttp\client.py", line 779, in _ws_connect
    resp = await self.request(
  File "C:\Users\Михаил\PycharmProjects\football_discordBot\venv\lib\site-packages\aiohttp\client.py", line 536, in _request
    conn = await self._connector.connect(
  File "C:\Users\Михаил\PycharmProjects\football_discordBot\venv\lib\site-packages\aiohttp\connector.py", line 540, in connect
    proto = await self._create_connection(req, traces, timeout)
  File "C:\Users\Михаил\PycharmProjects\football_discordBot\venv\lib\site-packages\aiohttp\connector.py", line 901, in _create_connection
    _, proto = await self._create_direct_connection(req, traces, timeout)
  File "C:\Users\Михаил\PycharmProjects\football_discordBot\venv\lib\site-packages\aiohttp\connector.py", line 1166, in _create_direct_connection
    raise ClientConnectorError(req.connection_key, exc) from exc
aiohttp.client_exceptions.ClientConnectorError: Cannot connect to host gateway-us-east1-b.discord.gg:443 ssl:default [getaddrinfo failed]
[23-01-26 19:31:43] [client.py ERROR] Attempting a reconnect in 6.55s
Traceback (most recent call last):
  File "C:\Users\Михаил\PycharmProjects\football_discordBot\venv\lib\site-packages\aiohttp\connector.py", line 1152, in _create_direct_connection
    hosts = await asyncio.shield(host_resolved)
  File "C:\Users\Михаил\PycharmProjects\football_discordBot\venv\lib\site-packages\aiohttp\connector.py", line 874, in _resolve_host
    addrs = await self._resolver.resolve(host, port, family=self._family)
  File "C:\Users\Михаил\PycharmProjects\football_discordBot\venv\lib\site-packages\aiohttp\resolver.py", line 33, in resolve
    infos = await self._loop.getaddrinfo(
  File "C:\Users\Михаил\AppData\Local\Programs\Python\Python310\lib\asyncio\base_events.py", line 860, in getaddrinfo
    return await self.run_in_executor(
  File "C:\Users\Михаил\AppData\Local\Programs\Python\Python310\lib\concurrent\futures\thread.py", line 58, in run
    result = self.fn(*self.args, **self.kwargs)
  File "C:\Users\Михаил\AppData\Local\Programs\Python\Python310\lib\socket.py", line 955, in getaddrinfo
    for res in _socket.getaddrinfo(host, port, family, type, proto, flags):
socket.gaierror: [Errno 11004] getaddrinfo failed

The above exception was the direct cause of the following exception:

Traceback (most recent call last):
  File "C:\Users\Михаил\PycharmProjects\football_discordBot\venv\lib\site-packages\nextcord\client.py", line 708, in connect
    self.ws = await asyncio.wait_for(coro, timeout=60.0)
  File "C:\Users\Михаил\AppData\Local\Programs\Python\Python310\lib\asyncio\tasks.py", line 445, in wait_for
    return fut.result()
  File "C:\Users\Михаил\PycharmProjects\football_discordBot\venv\lib\site-packages\nextcord\gateway.py", line 365, in from_client
    socket = await client.http.ws_connect(gateway)
  File "C:\Users\Михаил\PycharmProjects\football_discordBot\venv\lib\site-packages\nextcord\http.py", line 250, in ws_connect
    return await self.__session.ws_connect(url, **kwargs)
  File "C:\Users\Михаил\PycharmProjects\football_discordBot\venv\lib\site-packages\aiohttp\client.py", line 779, in _ws_connect
    resp = await self.request(
  File "C:\Users\Михаил\PycharmProjects\football_discordBot\venv\lib\site-packages\aiohttp\client.py", line 536, in _request
    conn = await self._connector.connect(
  File "C:\Users\Михаил\PycharmProjects\football_discordBot\venv\lib\site-packages\aiohttp\connector.py", line 540, in connect
    proto = await self._create_connection(req, traces, timeout)
  File "C:\Users\Михаил\PycharmProjects\football_discordBot\venv\lib\site-packages\aiohttp\connector.py", line 901, in _create_connection
    _, proto = await self._create_direct_connection(req, traces, timeout)
  File "C:\Users\Михаил\PycharmProjects\football_discordBot\venv\lib\site-packages\aiohttp\connector.py", line 1166, in _create_direct_connection
    raise ClientConnectorError(req.connection_key, exc) from exc
aiohttp.client_exceptions.ClientConnectorError: Cannot connect to host gateway-us-east1-b.discord.gg:443 ssl:default [getaddrinfo failed]
[23-01-26 19:31:49] [client.py ERROR] Attempting a reconnect in 8.01s
Traceback (most recent call last):
  File "C:\Users\Михаил\PycharmProjects\football_discordBot\venv\lib\site-packages\aiohttp\connector.py", line 1152, in _create_direct_connection
    hosts = await asyncio.shield(host_resolved)
  File "C:\Users\Михаил\PycharmProjects\football_discordBot\venv\lib\site-packages\aiohttp\connector.py", line 874, in _resolve_host
    addrs = await self._resolver.resolve(host, port, family=self._family)
  File "C:\Users\Михаил\PycharmProjects\football_discordBot\venv\lib\site-packages\aiohttp\resolver.py", line 33, in resolve
    infos = await self._loop.getaddrinfo(
  File "C:\Users\Михаил\AppData\Local\Programs\Python\Python310\lib\asyncio\base_events.py", line 860, in getaddrinfo
    return await self.run_in_executor(
  File "C:\Users\Михаил\AppData\Local\Programs\Python\Python310\lib\concurrent\futures\thread.py", line 58, in run
    result = self.fn(*self.args, **self.kwargs)
  File "C:\Users\Михаил\AppData\Local\Programs\Python\Python310\lib\socket.py", line 955, in getaddrinfo
    for res in _socket.getaddrinfo(host, port, family, type, proto, flags):
socket.gaierror: [Errno 11004] getaddrinfo failed

The above exception was the direct cause of the following exception:

Traceback (most recent call last):
  File "C:\Users\Михаил\PycharmProjects\football_discordBot\venv\lib\site-packages\nextcord\client.py", line 708, in connect
    self.ws = await asyncio.wait_for(coro, timeout=60.0)
  File "C:\Users\Михаил\AppData\Local\Programs\Python\Python310\lib\asyncio\tasks.py", line 445, in wait_for
    return fut.result()
  File "C:\Users\Михаил\PycharmProjects\football_discordBot\venv\lib\site-packages\nextcord\gateway.py", line 365, in from_client
    socket = await client.http.ws_connect(gateway)
  File "C:\Users\Михаил\PycharmProjects\football_discordBot\venv\lib\site-packages\nextcord\http.py", line 250, in ws_connect
    return await self.__session.ws_connect(url, **kwargs)
  File "C:\Users\Михаил\PycharmProjects\football_discordBot\venv\lib\site-packages\aiohttp\client.py", line 779, in _ws_connect
    resp = await self.request(
  File "C:\Users\Михаил\PycharmProjects\football_discordBot\venv\lib\site-packages\aiohttp\client.py", line 536, in _request
    conn = await self._connector.connect(
  File "C:\Users\Михаил\PycharmProjects\football_discordBot\venv\lib\site-packages\aiohttp\connector.py", line 540, in connect
    proto = await self._create_connection(req, traces, timeout)
  File "C:\Users\Михаил\PycharmProjects\football_discordBot\venv\lib\site-packages\aiohttp\connector.py", line 901, in _create_connection
    _, proto = await self._create_direct_connection(req, traces, timeout)
  File "C:\Users\Михаил\PycharmProjects\football_discordBot\venv\lib\site-packages\aiohttp\connector.py", line 1166, in _create_direct_connection
    raise ClientConnectorError(req.connection_key, exc) from exc
aiohttp.client_exceptions.ClientConnectorError: Cannot connect to host gateway-us-east1-b.discord.gg:443 ssl:default [getaddrinfo failed]
[23-01-26 19:31:57] [client.py ERROR] Attempting a reconnect in 7.43s
Traceback (most recent call last):
  File "C:\Users\Михаил\PycharmProjects\football_discordBot\venv\lib\site-packages\aiohttp\connector.py", line 1152, in _create_direct_connection
    hosts = await asyncio.shield(host_resolved)
  File "C:\Users\Михаил\PycharmProjects\football_discordBot\venv\lib\site-packages\aiohttp\connector.py", line 874, in _resolve_host
    addrs = await self._resolver.resolve(host, port, family=self._family)
  File "C:\Users\Михаил\PycharmProjects\football_discordBot\venv\lib\site-packages\aiohttp\resolver.py", line 33, in resolve
    infos = await self._loop.getaddrinfo(
  File "C:\Users\Михаил\AppData\Local\Programs\Python\Python310\lib\asyncio\base_events.py", line 860, in getaddrinfo
    return await self.run_in_executor(
  File "C:\Users\Михаил\AppData\Local\Programs\Python\Python310\lib\concurrent\futures\thread.py", line 58, in run
    result = self.fn(*self.args, **self.kwargs)
  File "C:\Users\Михаил\AppData\Local\Programs\Python\Python310\lib\socket.py", line 955, in getaddrinfo
    for res in _socket.getaddrinfo(host, port, family, type, proto, flags):
socket.gaierror: [Errno 11004] getaddrinfo failed

The above exception was the direct cause of the following exception:

Traceback (most recent call last):
  File "C:\Users\Михаил\PycharmProjects\football_discordBot\venv\lib\site-packages\nextcord\client.py", line 708, in connect
    self.ws = await asyncio.wait_for(coro, timeout=60.0)
  File "C:\Users\Михаил\AppData\Local\Programs\Python\Python310\lib\asyncio\tasks.py", line 445, in wait_for
    return fut.result()
  File "C:\Users\Михаил\PycharmProjects\football_discordBot\venv\lib\site-packages\nextcord\gateway.py", line 365, in from_client
    socket = await client.http.ws_connect(gateway)
  File "C:\Users\Михаил\PycharmProjects\football_discordBot\venv\lib\site-packages\nextcord\http.py", line 250, in ws_connect
    return await self.__session.ws_connect(url, **kwargs)
  File "C:\Users\Михаил\PycharmProjects\football_discordBot\venv\lib\site-packages\aiohttp\client.py", line 779, in _ws_connect
    resp = await self.request(
  File "C:\Users\Михаил\PycharmProjects\football_discordBot\venv\lib\site-packages\aiohttp\client.py", line 536, in _request
    conn = await self._connector.connect(
  File "C:\Users\Михаил\PycharmProjects\football_discordBot\venv\lib\site-packages\aiohttp\connector.py", line 540, in connect
    proto = await self._create_connection(req, traces, timeout)
  File "C:\Users\Михаил\PycharmProjects\football_discordBot\venv\lib\site-packages\aiohttp\connector.py", line 901, in _create_connection
    _, proto = await self._create_direct_connection(req, traces, timeout)
  File "C:\Users\Михаил\PycharmProjects\football_discordBot\venv\lib\site-packages\aiohttp\connector.py", line 1166, in _create_direct_connection
    raise ClientConnectorError(req.connection_key, exc) from exc
aiohttp.client_exceptions.ClientConnectorError: Cannot connect to host gateway-us-east1-b.discord.gg:443 ssl:default [getaddrinfo failed]
[23-01-26 19:32:05] [client.py ERROR] Attempting a reconnect in 9.15s
Traceback (most recent call last):
  File "C:\Users\Михаил\PycharmProjects\football_discordBot\venv\lib\site-packages\aiohttp\connector.py", line 1152, in _create_direct_connection
    hosts = await asyncio.shield(host_resolved)
  File "C:\Users\Михаил\PycharmProjects\football_discordBot\venv\lib\site-packages\aiohttp\connector.py", line 874, in _resolve_host
    addrs = await self._resolver.resolve(host, port, family=self._family)
  File "C:\Users\Михаил\PycharmProjects\football_discordBot\venv\lib\site-packages\aiohttp\resolver.py", line 33, in resolve
    infos = await self._loop.getaddrinfo(
  File "C:\Users\Михаил\AppData\Local\Programs\Python\Python310\lib\asyncio\base_events.py", line 860, in getaddrinfo
    return await self.run_in_executor(
  File "C:\Users\Михаил\AppData\Local\Programs\Python\Python310\lib\concurrent\futures\thread.py", line 58, in run
    result = self.fn(*self.args, **self.kwargs)
  File "C:\Users\Михаил\AppData\Local\Programs\Python\Python310\lib\socket.py", line 955, in getaddrinfo
    for res in _socket.getaddrinfo(host, port, family, type, proto, flags):
socket.gaierror: [Errno 11004] getaddrinfo failed

The above exception was the direct cause of the following exception:

Traceback (most recent call last):
  File "C:\Users\Михаил\PycharmProjects\football_discordBot\venv\lib\site-packages\nextcord\client.py", line 708, in connect
    self.ws = await asyncio.wait_for(coro, timeout=60.0)
  File "C:\Users\Михаил\AppData\Local\Programs\Python\Python310\lib\asyncio\tasks.py", line 445, in wait_for
    return fut.result()
  File "C:\Users\Михаил\PycharmProjects\football_discordBot\venv\lib\site-packages\nextcord\gateway.py", line 365, in from_client
    socket = await client.http.ws_connect(gateway)
  File "C:\Users\Михаил\PycharmProjects\football_discordBot\venv\lib\site-packages\nextcord\http.py", line 250, in ws_connect
    return await self.__session.ws_connect(url, **kwargs)
  File "C:\Users\Михаил\PycharmProjects\football_discordBot\venv\lib\site-packages\aiohttp\client.py", line 779, in _ws_connect
    resp = await self.request(
  File "C:\Users\Михаил\PycharmProjects\football_discordBot\venv\lib\site-packages\aiohttp\client.py", line 536, in _request
    conn = await self._connector.connect(
  File "C:\Users\Михаил\PycharmProjects\football_discordBot\venv\lib\site-packages\aiohttp\connector.py", line 540, in connect
    proto = await self._create_connection(req, traces, timeout)
  File "C:\Users\Михаил\PycharmProjects\football_discordBot\venv\lib\site-packages\aiohttp\connector.py", line 901, in _create_connection
    _, proto = await self._create_direct_connection(req, traces, timeout)
  File "C:\Users\Михаил\PycharmProjects\football_discordBot\venv\lib\site-packages\aiohttp\connector.py", line 1166, in _create_direct_connection
    raise ClientConnectorError(req.connection_key, exc) from exc
aiohttp.client_exceptions.ClientConnectorError: Cannot connect to host gateway-us-east1-b.discord.gg:443 ssl:default [getaddrinfo failed]
[23-01-26 19:32:14] [client.py ERROR] Attempting a reconnect in 121.77s
Traceback (most recent call last):
  File "C:\Users\Михаил\PycharmProjects\football_discordBot\venv\lib\site-packages\aiohttp\connector.py", line 1152, in _create_direct_connection
    hosts = await asyncio.shield(host_resolved)
  File "C:\Users\Михаил\PycharmProjects\football_discordBot\venv\lib\site-packages\aiohttp\connector.py", line 874, in _resolve_host
    addrs = await self._resolver.resolve(host, port, family=self._family)
  File "C:\Users\Михаил\PycharmProjects\football_discordBot\venv\lib\site-packages\aiohttp\resolver.py", line 33, in resolve
    infos = await self._loop.getaddrinfo(
  File "C:\Users\Михаил\AppData\Local\Programs\Python\Python310\lib\asyncio\base_events.py", line 860, in getaddrinfo
    return await self.run_in_executor(
  File "C:\Users\Михаил\AppData\Local\Programs\Python\Python310\lib\concurrent\futures\thread.py", line 58, in run
    result = self.fn(*self.args, **self.kwargs)
  File "C:\Users\Михаил\AppData\Local\Programs\Python\Python310\lib\socket.py", line 955, in getaddrinfo
    for res in _socket.getaddrinfo(host, port, family, type, proto, flags):
socket.gaierror: [Errno 11004] getaddrinfo failed

The above exception was the direct cause of the following exception:

Traceback (most recent call last):
  File "C:\Users\Михаил\PycharmProjects\football_discordBot\venv\lib\site-packages\nextcord\client.py", line 708, in connect
    self.ws = await asyncio.wait_for(coro, timeout=60.0)
  File "C:\Users\Михаил\AppData\Local\Programs\Python\Python310\lib\asyncio\tasks.py", line 445, in wait_for
    return fut.result()
  File "C:\Users\Михаил\PycharmProjects\football_discordBot\venv\lib\site-packages\nextcord\gateway.py", line 365, in from_client
    socket = await client.http.ws_connect(gateway)
  File "C:\Users\Михаил\PycharmProjects\football_discordBot\venv\lib\site-packages\nextcord\http.py", line 250, in ws_connect
    return await self.__session.ws_connect(url, **kwargs)
  File "C:\Users\Михаил\PycharmProjects\football_discordBot\venv\lib\site-packages\aiohttp\client.py", line 779, in _ws_connect
    resp = await self.request(
  File "C:\Users\Михаил\PycharmProjects\football_discordBot\venv\lib\site-packages\aiohttp\client.py", line 536, in _request
    conn = await self._connector.connect(
  File "C:\Users\Михаил\PycharmProjects\football_discordBot\venv\lib\site-packages\aiohttp\connector.py", line 540, in connect
    proto = await self._create_connection(req, traces, timeout)
  File "C:\Users\Михаил\PycharmProjects\football_discordBot\venv\lib\site-packages\aiohttp\connector.py", line 901, in _create_connection
    _, proto = await self._create_direct_connection(req, traces, timeout)
  File "C:\Users\Михаил\PycharmProjects\football_discordBot\venv\lib\site-packages\aiohttp\connector.py", line 1166, in _create_direct_connection
    raise ClientConnectorError(req.connection_key, exc) from exc
aiohttp.client_exceptions.ClientConnectorError: Cannot connect to host gateway-us-east1-b.discord.gg:443 ssl:default [getaddrinfo failed]
[23-01-26 19:34:16] [client.py ERROR] Attempting a reconnect in 203.42s
Traceback (most recent call last):
  File "C:\Users\Михаил\PycharmProjects\football_discordBot\venv\lib\site-packages\aiohttp\connector.py", line 1152, in _create_direct_connection
    hosts = await asyncio.shield(host_resolved)
  File "C:\Users\Михаил\PycharmProjects\football_discordBot\venv\lib\site-packages\aiohttp\connector.py", line 874, in _resolve_host
    addrs = await self._resolver.resolve(host, port, family=self._family)
  File "C:\Users\Михаил\PycharmProjects\football_discordBot\venv\lib\site-packages\aiohttp\resolver.py", line 33, in resolve
    infos = await self._loop.getaddrinfo(
  File "C:\Users\Михаил\AppData\Local\Programs\Python\Python310\lib\asyncio\base_events.py", line 860, in getaddrinfo
    return await self.run_in_executor(
  File "C:\Users\Михаил\AppData\Local\Programs\Python\Python310\lib\concurrent\futures\thread.py", line 58, in run
    result = self.fn(*self.args, **self.kwargs)
  File "C:\Users\Михаил\AppData\Local\Programs\Python\Python310\lib\socket.py", line 955, in getaddrinfo
    for res in _socket.getaddrinfo(host, port, family, type, proto, flags):
socket.gaierror: [Errno 11004] getaddrinfo failed

The above exception was the direct cause of the following exception:

Traceback (most recent call last):
  File "C:\Users\Михаил\PycharmProjects\football_discordBot\venv\lib\site-packages\nextcord\client.py", line 708, in connect
    self.ws = await asyncio.wait_for(coro, timeout=60.0)
  File "C:\Users\Михаил\AppData\Local\Programs\Python\Python310\lib\asyncio\tasks.py", line 445, in wait_for
    return fut.result()
  File "C:\Users\Михаил\PycharmProjects\football_discordBot\venv\lib\site-packages\nextcord\gateway.py", line 365, in from_client
    socket = await client.http.ws_connect(gateway)
  File "C:\Users\Михаил\PycharmProjects\football_discordBot\venv\lib\site-packages\nextcord\http.py", line 250, in ws_connect
    return await self.__session.ws_connect(url, **kwargs)
  File "C:\Users\Михаил\PycharmProjects\football_discordBot\venv\lib\site-packages\aiohttp\client.py", line 779, in _ws_connect
    resp = await self.request(
  File "C:\Users\Михаил\PycharmProjects\football_discordBot\venv\lib\site-packages\aiohttp\client.py", line 536, in _request
    conn = await self._connector.connect(
  File "C:\Users\Михаил\PycharmProjects\football_discordBot\venv\lib\site-packages\aiohttp\connector.py", line 540, in connect
    proto = await self._create_connection(req, traces, timeout)
  File "C:\Users\Михаил\PycharmProjects\football_discordBot\venv\lib\site-packages\aiohttp\connector.py", line 901, in _create_connection
    _, proto = await self._create_direct_connection(req, traces, timeout)
  File "C:\Users\Михаил\PycharmProjects\football_discordBot\venv\lib\site-packages\aiohttp\connector.py", line 1166, in _create_direct_connection
    raise ClientConnectorError(req.connection_key, exc) from exc
aiohttp.client_exceptions.ClientConnectorError: Cannot connect to host gateway-us-east1-b.discord.gg:443 ssl:default [getaddrinfo failed]
[23-01-26 19:37:39] [client.py ERROR] Attempting a reconnect in 348.11s
Traceback (most recent call last):
  File "C:\Users\Михаил\PycharmProjects\football_discordBot\venv\lib\site-packages\aiohttp\connector.py", line 1152, in _create_direct_connection
    hosts = await asyncio.shield(host_resolved)
  File "C:\Users\Михаил\PycharmProjects\football_discordBot\venv\lib\site-packages\aiohttp\connector.py", line 874, in _resolve_host
    addrs = await self._resolver.resolve(host, port, family=self._family)
  File "C:\Users\Михаил\PycharmProjects\football_discordBot\venv\lib\site-packages\aiohttp\resolver.py", line 33, in resolve
    infos = await self._loop.getaddrinfo(
  File "C:\Users\Михаил\AppData\Local\Programs\Python\Python310\lib\asyncio\base_events.py", line 860, in getaddrinfo
    return await self.run_in_executor(
  File "C:\Users\Михаил\AppData\Local\Programs\Python\Python310\lib\concurrent\futures\thread.py", line 58, in run
    result = self.fn(*self.args, **self.kwargs)
  File "C:\Users\Михаил\AppData\Local\Programs\Python\Python310\lib\socket.py", line 955, in getaddrinfo
    for res in _socket.getaddrinfo(host, port, family, type, proto, flags):
socket.gaierror: [Errno 11004] getaddrinfo failed

The above exception was the direct cause of the following exception:

Traceback (most recent call last):
  File "C:\Users\Михаил\PycharmProjects\football_discordBot\venv\lib\site-packages\nextcord\client.py", line 708, in connect
    self.ws = await asyncio.wait_for(coro, timeout=60.0)
  File "C:\Users\Михаил\AppData\Local\Programs\Python\Python310\lib\asyncio\tasks.py", line 445, in wait_for
    return fut.result()
  File "C:\Users\Михаил\PycharmProjects\football_discordBot\venv\lib\site-packages\nextcord\gateway.py", line 365, in from_client
    socket = await client.http.ws_connect(gateway)
  File "C:\Users\Михаил\PycharmProjects\football_discordBot\venv\lib\site-packages\nextcord\http.py", line 250, in ws_connect
    return await self.__session.ws_connect(url, **kwargs)
  File "C:\Users\Михаил\PycharmProjects\football_discordBot\venv\lib\site-packages\aiohttp\client.py", line 779, in _ws_connect
    resp = await self.request(
  File "C:\Users\Михаил\PycharmProjects\football_discordBot\venv\lib\site-packages\aiohttp\client.py", line 536, in _request
    conn = await self._connector.connect(
  File "C:\Users\Михаил\PycharmProjects\football_discordBot\venv\lib\site-packages\aiohttp\connector.py", line 540, in connect
    proto = await self._create_connection(req, traces, timeout)
  File "C:\Users\Михаил\PycharmProjects\football_discordBot\venv\lib\site-packages\aiohttp\connector.py", line 901, in _create_connection
    _, proto = await self._create_direct_connection(req, traces, timeout)
  File "C:\Users\Михаил\PycharmProjects\football_discordBot\venv\lib\site-packages\aiohttp\connector.py", line 1166, in _create_direct_connection
    raise ClientConnectorError(req.connection_key, exc) from exc
aiohttp.client_exceptions.ClientConnectorError: Cannot connect to host gateway-us-east1-b.discord.gg:443 ssl:default [getaddrinfo failed]
[23-01-26 19:43:27] [client.py ERROR] Attempting a reconnect in 655.24s
Traceback (most recent call last):
  File "C:\Users\Михаил\PycharmProjects\football_discordBot\venv\lib\site-packages\aiohttp\connector.py", line 1152, in _create_direct_connection
    hosts = await asyncio.shield(host_resolved)
  File "C:\Users\Михаил\PycharmProjects\football_discordBot\venv\lib\site-packages\aiohttp\connector.py", line 874, in _resolve_host
    addrs = await self._resolver.resolve(host, port, family=self._family)
  File "C:\Users\Михаил\PycharmProjects\football_discordBot\venv\lib\site-packages\aiohttp\resolver.py", line 33, in resolve
    infos = await self._loop.getaddrinfo(
  File "C:\Users\Михаил\AppData\Local\Programs\Python\Python310\lib\asyncio\base_events.py", line 860, in getaddrinfo
    return await self.run_in_executor(
  File "C:\Users\Михаил\AppData\Local\Programs\Python\Python310\lib\concurrent\futures\thread.py", line 58, in run
    result = self.fn(*self.args, **self.kwargs)
  File "C:\Users\Михаил\AppData\Local\Programs\Python\Python310\lib\socket.py", line 955, in getaddrinfo
    for res in _socket.getaddrinfo(host, port, family, type, proto, flags):
socket.gaierror: [Errno 11004] getaddrinfo failed

The above exception was the direct cause of the following exception:

Traceback (most recent call last):
  File "C:\Users\Михаил\PycharmProjects\football_discordBot\venv\lib\site-packages\nextcord\client.py", line 708, in connect
    self.ws = await asyncio.wait_for(coro, timeout=60.0)
  File "C:\Users\Михаил\AppData\Local\Programs\Python\Python310\lib\asyncio\tasks.py", line 445, in wait_for
    return fut.result()
  File "C:\Users\Михаил\PycharmProjects\football_discordBot\venv\lib\site-packages\nextcord\gateway.py", line 365, in from_client
    socket = await client.http.ws_connect(gateway)
  File "C:\Users\Михаил\PycharmProjects\football_discordBot\venv\lib\site-packages\nextcord\http.py", line 250, in ws_connect
    return await self.__session.ws_connect(url, **kwargs)
  File "C:\Users\Михаил\PycharmProjects\football_discordBot\venv\lib\site-packages\aiohttp\client.py", line 779, in _ws_connect
    resp = await self.request(
  File "C:\Users\Михаил\PycharmProjects\football_discordBot\venv\lib\site-packages\aiohttp\client.py", line 536, in _request
    conn = await self._connector.connect(
  File "C:\Users\Михаил\PycharmProjects\football_discordBot\venv\lib\site-packages\aiohttp\connector.py", line 540, in connect
    proto = await self._create_connection(req, traces, timeout)
  File "C:\Users\Михаил\PycharmProjects\football_discordBot\venv\lib\site-packages\aiohttp\connector.py", line 901, in _create_connection
    _, proto = await self._create_direct_connection(req, traces, timeout)
  File "C:\Users\Михаил\PycharmProjects\football_discordBot\venv\lib\site-packages\aiohttp\connector.py", line 1166, in _create_direct_connection
    raise ClientConnectorError(req.connection_key, exc) from exc
aiohttp.client_exceptions.ClientConnectorError: Cannot connect to host gateway-us-east1-b.discord.gg:443 ssl:default [getaddrinfo failed]
[23-01-26 19:54:22] [client.py ERROR] Attempting a reconnect in 291.69s
Traceback (most recent call last):
  File "C:\Users\Михаил\PycharmProjects\football_discordBot\venv\lib\site-packages\aiohttp\connector.py", line 1152, in _create_direct_connection
    hosts = await asyncio.shield(host_resolved)
  File "C:\Users\Михаил\PycharmProjects\football_discordBot\venv\lib\site-packages\aiohttp\connector.py", line 874, in _resolve_host
    addrs = await self._resolver.resolve(host, port, family=self._family)
  File "C:\Users\Михаил\PycharmProjects\football_discordBot\venv\lib\site-packages\aiohttp\resolver.py", line 33, in resolve
    infos = await self._loop.getaddrinfo(
  File "C:\Users\Михаил\AppData\Local\Programs\Python\Python310\lib\asyncio\base_events.py", line 860, in getaddrinfo
    return await self.run_in_executor(
  File "C:\Users\Михаил\AppData\Local\Programs\Python\Python310\lib\concurrent\futures\thread.py", line 58, in run
    result = self.fn(*self.args, **self.kwargs)
  File "C:\Users\Михаил\AppData\Local\Programs\Python\Python310\lib\socket.py", line 955, in getaddrinfo
    for res in _socket.getaddrinfo(host, port, family, type, proto, flags):
socket.gaierror: [Errno 11004] getaddrinfo failed

The above exception was the direct cause of the following exception:

Traceback (most recent call last):
  File "C:\Users\Михаил\PycharmProjects\football_discordBot\venv\lib\site-packages\nextcord\client.py", line 708, in connect
    self.ws = await asyncio.wait_for(coro, timeout=60.0)
  File "C:\Users\Михаил\AppData\Local\Programs\Python\Python310\lib\asyncio\tasks.py", line 445, in wait_for
    return fut.result()
  File "C:\Users\Михаил\PycharmProjects\football_discordBot\venv\lib\site-packages\nextcord\gateway.py", line 365, in from_client
    socket = await client.http.ws_connect(gateway)
  File "C:\Users\Михаил\PycharmProjects\football_discordBot\venv\lib\site-packages\nextcord\http.py", line 250, in ws_connect
    return await self.__session.ws_connect(url, **kwargs)
  File "C:\Users\Михаил\PycharmProjects\football_discordBot\venv\lib\site-packages\aiohttp\client.py", line 779, in _ws_connect
    resp = await self.request(
  File "C:\Users\Михаил\PycharmProjects\football_discordBot\venv\lib\site-packages\aiohttp\client.py", line 536, in _request
    conn = await self._connector.connect(
  File "C:\Users\Михаил\PycharmProjects\football_discordBot\venv\lib\site-packages\aiohttp\connector.py", line 540, in connect
    proto = await self._create_connection(req, traces, timeout)
  File "C:\Users\Михаил\PycharmProjects\football_discordBot\venv\lib\site-packages\aiohttp\connector.py", line 901, in _create_connection
    _, proto = await self._create_direct_connection(req, traces, timeout)
  File "C:\Users\Михаил\PycharmProjects\football_discordBot\venv\lib\site-packages\aiohttp\connector.py", line 1166, in _create_direct_connection
    raise ClientConnectorError(req.connection_key, exc) from exc
aiohttp.client_exceptions.ClientConnectorError: Cannot connect to host gateway-us-east1-b.discord.gg:443 ssl:default [getaddrinfo failed]
[23-01-26 19:59:14] [client.py ERROR] Attempting a reconnect in 199.32s
Traceback (most recent call last):
  File "C:\Users\Михаил\PycharmProjects\football_discordBot\venv\lib\site-packages\aiohttp\connector.py", line 1152, in _create_direct_connection
    hosts = await asyncio.shield(host_resolved)
  File "C:\Users\Михаил\PycharmProjects\football_discordBot\venv\lib\site-packages\aiohttp\connector.py", line 874, in _resolve_host
    addrs = await self._resolver.resolve(host, port, family=self._family)
  File "C:\Users\Михаил\PycharmProjects\football_discordBot\venv\lib\site-packages\aiohttp\resolver.py", line 33, in resolve
    infos = await self._loop.getaddrinfo(
  File "C:\Users\Михаил\AppData\Local\Programs\Python\Python310\lib\asyncio\base_events.py", line 860, in getaddrinfo
    return await self.run_in_executor(
  File "C:\Users\Михаил\AppData\Local\Programs\Python\Python310\lib\concurrent\futures\thread.py", line 58, in run
    result = self.fn(*self.args, **self.kwargs)
  File "C:\Users\Михаил\AppData\Local\Programs\Python\Python310\lib\socket.py", line 955, in getaddrinfo
    for res in _socket.getaddrinfo(host, port, family, type, proto, flags):
socket.gaierror: [Errno 11004] getaddrinfo failed

The above exception was the direct cause of the following exception:

Traceback (most recent call last):
  File "C:\Users\Михаил\PycharmProjects\football_discordBot\venv\lib\site-packages\nextcord\client.py", line 708, in connect
    self.ws = await asyncio.wait_for(coro, timeout=60.0)
  File "C:\Users\Михаил\AppData\Local\Programs\Python\Python310\lib\asyncio\tasks.py", line 445, in wait_for
    return fut.result()
  File "C:\Users\Михаил\PycharmProjects\football_discordBot\venv\lib\site-packages\nextcord\gateway.py", line 365, in from_client
    socket = await client.http.ws_connect(gateway)
  File "C:\Users\Михаил\PycharmProjects\football_discordBot\venv\lib\site-packages\nextcord\http.py", line 250, in ws_connect
    return await self.__session.ws_connect(url, **kwargs)
  File "C:\Users\Михаил\PycharmProjects\football_discordBot\venv\lib\site-packages\aiohttp\client.py", line 779, in _ws_connect
    resp = await self.request(
  File "C:\Users\Михаил\PycharmProjects\football_discordBot\venv\lib\site-packages\aiohttp\client.py", line 536, in _request
    conn = await self._connector.connect(
  File "C:\Users\Михаил\PycharmProjects\football_discordBot\venv\lib\site-packages\aiohttp\connector.py", line 540, in connect
    proto = await self._create_connection(req, traces, timeout)
  File "C:\Users\Михаил\PycharmProjects\football_discordBot\venv\lib\site-packages\aiohttp\connector.py", line 901, in _create_connection
    _, proto = await self._create_direct_connection(req, traces, timeout)
  File "C:\Users\Михаил\PycharmProjects\football_discordBot\venv\lib\site-packages\aiohttp\connector.py", line 1166, in _create_direct_connection
    raise ClientConnectorError(req.connection_key, exc) from exc
aiohttp.client_exceptions.ClientConnectorError: Cannot connect to host gateway-us-east1-b.discord.gg:443 ssl:default [getaddrinfo failed]
[23-01-27 15:09:41] [client.py ERROR] Attempting a reconnect in 1.71s
Traceback (most recent call last):
  File "C:\Users\Михаил\PycharmProjects\football_discordBot\venv\lib\site-packages\aiohttp\connector.py", line 1152, in _create_direct_connection
    hosts = await asyncio.shield(host_resolved)
  File "C:\Users\Михаил\PycharmProjects\football_discordBot\venv\lib\site-packages\aiohttp\connector.py", line 874, in _resolve_host
    addrs = await self._resolver.resolve(host, port, family=self._family)
  File "C:\Users\Михаил\PycharmProjects\football_discordBot\venv\lib\site-packages\aiohttp\resolver.py", line 33, in resolve
    infos = await self._loop.getaddrinfo(
  File "C:\Users\Михаил\AppData\Local\Programs\Python\Python310\lib\asyncio\base_events.py", line 860, in getaddrinfo
    return await self.run_in_executor(
  File "C:\Users\Михаил\AppData\Local\Programs\Python\Python310\lib\concurrent\futures\thread.py", line 58, in run
    result = self.fn(*self.args, **self.kwargs)
  File "C:\Users\Михаил\AppData\Local\Programs\Python\Python310\lib\socket.py", line 955, in getaddrinfo
    for res in _socket.getaddrinfo(host, port, family, type, proto, flags):
socket.gaierror: [Errno 11001] getaddrinfo failed

The above exception was the direct cause of the following exception:

Traceback (most recent call last):
  File "C:\Users\Михаил\PycharmProjects\football_discordBot\venv\lib\site-packages\nextcord\client.py", line 708, in connect
    self.ws = await asyncio.wait_for(coro, timeout=60.0)
  File "C:\Users\Михаил\AppData\Local\Programs\Python\Python310\lib\asyncio\tasks.py", line 445, in wait_for
    return fut.result()
  File "C:\Users\Михаил\PycharmProjects\football_discordBot\venv\lib\site-packages\nextcord\gateway.py", line 365, in from_client
    socket = await client.http.ws_connect(gateway)
  File "C:\Users\Михаил\PycharmProjects\football_discordBot\venv\lib\site-packages\nextcord\http.py", line 250, in ws_connect
    return await self.__session.ws_connect(url, **kwargs)
  File "C:\Users\Михаил\PycharmProjects\football_discordBot\venv\lib\site-packages\aiohttp\client.py", line 779, in _ws_connect
    resp = await self.request(
  File "C:\Users\Михаил\PycharmProjects\football_discordBot\venv\lib\site-packages\aiohttp\client.py", line 536, in _request
    conn = await self._connector.connect(
  File "C:\Users\Михаил\PycharmProjects\football_discordBot\venv\lib\site-packages\aiohttp\connector.py", line 540, in connect
    proto = await self._create_connection(req, traces, timeout)
  File "C:\Users\Михаил\PycharmProjects\football_discordBot\venv\lib\site-packages\aiohttp\connector.py", line 901, in _create_connection
    _, proto = await self._create_direct_connection(req, traces, timeout)
  File "C:\Users\Михаил\PycharmProjects\football_discordBot\venv\lib\site-packages\aiohttp\connector.py", line 1166, in _create_direct_connection
    raise ClientConnectorError(req.connection_key, exc) from exc
aiohttp.client_exceptions.ClientConnectorError: Cannot connect to host gateway-us-east1-c.discord.gg:443 ssl:default [getaddrinfo failed]
[23-01-27 15:09:48] [client.py ERROR] Attempting a reconnect in 0.09s
Traceback (most recent call last):
  File "C:\Users\Михаил\PycharmProjects\football_discordBot\venv\lib\site-packages\aiohttp\connector.py", line 1152, in _create_direct_connection
    hosts = await asyncio.shield(host_resolved)
  File "C:\Users\Михаил\PycharmProjects\football_discordBot\venv\lib\site-packages\aiohttp\connector.py", line 874, in _resolve_host
    addrs = await self._resolver.resolve(host, port, family=self._family)
  File "C:\Users\Михаил\PycharmProjects\football_discordBot\venv\lib\site-packages\aiohttp\resolver.py", line 33, in resolve
    infos = await self._loop.getaddrinfo(
  File "C:\Users\Михаил\AppData\Local\Programs\Python\Python310\lib\asyncio\base_events.py", line 860, in getaddrinfo
    return await self.run_in_executor(
  File "C:\Users\Михаил\AppData\Local\Programs\Python\Python310\lib\concurrent\futures\thread.py", line 58, in run
    result = self.fn(*self.args, **self.kwargs)
  File "C:\Users\Михаил\AppData\Local\Programs\Python\Python310\lib\socket.py", line 955, in getaddrinfo
    for res in _socket.getaddrinfo(host, port, family, type, proto, flags):
socket.gaierror: [Errno 11004] getaddrinfo failed

The above exception was the direct cause of the following exception:

Traceback (most recent call last):
  File "C:\Users\Михаил\PycharmProjects\football_discordBot\venv\lib\site-packages\nextcord\client.py", line 708, in connect
    self.ws = await asyncio.wait_for(coro, timeout=60.0)
  File "C:\Users\Михаил\AppData\Local\Programs\Python\Python310\lib\asyncio\tasks.py", line 445, in wait_for
    return fut.result()
  File "C:\Users\Михаил\PycharmProjects\football_discordBot\venv\lib\site-packages\nextcord\gateway.py", line 365, in from_client
    socket = await client.http.ws_connect(gateway)
  File "C:\Users\Михаил\PycharmProjects\football_discordBot\venv\lib\site-packages\nextcord\http.py", line 250, in ws_connect
    return await self.__session.ws_connect(url, **kwargs)
  File "C:\Users\Михаил\PycharmProjects\football_discordBot\venv\lib\site-packages\aiohttp\client.py", line 779, in _ws_connect
    resp = await self.request(
  File "C:\Users\Михаил\PycharmProjects\football_discordBot\venv\lib\site-packages\aiohttp\client.py", line 536, in _request
    conn = await self._connector.connect(
  File "C:\Users\Михаил\PycharmProjects\football_discordBot\venv\lib\site-packages\aiohttp\connector.py", line 540, in connect
    proto = await self._create_connection(req, traces, timeout)
  File "C:\Users\Михаил\PycharmProjects\football_discordBot\venv\lib\site-packages\aiohttp\connector.py", line 901, in _create_connection
    _, proto = await self._create_direct_connection(req, traces, timeout)
  File "C:\Users\Михаил\PycharmProjects\football_discordBot\venv\lib\site-packages\aiohttp\connector.py", line 1166, in _create_direct_connection
    raise ClientConnectorError(req.connection_key, exc) from exc
aiohttp.client_exceptions.ClientConnectorError: Cannot connect to host gateway-us-east1-c.discord.gg:443 ssl:default [getaddrinfo failed]
[23-01-27 15:09:48] [client.py ERROR] Attempting a reconnect in 2.32s
Traceback (most recent call last):
  File "C:\Users\Михаил\PycharmProjects\football_discordBot\venv\lib\site-packages\aiohttp\connector.py", line 1152, in _create_direct_connection
    hosts = await asyncio.shield(host_resolved)
  File "C:\Users\Михаил\PycharmProjects\football_discordBot\venv\lib\site-packages\aiohttp\connector.py", line 874, in _resolve_host
    addrs = await self._resolver.resolve(host, port, family=self._family)
  File "C:\Users\Михаил\PycharmProjects\football_discordBot\venv\lib\site-packages\aiohttp\resolver.py", line 33, in resolve
    infos = await self._loop.getaddrinfo(
  File "C:\Users\Михаил\AppData\Local\Programs\Python\Python310\lib\asyncio\base_events.py", line 860, in getaddrinfo
    return await self.run_in_executor(
  File "C:\Users\Михаил\AppData\Local\Programs\Python\Python310\lib\concurrent\futures\thread.py", line 58, in run
    result = self.fn(*self.args, **self.kwargs)
  File "C:\Users\Михаил\AppData\Local\Programs\Python\Python310\lib\socket.py", line 955, in getaddrinfo
    for res in _socket.getaddrinfo(host, port, family, type, proto, flags):
socket.gaierror: [Errno 11004] getaddrinfo failed

The above exception was the direct cause of the following exception:

Traceback (most recent call last):
  File "C:\Users\Михаил\PycharmProjects\football_discordBot\venv\lib\site-packages\nextcord\client.py", line 708, in connect
    self.ws = await asyncio.wait_for(coro, timeout=60.0)
  File "C:\Users\Михаил\AppData\Local\Programs\Python\Python310\lib\asyncio\tasks.py", line 445, in wait_for
    return fut.result()
  File "C:\Users\Михаил\PycharmProjects\football_discordBot\venv\lib\site-packages\nextcord\gateway.py", line 365, in from_client
    socket = await client.http.ws_connect(gateway)
  File "C:\Users\Михаил\PycharmProjects\football_discordBot\venv\lib\site-packages\nextcord\http.py", line 250, in ws_connect
    return await self.__session.ws_connect(url, **kwargs)
  File "C:\Users\Михаил\PycharmProjects\football_discordBot\venv\lib\site-packages\aiohttp\client.py", line 779, in _ws_connect
    resp = await self.request(
  File "C:\Users\Михаил\PycharmProjects\football_discordBot\venv\lib\site-packages\aiohttp\client.py", line 536, in _request
    conn = await self._connector.connect(
  File "C:\Users\Михаил\PycharmProjects\football_discordBot\venv\lib\site-packages\aiohttp\connector.py", line 540, in connect
    proto = await self._create_connection(req, traces, timeout)
  File "C:\Users\Михаил\PycharmProjects\football_discordBot\venv\lib\site-packages\aiohttp\connector.py", line 901, in _create_connection
    _, proto = await self._create_direct_connection(req, traces, timeout)
  File "C:\Users\Михаил\PycharmProjects\football_discordBot\venv\lib\site-packages\aiohttp\connector.py", line 1166, in _create_direct_connection
    raise ClientConnectorError(req.connection_key, exc) from exc
aiohttp.client_exceptions.ClientConnectorError: Cannot connect to host gateway-us-east1-c.discord.gg:443 ssl:default [getaddrinfo failed]
[23-01-27 15:43:07] [client.py ERROR] Attempting a reconnect in 0.42s
Traceback (most recent call last):
  File "C:\Users\Михаил\PycharmProjects\football_discordBot\venv\lib\site-packages\aiohttp\connector.py", line 1152, in _create_direct_connection
    hosts = await asyncio.shield(host_resolved)
  File "C:\Users\Михаил\PycharmProjects\football_discordBot\venv\lib\site-packages\aiohttp\connector.py", line 874, in _resolve_host
    addrs = await self._resolver.resolve(host, port, family=self._family)
  File "C:\Users\Михаил\PycharmProjects\football_discordBot\venv\lib\site-packages\aiohttp\resolver.py", line 33, in resolve
    infos = await self._loop.getaddrinfo(
  File "C:\Users\Михаил\AppData\Local\Programs\Python\Python310\lib\asyncio\base_events.py", line 860, in getaddrinfo
    return await self.run_in_executor(
  File "C:\Users\Михаил\AppData\Local\Programs\Python\Python310\lib\concurrent\futures\thread.py", line 58, in run
    result = self.fn(*self.args, **self.kwargs)
  File "C:\Users\Михаил\AppData\Local\Programs\Python\Python310\lib\socket.py", line 955, in getaddrinfo
    for res in _socket.getaddrinfo(host, port, family, type, proto, flags):
socket.gaierror: [Errno 11004] getaddrinfo failed

The above exception was the direct cause of the following exception:

Traceback (most recent call last):
  File "C:\Users\Михаил\PycharmProjects\football_discordBot\venv\lib\site-packages\nextcord\client.py", line 708, in connect
    self.ws = await asyncio.wait_for(coro, timeout=60.0)
  File "C:\Users\Михаил\AppData\Local\Programs\Python\Python310\lib\asyncio\tasks.py", line 445, in wait_for
    return fut.result()
  File "C:\Users\Михаил\PycharmProjects\football_discordBot\venv\lib\site-packages\nextcord\gateway.py", line 365, in from_client
    socket = await client.http.ws_connect(gateway)
  File "C:\Users\Михаил\PycharmProjects\football_discordBot\venv\lib\site-packages\nextcord\http.py", line 250, in ws_connect
    return await self.__session.ws_connect(url, **kwargs)
  File "C:\Users\Михаил\PycharmProjects\football_discordBot\venv\lib\site-packages\aiohttp\client.py", line 779, in _ws_connect
    resp = await self.request(
  File "C:\Users\Михаил\PycharmProjects\football_discordBot\venv\lib\site-packages\aiohttp\client.py", line 536, in _request
    conn = await self._connector.connect(
  File "C:\Users\Михаил\PycharmProjects\football_discordBot\venv\lib\site-packages\aiohttp\connector.py", line 540, in connect
    proto = await self._create_connection(req, traces, timeout)
  File "C:\Users\Михаил\PycharmProjects\football_discordBot\venv\lib\site-packages\aiohttp\connector.py", line 901, in _create_connection
    _, proto = await self._create_direct_connection(req, traces, timeout)
  File "C:\Users\Михаил\PycharmProjects\football_discordBot\venv\lib\site-packages\aiohttp\connector.py", line 1166, in _create_direct_connection
    raise ClientConnectorError(req.connection_key, exc) from exc
aiohttp.client_exceptions.ClientConnectorError: Cannot connect to host gateway-us-east1-b.discord.gg:443 ssl:default [getaddrinfo failed]
[23-01-27 15:43:08] [client.py ERROR] Attempting a reconnect in 1.13s
Traceback (most recent call last):
  File "C:\Users\Михаил\PycharmProjects\football_discordBot\venv\lib\site-packages\aiohttp\connector.py", line 1152, in _create_direct_connection
    hosts = await asyncio.shield(host_resolved)
  File "C:\Users\Михаил\PycharmProjects\football_discordBot\venv\lib\site-packages\aiohttp\connector.py", line 874, in _resolve_host
    addrs = await self._resolver.resolve(host, port, family=self._family)
  File "C:\Users\Михаил\PycharmProjects\football_discordBot\venv\lib\site-packages\aiohttp\resolver.py", line 33, in resolve
    infos = await self._loop.getaddrinfo(
  File "C:\Users\Михаил\AppData\Local\Programs\Python\Python310\lib\asyncio\base_events.py", line 860, in getaddrinfo
    return await self.run_in_executor(
  File "C:\Users\Михаил\AppData\Local\Programs\Python\Python310\lib\concurrent\futures\thread.py", line 58, in run
    result = self.fn(*self.args, **self.kwargs)
  File "C:\Users\Михаил\AppData\Local\Programs\Python\Python310\lib\socket.py", line 955, in getaddrinfo
    for res in _socket.getaddrinfo(host, port, family, type, proto, flags):
socket.gaierror: [Errno 11004] getaddrinfo failed

The above exception was the direct cause of the following exception:

Traceback (most recent call last):
  File "C:\Users\Михаил\PycharmProjects\football_discordBot\venv\lib\site-packages\nextcord\client.py", line 708, in connect
    self.ws = await asyncio.wait_for(coro, timeout=60.0)
  File "C:\Users\Михаил\AppData\Local\Programs\Python\Python310\lib\asyncio\tasks.py", line 445, in wait_for
    return fut.result()
  File "C:\Users\Михаил\PycharmProjects\football_discordBot\venv\lib\site-packages\nextcord\gateway.py", line 365, in from_client
    socket = await client.http.ws_connect(gateway)
  File "C:\Users\Михаил\PycharmProjects\football_discordBot\venv\lib\site-packages\nextcord\http.py", line 250, in ws_connect
    return await self.__session.ws_connect(url, **kwargs)
  File "C:\Users\Михаил\PycharmProjects\football_discordBot\venv\lib\site-packages\aiohttp\client.py", line 779, in _ws_connect
    resp = await self.request(
  File "C:\Users\Михаил\PycharmProjects\football_discordBot\venv\lib\site-packages\aiohttp\client.py", line 536, in _request
    conn = await self._connector.connect(
  File "C:\Users\Михаил\PycharmProjects\football_discordBot\venv\lib\site-packages\aiohttp\connector.py", line 540, in connect
    proto = await self._create_connection(req, traces, timeout)
  File "C:\Users\Михаил\PycharmProjects\football_discordBot\venv\lib\site-packages\aiohttp\connector.py", line 901, in _create_connection
    _, proto = await self._create_direct_connection(req, traces, timeout)
  File "C:\Users\Михаил\PycharmProjects\football_discordBot\venv\lib\site-packages\aiohttp\connector.py", line 1166, in _create_direct_connection
    raise ClientConnectorError(req.connection_key, exc) from exc
aiohttp.client_exceptions.ClientConnectorError: Cannot connect to host gateway-us-east1-b.discord.gg:443 ssl:default [getaddrinfo failed]
[23-01-27 15:43:09] [client.py ERROR] Attempting a reconnect in 5.88s
Traceback (most recent call last):
  File "C:\Users\Михаил\PycharmProjects\football_discordBot\venv\lib\site-packages\aiohttp\connector.py", line 1152, in _create_direct_connection
    hosts = await asyncio.shield(host_resolved)
  File "C:\Users\Михаил\PycharmProjects\football_discordBot\venv\lib\site-packages\aiohttp\connector.py", line 874, in _resolve_host
    addrs = await self._resolver.resolve(host, port, family=self._family)
  File "C:\Users\Михаил\PycharmProjects\football_discordBot\venv\lib\site-packages\aiohttp\resolver.py", line 33, in resolve
    infos = await self._loop.getaddrinfo(
  File "C:\Users\Михаил\AppData\Local\Programs\Python\Python310\lib\asyncio\base_events.py", line 860, in getaddrinfo
    return await self.run_in_executor(
  File "C:\Users\Михаил\AppData\Local\Programs\Python\Python310\lib\concurrent\futures\thread.py", line 58, in run
    result = self.fn(*self.args, **self.kwargs)
  File "C:\Users\Михаил\AppData\Local\Programs\Python\Python310\lib\socket.py", line 955, in getaddrinfo
    for res in _socket.getaddrinfo(host, port, family, type, proto, flags):
socket.gaierror: [Errno 11004] getaddrinfo failed

The above exception was the direct cause of the following exception:

Traceback (most recent call last):
  File "C:\Users\Михаил\PycharmProjects\football_discordBot\venv\lib\site-packages\nextcord\client.py", line 708, in connect
    self.ws = await asyncio.wait_for(coro, timeout=60.0)
  File "C:\Users\Михаил\AppData\Local\Programs\Python\Python310\lib\asyncio\tasks.py", line 445, in wait_for
    return fut.result()
  File "C:\Users\Михаил\PycharmProjects\football_discordBot\venv\lib\site-packages\nextcord\gateway.py", line 365, in from_client
    socket = await client.http.ws_connect(gateway)
  File "C:\Users\Михаил\PycharmProjects\football_discordBot\venv\lib\site-packages\nextcord\http.py", line 250, in ws_connect
    return await self.__session.ws_connect(url, **kwargs)
  File "C:\Users\Михаил\PycharmProjects\football_discordBot\venv\lib\site-packages\aiohttp\client.py", line 779, in _ws_connect
    resp = await self.request(
  File "C:\Users\Михаил\PycharmProjects\football_discordBot\venv\lib\site-packages\aiohttp\client.py", line 536, in _request
    conn = await self._connector.connect(
  File "C:\Users\Михаил\PycharmProjects\football_discordBot\venv\lib\site-packages\aiohttp\connector.py", line 540, in connect
    proto = await self._create_connection(req, traces, timeout)
  File "C:\Users\Михаил\PycharmProjects\football_discordBot\venv\lib\site-packages\aiohttp\connector.py", line 901, in _create_connection
    _, proto = await self._create_direct_connection(req, traces, timeout)
  File "C:\Users\Михаил\PycharmProjects\football_discordBot\venv\lib\site-packages\aiohttp\connector.py", line 1166, in _create_direct_connection
    raise ClientConnectorError(req.connection_key, exc) from exc
aiohttp.client_exceptions.ClientConnectorError: Cannot connect to host gateway-us-east1-b.discord.gg:443 ssl:default [getaddrinfo failed]
[23-01-27 15:43:15] [client.py ERROR] Attempting a reconnect in 10.87s
Traceback (most recent call last):
  File "C:\Users\Михаил\PycharmProjects\football_discordBot\venv\lib\site-packages\aiohttp\connector.py", line 1152, in _create_direct_connection
    hosts = await asyncio.shield(host_resolved)
  File "C:\Users\Михаил\PycharmProjects\football_discordBot\venv\lib\site-packages\aiohttp\connector.py", line 874, in _resolve_host
    addrs = await self._resolver.resolve(host, port, family=self._family)
  File "C:\Users\Михаил\PycharmProjects\football_discordBot\venv\lib\site-packages\aiohttp\resolver.py", line 33, in resolve
    infos = await self._loop.getaddrinfo(
  File "C:\Users\Михаил\AppData\Local\Programs\Python\Python310\lib\asyncio\base_events.py", line 860, in getaddrinfo
    return await self.run_in_executor(
  File "C:\Users\Михаил\AppData\Local\Programs\Python\Python310\lib\concurrent\futures\thread.py", line 58, in run
    result = self.fn(*self.args, **self.kwargs)
  File "C:\Users\Михаил\AppData\Local\Programs\Python\Python310\lib\socket.py", line 955, in getaddrinfo
    for res in _socket.getaddrinfo(host, port, family, type, proto, flags):
socket.gaierror: [Errno 11004] getaddrinfo failed

The above exception was the direct cause of the following exception:

Traceback (most recent call last):
  File "C:\Users\Михаил\PycharmProjects\football_discordBot\venv\lib\site-packages\nextcord\client.py", line 708, in connect
    self.ws = await asyncio.wait_for(coro, timeout=60.0)
  File "C:\Users\Михаил\AppData\Local\Programs\Python\Python310\lib\asyncio\tasks.py", line 445, in wait_for
    return fut.result()
  File "C:\Users\Михаил\PycharmProjects\football_discordBot\venv\lib\site-packages\nextcord\gateway.py", line 365, in from_client
    socket = await client.http.ws_connect(gateway)
  File "C:\Users\Михаил\PycharmProjects\football_discordBot\venv\lib\site-packages\nextcord\http.py", line 250, in ws_connect
    return await self.__session.ws_connect(url, **kwargs)
  File "C:\Users\Михаил\PycharmProjects\football_discordBot\venv\lib\site-packages\aiohttp\client.py", line 779, in _ws_connect
    resp = await self.request(
  File "C:\Users\Михаил\PycharmProjects\football_discordBot\venv\lib\site-packages\aiohttp\client.py", line 536, in _request
    conn = await self._connector.connect(
  File "C:\Users\Михаил\PycharmProjects\football_discordBot\venv\lib\site-packages\aiohttp\connector.py", line 540, in connect
    proto = await self._create_connection(req, traces, timeout)
  File "C:\Users\Михаил\PycharmProjects\football_discordBot\venv\lib\site-packages\aiohttp\connector.py", line 901, in _create_connection
    _, proto = await self._create_direct_connection(req, traces, timeout)
  File "C:\Users\Михаил\PycharmProjects\football_discordBot\venv\lib\site-packages\aiohttp\connector.py", line 1166, in _create_direct_connection
    raise ClientConnectorError(req.connection_key, exc) from exc
aiohttp.client_exceptions.ClientConnectorError: Cannot connect to host gateway-us-east1-b.discord.gg:443 ssl:default [getaddrinfo failed]
[23-01-27 15:43:26] [client.py ERROR] Attempting a reconnect in 20.67s
Traceback (most recent call last):
  File "C:\Users\Михаил\PycharmProjects\football_discordBot\venv\lib\site-packages\aiohttp\connector.py", line 1152, in _create_direct_connection
    hosts = await asyncio.shield(host_resolved)
  File "C:\Users\Михаил\PycharmProjects\football_discordBot\venv\lib\site-packages\aiohttp\connector.py", line 874, in _resolve_host
    addrs = await self._resolver.resolve(host, port, family=self._family)
  File "C:\Users\Михаил\PycharmProjects\football_discordBot\venv\lib\site-packages\aiohttp\resolver.py", line 33, in resolve
    infos = await self._loop.getaddrinfo(
  File "C:\Users\Михаил\AppData\Local\Programs\Python\Python310\lib\asyncio\base_events.py", line 860, in getaddrinfo
    return await self.run_in_executor(
  File "C:\Users\Михаил\AppData\Local\Programs\Python\Python310\lib\concurrent\futures\thread.py", line 58, in run
    result = self.fn(*self.args, **self.kwargs)
  File "C:\Users\Михаил\AppData\Local\Programs\Python\Python310\lib\socket.py", line 955, in getaddrinfo
    for res in _socket.getaddrinfo(host, port, family, type, proto, flags):
socket.gaierror: [Errno 11004] getaddrinfo failed

The above exception was the direct cause of the following exception:

Traceback (most recent call last):
  File "C:\Users\Михаил\PycharmProjects\football_discordBot\venv\lib\site-packages\nextcord\client.py", line 708, in connect
    self.ws = await asyncio.wait_for(coro, timeout=60.0)
  File "C:\Users\Михаил\AppData\Local\Programs\Python\Python310\lib\asyncio\tasks.py", line 445, in wait_for
    return fut.result()
  File "C:\Users\Михаил\PycharmProjects\football_discordBot\venv\lib\site-packages\nextcord\gateway.py", line 365, in from_client
    socket = await client.http.ws_connect(gateway)
  File "C:\Users\Михаил\PycharmProjects\football_discordBot\venv\lib\site-packages\nextcord\http.py", line 250, in ws_connect
    return await self.__session.ws_connect(url, **kwargs)
  File "C:\Users\Михаил\PycharmProjects\football_discordBot\venv\lib\site-packages\aiohttp\client.py", line 779, in _ws_connect
    resp = await self.request(
  File "C:\Users\Михаил\PycharmProjects\football_discordBot\venv\lib\site-packages\aiohttp\client.py", line 536, in _request
    conn = await self._connector.connect(
  File "C:\Users\Михаил\PycharmProjects\football_discordBot\venv\lib\site-packages\aiohttp\connector.py", line 540, in connect
    proto = await self._create_connection(req, traces, timeout)
  File "C:\Users\Михаил\PycharmProjects\football_discordBot\venv\lib\site-packages\aiohttp\connector.py", line 901, in _create_connection
    _, proto = await self._create_direct_connection(req, traces, timeout)
  File "C:\Users\Михаил\PycharmProjects\football_discordBot\venv\lib\site-packages\aiohttp\connector.py", line 1166, in _create_direct_connection
    raise ClientConnectorError(req.connection_key, exc) from exc
aiohttp.client_exceptions.ClientConnectorError: Cannot connect to host gateway-us-east1-b.discord.gg:443 ssl:default [getaddrinfo failed]
[23-01-27 15:43:46] [client.py ERROR] Attempting a reconnect in 20.45s
Traceback (most recent call last):
  File "C:\Users\Михаил\PycharmProjects\football_discordBot\venv\lib\site-packages\aiohttp\connector.py", line 1152, in _create_direct_connection
    hosts = await asyncio.shield(host_resolved)
  File "C:\Users\Михаил\PycharmProjects\football_discordBot\venv\lib\site-packages\aiohttp\connector.py", line 874, in _resolve_host
    addrs = await self._resolver.resolve(host, port, family=self._family)
  File "C:\Users\Михаил\PycharmProjects\football_discordBot\venv\lib\site-packages\aiohttp\resolver.py", line 33, in resolve
    infos = await self._loop.getaddrinfo(
  File "C:\Users\Михаил\AppData\Local\Programs\Python\Python310\lib\asyncio\base_events.py", line 860, in getaddrinfo
    return await self.run_in_executor(
  File "C:\Users\Михаил\AppData\Local\Programs\Python\Python310\lib\concurrent\futures\thread.py", line 58, in run
    result = self.fn(*self.args, **self.kwargs)
  File "C:\Users\Михаил\AppData\Local\Programs\Python\Python310\lib\socket.py", line 955, in getaddrinfo
    for res in _socket.getaddrinfo(host, port, family, type, proto, flags):
socket.gaierror: [Errno 11004] getaddrinfo failed

The above exception was the direct cause of the following exception:

Traceback (most recent call last):
  File "C:\Users\Михаил\PycharmProjects\football_discordBot\venv\lib\site-packages\nextcord\client.py", line 708, in connect
    self.ws = await asyncio.wait_for(coro, timeout=60.0)
  File "C:\Users\Михаил\AppData\Local\Programs\Python\Python310\lib\asyncio\tasks.py", line 445, in wait_for
    return fut.result()
  File "C:\Users\Михаил\PycharmProjects\football_discordBot\venv\lib\site-packages\nextcord\gateway.py", line 365, in from_client
    socket = await client.http.ws_connect(gateway)
  File "C:\Users\Михаил\PycharmProjects\football_discordBot\venv\lib\site-packages\nextcord\http.py", line 250, in ws_connect
    return await self.__session.ws_connect(url, **kwargs)
  File "C:\Users\Михаил\PycharmProjects\football_discordBot\venv\lib\site-packages\aiohttp\client.py", line 779, in _ws_connect
    resp = await self.request(
  File "C:\Users\Михаил\PycharmProjects\football_discordBot\venv\lib\site-packages\aiohttp\client.py", line 536, in _request
    conn = await self._connector.connect(
  File "C:\Users\Михаил\PycharmProjects\football_discordBot\venv\lib\site-packages\aiohttp\connector.py", line 540, in connect
    proto = await self._create_connection(req, traces, timeout)
  File "C:\Users\Михаил\PycharmProjects\football_discordBot\venv\lib\site-packages\aiohttp\connector.py", line 901, in _create_connection
    _, proto = await self._create_direct_connection(req, traces, timeout)
  File "C:\Users\Михаил\PycharmProjects\football_discordBot\venv\lib\site-packages\aiohttp\connector.py", line 1166, in _create_direct_connection
    raise ClientConnectorError(req.connection_key, exc) from exc
aiohttp.client_exceptions.ClientConnectorError: Cannot connect to host gateway-us-east1-b.discord.gg:443 ssl:default [getaddrinfo failed]
[23-01-27 15:44:07] [client.py ERROR] Attempting a reconnect in 48.89s
Traceback (most recent call last):
  File "C:\Users\Михаил\PycharmProjects\football_discordBot\venv\lib\site-packages\aiohttp\connector.py", line 1152, in _create_direct_connection
    hosts = await asyncio.shield(host_resolved)
  File "C:\Users\Михаил\PycharmProjects\football_discordBot\venv\lib\site-packages\aiohttp\connector.py", line 874, in _resolve_host
    addrs = await self._resolver.resolve(host, port, family=self._family)
  File "C:\Users\Михаил\PycharmProjects\football_discordBot\venv\lib\site-packages\aiohttp\resolver.py", line 33, in resolve
    infos = await self._loop.getaddrinfo(
  File "C:\Users\Михаил\AppData\Local\Programs\Python\Python310\lib\asyncio\base_events.py", line 860, in getaddrinfo
    return await self.run_in_executor(
  File "C:\Users\Михаил\AppData\Local\Programs\Python\Python310\lib\concurrent\futures\thread.py", line 58, in run
    result = self.fn(*self.args, **self.kwargs)
  File "C:\Users\Михаил\AppData\Local\Programs\Python\Python310\lib\socket.py", line 955, in getaddrinfo
    for res in _socket.getaddrinfo(host, port, family, type, proto, flags):
socket.gaierror: [Errno 11004] getaddrinfo failed

The above exception was the direct cause of the following exception:

Traceback (most recent call last):
  File "C:\Users\Михаил\PycharmProjects\football_discordBot\venv\lib\site-packages\nextcord\client.py", line 708, in connect
    self.ws = await asyncio.wait_for(coro, timeout=60.0)
  File "C:\Users\Михаил\AppData\Local\Programs\Python\Python310\lib\asyncio\tasks.py", line 445, in wait_for
    return fut.result()
  File "C:\Users\Михаил\PycharmProjects\football_discordBot\venv\lib\site-packages\nextcord\gateway.py", line 365, in from_client
    socket = await client.http.ws_connect(gateway)
  File "C:\Users\Михаил\PycharmProjects\football_discordBot\venv\lib\site-packages\nextcord\http.py", line 250, in ws_connect
    return await self.__session.ws_connect(url, **kwargs)
  File "C:\Users\Михаил\PycharmProjects\football_discordBot\venv\lib\site-packages\aiohttp\client.py", line 779, in _ws_connect
    resp = await self.request(
  File "C:\Users\Михаил\PycharmProjects\football_discordBot\venv\lib\site-packages\aiohttp\client.py", line 536, in _request
    conn = await self._connector.connect(
  File "C:\Users\Михаил\PycharmProjects\football_discordBot\venv\lib\site-packages\aiohttp\connector.py", line 540, in connect
    proto = await self._create_connection(req, traces, timeout)
  File "C:\Users\Михаил\PycharmProjects\football_discordBot\venv\lib\site-packages\aiohttp\connector.py", line 901, in _create_connection
    _, proto = await self._create_direct_connection(req, traces, timeout)
  File "C:\Users\Михаил\PycharmProjects\football_discordBot\venv\lib\site-packages\aiohttp\connector.py", line 1166, in _create_direct_connection
    raise ClientConnectorError(req.connection_key, exc) from exc
aiohttp.client_exceptions.ClientConnectorError: Cannot connect to host gateway-us-east1-b.discord.gg:443 ssl:default [getaddrinfo failed]
[23-01-27 15:44:56] [client.py ERROR] Attempting a reconnect in 230.83s
Traceback (most recent call last):
  File "C:\Users\Михаил\PycharmProjects\football_discordBot\venv\lib\site-packages\aiohttp\connector.py", line 1152, in _create_direct_connection
    hosts = await asyncio.shield(host_resolved)
  File "C:\Users\Михаил\PycharmProjects\football_discordBot\venv\lib\site-packages\aiohttp\connector.py", line 874, in _resolve_host
    addrs = await self._resolver.resolve(host, port, family=self._family)
  File "C:\Users\Михаил\PycharmProjects\football_discordBot\venv\lib\site-packages\aiohttp\resolver.py", line 33, in resolve
    infos = await self._loop.getaddrinfo(
  File "C:\Users\Михаил\AppData\Local\Programs\Python\Python310\lib\asyncio\base_events.py", line 860, in getaddrinfo
    return await self.run_in_executor(
  File "C:\Users\Михаил\AppData\Local\Programs\Python\Python310\lib\concurrent\futures\thread.py", line 58, in run
    result = self.fn(*self.args, **self.kwargs)
  File "C:\Users\Михаил\AppData\Local\Programs\Python\Python310\lib\socket.py", line 955, in getaddrinfo
    for res in _socket.getaddrinfo(host, port, family, type, proto, flags):
socket.gaierror: [Errno 11004] getaddrinfo failed

The above exception was the direct cause of the following exception:

Traceback (most recent call last):
  File "C:\Users\Михаил\PycharmProjects\football_discordBot\venv\lib\site-packages\nextcord\client.py", line 708, in connect
    self.ws = await asyncio.wait_for(coro, timeout=60.0)
  File "C:\Users\Михаил\AppData\Local\Programs\Python\Python310\lib\asyncio\tasks.py", line 445, in wait_for
    return fut.result()
  File "C:\Users\Михаил\PycharmProjects\football_discordBot\venv\lib\site-packages\nextcord\gateway.py", line 365, in from_client
    socket = await client.http.ws_connect(gateway)
  File "C:\Users\Михаил\PycharmProjects\football_discordBot\venv\lib\site-packages\nextcord\http.py", line 250, in ws_connect
    return await self.__session.ws_connect(url, **kwargs)
  File "C:\Users\Михаил\PycharmProjects\football_discordBot\venv\lib\site-packages\aiohttp\client.py", line 779, in _ws_connect
    resp = await self.request(
  File "C:\Users\Михаил\PycharmProjects\football_discordBot\venv\lib\site-packages\aiohttp\client.py", line 536, in _request
    conn = await self._connector.connect(
  File "C:\Users\Михаил\PycharmProjects\football_discordBot\venv\lib\site-packages\aiohttp\connector.py", line 540, in connect
    proto = await self._create_connection(req, traces, timeout)
  File "C:\Users\Михаил\PycharmProjects\football_discordBot\venv\lib\site-packages\aiohttp\connector.py", line 901, in _create_connection
    _, proto = await self._create_direct_connection(req, traces, timeout)
  File "C:\Users\Михаил\PycharmProjects\football_discordBot\venv\lib\site-packages\aiohttp\connector.py", line 1166, in _create_direct_connection
    raise ClientConnectorError(req.connection_key, exc) from exc
aiohttp.client_exceptions.ClientConnectorError: Cannot connect to host gateway-us-east1-b.discord.gg:443 ssl:default [getaddrinfo failed]
[23-01-27 15:48:47] [client.py ERROR] Attempting a reconnect in 252.50s
Traceback (most recent call last):
  File "C:\Users\Михаил\PycharmProjects\football_discordBot\venv\lib\site-packages\aiohttp\connector.py", line 1152, in _create_direct_connection
    hosts = await asyncio.shield(host_resolved)
  File "C:\Users\Михаил\PycharmProjects\football_discordBot\venv\lib\site-packages\aiohttp\connector.py", line 874, in _resolve_host
    addrs = await self._resolver.resolve(host, port, family=self._family)
  File "C:\Users\Михаил\PycharmProjects\football_discordBot\venv\lib\site-packages\aiohttp\resolver.py", line 33, in resolve
    infos = await self._loop.getaddrinfo(
  File "C:\Users\Михаил\AppData\Local\Programs\Python\Python310\lib\asyncio\base_events.py", line 860, in getaddrinfo
    return await self.run_in_executor(
  File "C:\Users\Михаил\AppData\Local\Programs\Python\Python310\lib\concurrent\futures\thread.py", line 58, in run
    result = self.fn(*self.args, **self.kwargs)
  File "C:\Users\Михаил\AppData\Local\Programs\Python\Python310\lib\socket.py", line 955, in getaddrinfo
    for res in _socket.getaddrinfo(host, port, family, type, proto, flags):
socket.gaierror: [Errno 11004] getaddrinfo failed

The above exception was the direct cause of the following exception:

Traceback (most recent call last):
  File "C:\Users\Михаил\PycharmProjects\football_discordBot\venv\lib\site-packages\nextcord\client.py", line 708, in connect
    self.ws = await asyncio.wait_for(coro, timeout=60.0)
  File "C:\Users\Михаил\AppData\Local\Programs\Python\Python310\lib\asyncio\tasks.py", line 445, in wait_for
    return fut.result()
  File "C:\Users\Михаил\PycharmProjects\football_discordBot\venv\lib\site-packages\nextcord\gateway.py", line 365, in from_client
    socket = await client.http.ws_connect(gateway)
  File "C:\Users\Михаил\PycharmProjects\football_discordBot\venv\lib\site-packages\nextcord\http.py", line 250, in ws_connect
    return await self.__session.ws_connect(url, **kwargs)
  File "C:\Users\Михаил\PycharmProjects\football_discordBot\venv\lib\site-packages\aiohttp\client.py", line 779, in _ws_connect
    resp = await self.request(
  File "C:\Users\Михаил\PycharmProjects\football_discordBot\venv\lib\site-packages\aiohttp\client.py", line 536, in _request
    conn = await self._connector.connect(
  File "C:\Users\Михаил\PycharmProjects\football_discordBot\venv\lib\site-packages\aiohttp\connector.py", line 540, in connect
    proto = await self._create_connection(req, traces, timeout)
  File "C:\Users\Михаил\PycharmProjects\football_discordBot\venv\lib\site-packages\aiohttp\connector.py", line 901, in _create_connection
    _, proto = await self._create_direct_connection(req, traces, timeout)
  File "C:\Users\Михаил\PycharmProjects\football_discordBot\venv\lib\site-packages\aiohttp\connector.py", line 1166, in _create_direct_connection
    raise ClientConnectorError(req.connection_key, exc) from exc
aiohttp.client_exceptions.ClientConnectorError: Cannot connect to host gateway-us-east1-b.discord.gg:443 ssl:default [getaddrinfo failed]
[23-01-27 15:52:59] [client.py ERROR] Attempting a reconnect in 114.61s
Traceback (most recent call last):
  File "C:\Users\Михаил\PycharmProjects\football_discordBot\venv\lib\site-packages\aiohttp\connector.py", line 1152, in _create_direct_connection
    hosts = await asyncio.shield(host_resolved)
  File "C:\Users\Михаил\PycharmProjects\football_discordBot\venv\lib\site-packages\aiohttp\connector.py", line 874, in _resolve_host
    addrs = await self._resolver.resolve(host, port, family=self._family)
  File "C:\Users\Михаил\PycharmProjects\football_discordBot\venv\lib\site-packages\aiohttp\resolver.py", line 33, in resolve
    infos = await self._loop.getaddrinfo(
  File "C:\Users\Михаил\AppData\Local\Programs\Python\Python310\lib\asyncio\base_events.py", line 860, in getaddrinfo
    return await self.run_in_executor(
  File "C:\Users\Михаил\AppData\Local\Programs\Python\Python310\lib\concurrent\futures\thread.py", line 58, in run
    result = self.fn(*self.args, **self.kwargs)
  File "C:\Users\Михаил\AppData\Local\Programs\Python\Python310\lib\socket.py", line 955, in getaddrinfo
    for res in _socket.getaddrinfo(host, port, family, type, proto, flags):
socket.gaierror: [Errno 11004] getaddrinfo failed

The above exception was the direct cause of the following exception:

Traceback (most recent call last):
  File "C:\Users\Михаил\PycharmProjects\football_discordBot\venv\lib\site-packages\nextcord\client.py", line 708, in connect
    self.ws = await asyncio.wait_for(coro, timeout=60.0)
  File "C:\Users\Михаил\AppData\Local\Programs\Python\Python310\lib\asyncio\tasks.py", line 445, in wait_for
    return fut.result()
  File "C:\Users\Михаил\PycharmProjects\football_discordBot\venv\lib\site-packages\nextcord\gateway.py", line 365, in from_client
    socket = await client.http.ws_connect(gateway)
  File "C:\Users\Михаил\PycharmProjects\football_discordBot\venv\lib\site-packages\nextcord\http.py", line 250, in ws_connect
    return await self.__session.ws_connect(url, **kwargs)
  File "C:\Users\Михаил\PycharmProjects\football_discordBot\venv\lib\site-packages\aiohttp\client.py", line 779, in _ws_connect
    resp = await self.request(
  File "C:\Users\Михаил\PycharmProjects\football_discordBot\venv\lib\site-packages\aiohttp\client.py", line 536, in _request
    conn = await self._connector.connect(
  File "C:\Users\Михаил\PycharmProjects\football_discordBot\venv\lib\site-packages\aiohttp\connector.py", line 540, in connect
    proto = await self._create_connection(req, traces, timeout)
  File "C:\Users\Михаил\PycharmProjects\football_discordBot\venv\lib\site-packages\aiohttp\connector.py", line 901, in _create_connection
    _, proto = await self._create_direct_connection(req, traces, timeout)
  File "C:\Users\Михаил\PycharmProjects\football_discordBot\venv\lib\site-packages\aiohttp\connector.py", line 1166, in _create_direct_connection
    raise ClientConnectorError(req.connection_key, exc) from exc
aiohttp.client_exceptions.ClientConnectorError: Cannot connect to host gateway-us-east1-b.discord.gg:443 ssl:default [getaddrinfo failed]
[23-01-27 15:54:54] [client.py ERROR] Attempting a reconnect in 789.77s
Traceback (most recent call last):
  File "C:\Users\Михаил\PycharmProjects\football_discordBot\venv\lib\site-packages\aiohttp\connector.py", line 1152, in _create_direct_connection
    hosts = await asyncio.shield(host_resolved)
  File "C:\Users\Михаил\PycharmProjects\football_discordBot\venv\lib\site-packages\aiohttp\connector.py", line 874, in _resolve_host
    addrs = await self._resolver.resolve(host, port, family=self._family)
  File "C:\Users\Михаил\PycharmProjects\football_discordBot\venv\lib\site-packages\aiohttp\resolver.py", line 33, in resolve
    infos = await self._loop.getaddrinfo(
  File "C:\Users\Михаил\AppData\Local\Programs\Python\Python310\lib\asyncio\base_events.py", line 860, in getaddrinfo
    return await self.run_in_executor(
  File "C:\Users\Михаил\AppData\Local\Programs\Python\Python310\lib\concurrent\futures\thread.py", line 58, in run
    result = self.fn(*self.args, **self.kwargs)
  File "C:\Users\Михаил\AppData\Local\Programs\Python\Python310\lib\socket.py", line 955, in getaddrinfo
    for res in _socket.getaddrinfo(host, port, family, type, proto, flags):
socket.gaierror: [Errno 11004] getaddrinfo failed

The above exception was the direct cause of the following exception:

Traceback (most recent call last):
  File "C:\Users\Михаил\PycharmProjects\football_discordBot\venv\lib\site-packages\nextcord\client.py", line 708, in connect
    self.ws = await asyncio.wait_for(coro, timeout=60.0)
  File "C:\Users\Михаил\AppData\Local\Programs\Python\Python310\lib\asyncio\tasks.py", line 445, in wait_for
    return fut.result()
  File "C:\Users\Михаил\PycharmProjects\football_discordBot\venv\lib\site-packages\nextcord\gateway.py", line 365, in from_client
    socket = await client.http.ws_connect(gateway)
  File "C:\Users\Михаил\PycharmProjects\football_discordBot\venv\lib\site-packages\nextcord\http.py", line 250, in ws_connect
    return await self.__session.ws_connect(url, **kwargs)
  File "C:\Users\Михаил\PycharmProjects\football_discordBot\venv\lib\site-packages\aiohttp\client.py", line 779, in _ws_connect
    resp = await self.request(
  File "C:\Users\Михаил\PycharmProjects\football_discordBot\venv\lib\site-packages\aiohttp\client.py", line 536, in _request
    conn = await self._connector.connect(
  File "C:\Users\Михаил\PycharmProjects\football_discordBot\venv\lib\site-packages\aiohttp\connector.py", line 540, in connect
    proto = await self._create_connection(req, traces, timeout)
  File "C:\Users\Михаил\PycharmProjects\football_discordBot\venv\lib\site-packages\aiohttp\connector.py", line 901, in _create_connection
    _, proto = await self._create_direct_connection(req, traces, timeout)
  File "C:\Users\Михаил\PycharmProjects\football_discordBot\venv\lib\site-packages\aiohttp\connector.py", line 1166, in _create_direct_connection
    raise ClientConnectorError(req.connection_key, exc) from exc
aiohttp.client_exceptions.ClientConnectorError: Cannot connect to host gateway-us-east1-b.discord.gg:443 ssl:default [getaddrinfo failed]
[23-01-27 16:41:43] [gateway.py WARNING] Can't keep up, shard ID None websocket is 10.7s behind.
[23-01-27 17:03:47] [gateway.py WARNING] Can't keep up, shard ID None websocket is 10.3s behind.
[23-01-27 17:07:22] [client.py ERROR] Attempting a reconnect in 1.18s
Traceback (most recent call last):
  File "C:\Users\Михаил\PycharmProjects\football_discordBot\venv\lib\site-packages\aiohttp\connector.py", line 1152, in _create_direct_connection
    hosts = await asyncio.shield(host_resolved)
  File "C:\Users\Михаил\PycharmProjects\football_discordBot\venv\lib\site-packages\aiohttp\connector.py", line 874, in _resolve_host
    addrs = await self._resolver.resolve(host, port, family=self._family)
  File "C:\Users\Михаил\PycharmProjects\football_discordBot\venv\lib\site-packages\aiohttp\resolver.py", line 33, in resolve
    infos = await self._loop.getaddrinfo(
  File "C:\Users\Михаил\AppData\Local\Programs\Python\Python310\lib\asyncio\base_events.py", line 860, in getaddrinfo
    return await self.run_in_executor(
  File "C:\Users\Михаил\AppData\Local\Programs\Python\Python310\lib\concurrent\futures\thread.py", line 58, in run
    result = self.fn(*self.args, **self.kwargs)
  File "C:\Users\Михаил\AppData\Local\Programs\Python\Python310\lib\socket.py", line 955, in getaddrinfo
    for res in _socket.getaddrinfo(host, port, family, type, proto, flags):
socket.gaierror: [Errno 11004] getaddrinfo failed

The above exception was the direct cause of the following exception:

Traceback (most recent call last):
  File "C:\Users\Михаил\PycharmProjects\football_discordBot\venv\lib\site-packages\nextcord\client.py", line 708, in connect
    self.ws = await asyncio.wait_for(coro, timeout=60.0)
  File "C:\Users\Михаил\AppData\Local\Programs\Python\Python310\lib\asyncio\tasks.py", line 445, in wait_for
    return fut.result()
  File "C:\Users\Михаил\PycharmProjects\football_discordBot\venv\lib\site-packages\nextcord\gateway.py", line 365, in from_client
    socket = await client.http.ws_connect(gateway)
  File "C:\Users\Михаил\PycharmProjects\football_discordBot\venv\lib\site-packages\nextcord\http.py", line 250, in ws_connect
    return await self.__session.ws_connect(url, **kwargs)
  File "C:\Users\Михаил\PycharmProjects\football_discordBot\venv\lib\site-packages\aiohttp\client.py", line 779, in _ws_connect
    resp = await self.request(
  File "C:\Users\Михаил\PycharmProjects\football_discordBot\venv\lib\site-packages\aiohttp\client.py", line 536, in _request
    conn = await self._connector.connect(
  File "C:\Users\Михаил\PycharmProjects\football_discordBot\venv\lib\site-packages\aiohttp\connector.py", line 540, in connect
    proto = await self._create_connection(req, traces, timeout)
  File "C:\Users\Михаил\PycharmProjects\football_discordBot\venv\lib\site-packages\aiohttp\connector.py", line 901, in _create_connection
    _, proto = await self._create_direct_connection(req, traces, timeout)
  File "C:\Users\Михаил\PycharmProjects\football_discordBot\venv\lib\site-packages\aiohttp\connector.py", line 1166, in _create_direct_connection
    raise ClientConnectorError(req.connection_key, exc) from exc
aiohttp.client_exceptions.ClientConnectorError: Cannot connect to host gateway-us-east1-b.discord.gg:443 ssl:default [getaddrinfo failed]
[23-01-27 17:07:23] [client.py ERROR] Attempting a reconnect in 1.46s
Traceback (most recent call last):
  File "C:\Users\Михаил\PycharmProjects\football_discordBot\venv\lib\site-packages\aiohttp\connector.py", line 1152, in _create_direct_connection
    hosts = await asyncio.shield(host_resolved)
  File "C:\Users\Михаил\PycharmProjects\football_discordBot\venv\lib\site-packages\aiohttp\connector.py", line 874, in _resolve_host
    addrs = await self._resolver.resolve(host, port, family=self._family)
  File "C:\Users\Михаил\PycharmProjects\football_discordBot\venv\lib\site-packages\aiohttp\resolver.py", line 33, in resolve
    infos = await self._loop.getaddrinfo(
  File "C:\Users\Михаил\AppData\Local\Programs\Python\Python310\lib\asyncio\base_events.py", line 860, in getaddrinfo
    return await self.run_in_executor(
  File "C:\Users\Михаил\AppData\Local\Programs\Python\Python310\lib\concurrent\futures\thread.py", line 58, in run
    result = self.fn(*self.args, **self.kwargs)
  File "C:\Users\Михаил\AppData\Local\Programs\Python\Python310\lib\socket.py", line 955, in getaddrinfo
    for res in _socket.getaddrinfo(host, port, family, type, proto, flags):
socket.gaierror: [Errno 11004] getaddrinfo failed

The above exception was the direct cause of the following exception:

Traceback (most recent call last):
  File "C:\Users\Михаил\PycharmProjects\football_discordBot\venv\lib\site-packages\nextcord\client.py", line 708, in connect
    self.ws = await asyncio.wait_for(coro, timeout=60.0)
  File "C:\Users\Михаил\AppData\Local\Programs\Python\Python310\lib\asyncio\tasks.py", line 445, in wait_for
    return fut.result()
  File "C:\Users\Михаил\PycharmProjects\football_discordBot\venv\lib\site-packages\nextcord\gateway.py", line 365, in from_client
    socket = await client.http.ws_connect(gateway)
  File "C:\Users\Михаил\PycharmProjects\football_discordBot\venv\lib\site-packages\nextcord\http.py", line 250, in ws_connect
    return await self.__session.ws_connect(url, **kwargs)
  File "C:\Users\Михаил\PycharmProjects\football_discordBot\venv\lib\site-packages\aiohttp\client.py", line 779, in _ws_connect
    resp = await self.request(
  File "C:\Users\Михаил\PycharmProjects\football_discordBot\venv\lib\site-packages\aiohttp\client.py", line 536, in _request
    conn = await self._connector.connect(
  File "C:\Users\Михаил\PycharmProjects\football_discordBot\venv\lib\site-packages\aiohttp\connector.py", line 540, in connect
    proto = await self._create_connection(req, traces, timeout)
  File "C:\Users\Михаил\PycharmProjects\football_discordBot\venv\lib\site-packages\aiohttp\connector.py", line 901, in _create_connection
    _, proto = await self._create_direct_connection(req, traces, timeout)
  File "C:\Users\Михаил\PycharmProjects\football_discordBot\venv\lib\site-packages\aiohttp\connector.py", line 1166, in _create_direct_connection
    raise ClientConnectorError(req.connection_key, exc) from exc
aiohttp.client_exceptions.ClientConnectorError: Cannot connect to host gateway-us-east1-b.discord.gg:443 ssl:default [getaddrinfo failed]
[23-01-27 17:07:25] [client.py ERROR] Attempting a reconnect in 7.47s
Traceback (most recent call last):
  File "C:\Users\Михаил\PycharmProjects\football_discordBot\venv\lib\site-packages\aiohttp\connector.py", line 1152, in _create_direct_connection
    hosts = await asyncio.shield(host_resolved)
  File "C:\Users\Михаил\PycharmProjects\football_discordBot\venv\lib\site-packages\aiohttp\connector.py", line 874, in _resolve_host
    addrs = await self._resolver.resolve(host, port, family=self._family)
  File "C:\Users\Михаил\PycharmProjects\football_discordBot\venv\lib\site-packages\aiohttp\resolver.py", line 33, in resolve
    infos = await self._loop.getaddrinfo(
  File "C:\Users\Михаил\AppData\Local\Programs\Python\Python310\lib\asyncio\base_events.py", line 860, in getaddrinfo
    return await self.run_in_executor(
  File "C:\Users\Михаил\AppData\Local\Programs\Python\Python310\lib\concurrent\futures\thread.py", line 58, in run
    result = self.fn(*self.args, **self.kwargs)
  File "C:\Users\Михаил\AppData\Local\Programs\Python\Python310\lib\socket.py", line 955, in getaddrinfo
    for res in _socket.getaddrinfo(host, port, family, type, proto, flags):
socket.gaierror: [Errno 11004] getaddrinfo failed

The above exception was the direct cause of the following exception:

Traceback (most recent call last):
  File "C:\Users\Михаил\PycharmProjects\football_discordBot\venv\lib\site-packages\nextcord\client.py", line 708, in connect
    self.ws = await asyncio.wait_for(coro, timeout=60.0)
  File "C:\Users\Михаил\AppData\Local\Programs\Python\Python310\lib\asyncio\tasks.py", line 445, in wait_for
    return fut.result()
  File "C:\Users\Михаил\PycharmProjects\football_discordBot\venv\lib\site-packages\nextcord\gateway.py", line 365, in from_client
    socket = await client.http.ws_connect(gateway)
  File "C:\Users\Михаил\PycharmProjects\football_discordBot\venv\lib\site-packages\nextcord\http.py", line 250, in ws_connect
    return await self.__session.ws_connect(url, **kwargs)
  File "C:\Users\Михаил\PycharmProjects\football_discordBot\venv\lib\site-packages\aiohttp\client.py", line 779, in _ws_connect
    resp = await self.request(
  File "C:\Users\Михаил\PycharmProjects\football_discordBot\venv\lib\site-packages\aiohttp\client.py", line 536, in _request
    conn = await self._connector.connect(
  File "C:\Users\Михаил\PycharmProjects\football_discordBot\venv\lib\site-packages\aiohttp\connector.py", line 540, in connect
    proto = await self._create_connection(req, traces, timeout)
  File "C:\Users\Михаил\PycharmProjects\football_discordBot\venv\lib\site-packages\aiohttp\connector.py", line 901, in _create_connection
    _, proto = await self._create_direct_connection(req, traces, timeout)
  File "C:\Users\Михаил\PycharmProjects\football_discordBot\venv\lib\site-packages\aiohttp\connector.py", line 1166, in _create_direct_connection
    raise ClientConnectorError(req.connection_key, exc) from exc
aiohttp.client_exceptions.ClientConnectorError: Cannot connect to host gateway-us-east1-b.discord.gg:443 ssl:default [getaddrinfo failed]
[23-01-27 17:07:32] [client.py ERROR] Attempting a reconnect in 2.58s
Traceback (most recent call last):
  File "C:\Users\Михаил\PycharmProjects\football_discordBot\venv\lib\site-packages\aiohttp\connector.py", line 1152, in _create_direct_connection
    hosts = await asyncio.shield(host_resolved)
  File "C:\Users\Михаил\PycharmProjects\football_discordBot\venv\lib\site-packages\aiohttp\connector.py", line 874, in _resolve_host
    addrs = await self._resolver.resolve(host, port, family=self._family)
  File "C:\Users\Михаил\PycharmProjects\football_discordBot\venv\lib\site-packages\aiohttp\resolver.py", line 33, in resolve
    infos = await self._loop.getaddrinfo(
  File "C:\Users\Михаил\AppData\Local\Programs\Python\Python310\lib\asyncio\base_events.py", line 860, in getaddrinfo
    return await self.run_in_executor(
  File "C:\Users\Михаил\AppData\Local\Programs\Python\Python310\lib\concurrent\futures\thread.py", line 58, in run
    result = self.fn(*self.args, **self.kwargs)
  File "C:\Users\Михаил\AppData\Local\Programs\Python\Python310\lib\socket.py", line 955, in getaddrinfo
    for res in _socket.getaddrinfo(host, port, family, type, proto, flags):
socket.gaierror: [Errno 11004] getaddrinfo failed

The above exception was the direct cause of the following exception:

Traceback (most recent call last):
  File "C:\Users\Михаил\PycharmProjects\football_discordBot\venv\lib\site-packages\nextcord\client.py", line 708, in connect
    self.ws = await asyncio.wait_for(coro, timeout=60.0)
  File "C:\Users\Михаил\AppData\Local\Programs\Python\Python310\lib\asyncio\tasks.py", line 445, in wait_for
    return fut.result()
  File "C:\Users\Михаил\PycharmProjects\football_discordBot\venv\lib\site-packages\nextcord\gateway.py", line 365, in from_client
    socket = await client.http.ws_connect(gateway)
  File "C:\Users\Михаил\PycharmProjects\football_discordBot\venv\lib\site-packages\nextcord\http.py", line 250, in ws_connect
    return await self.__session.ws_connect(url, **kwargs)
  File "C:\Users\Михаил\PycharmProjects\football_discordBot\venv\lib\site-packages\aiohttp\client.py", line 779, in _ws_connect
    resp = await self.request(
  File "C:\Users\Михаил\PycharmProjects\football_discordBot\venv\lib\site-packages\aiohttp\client.py", line 536, in _request
    conn = await self._connector.connect(
  File "C:\Users\Михаил\PycharmProjects\football_discordBot\venv\lib\site-packages\aiohttp\connector.py", line 540, in connect
    proto = await self._create_connection(req, traces, timeout)
  File "C:\Users\Михаил\PycharmProjects\football_discordBot\venv\lib\site-packages\aiohttp\connector.py", line 901, in _create_connection
    _, proto = await self._create_direct_connection(req, traces, timeout)
  File "C:\Users\Михаил\PycharmProjects\football_discordBot\venv\lib\site-packages\aiohttp\connector.py", line 1166, in _create_direct_connection
    raise ClientConnectorError(req.connection_key, exc) from exc
aiohttp.client_exceptions.ClientConnectorError: Cannot connect to host gateway-us-east1-b.discord.gg:443 ssl:default [getaddrinfo failed]
[23-01-27 17:07:35] [client.py ERROR] Attempting a reconnect in 22.31s
Traceback (most recent call last):
  File "C:\Users\Михаил\PycharmProjects\football_discordBot\venv\lib\site-packages\aiohttp\connector.py", line 1152, in _create_direct_connection
    hosts = await asyncio.shield(host_resolved)
  File "C:\Users\Михаил\PycharmProjects\football_discordBot\venv\lib\site-packages\aiohttp\connector.py", line 874, in _resolve_host
    addrs = await self._resolver.resolve(host, port, family=self._family)
  File "C:\Users\Михаил\PycharmProjects\football_discordBot\venv\lib\site-packages\aiohttp\resolver.py", line 33, in resolve
    infos = await self._loop.getaddrinfo(
  File "C:\Users\Михаил\AppData\Local\Programs\Python\Python310\lib\asyncio\base_events.py", line 860, in getaddrinfo
    return await self.run_in_executor(
  File "C:\Users\Михаил\AppData\Local\Programs\Python\Python310\lib\concurrent\futures\thread.py", line 58, in run
    result = self.fn(*self.args, **self.kwargs)
  File "C:\Users\Михаил\AppData\Local\Programs\Python\Python310\lib\socket.py", line 955, in getaddrinfo
    for res in _socket.getaddrinfo(host, port, family, type, proto, flags):
socket.gaierror: [Errno 11004] getaddrinfo failed

The above exception was the direct cause of the following exception:

Traceback (most recent call last):
  File "C:\Users\Михаил\PycharmProjects\football_discordBot\venv\lib\site-packages\nextcord\client.py", line 708, in connect
    self.ws = await asyncio.wait_for(coro, timeout=60.0)
  File "C:\Users\Михаил\AppData\Local\Programs\Python\Python310\lib\asyncio\tasks.py", line 445, in wait_for
    return fut.result()
  File "C:\Users\Михаил\PycharmProjects\football_discordBot\venv\lib\site-packages\nextcord\gateway.py", line 365, in from_client
    socket = await client.http.ws_connect(gateway)
  File "C:\Users\Михаил\PycharmProjects\football_discordBot\venv\lib\site-packages\nextcord\http.py", line 250, in ws_connect
    return await self.__session.ws_connect(url, **kwargs)
  File "C:\Users\Михаил\PycharmProjects\football_discordBot\venv\lib\site-packages\aiohttp\client.py", line 779, in _ws_connect
    resp = await self.request(
  File "C:\Users\Михаил\PycharmProjects\football_discordBot\venv\lib\site-packages\aiohttp\client.py", line 536, in _request
    conn = await self._connector.connect(
  File "C:\Users\Михаил\PycharmProjects\football_discordBot\venv\lib\site-packages\aiohttp\connector.py", line 540, in connect
    proto = await self._create_connection(req, traces, timeout)
  File "C:\Users\Михаил\PycharmProjects\football_discordBot\venv\lib\site-packages\aiohttp\connector.py", line 901, in _create_connection
    _, proto = await self._create_direct_connection(req, traces, timeout)
  File "C:\Users\Михаил\PycharmProjects\football_discordBot\venv\lib\site-packages\aiohttp\connector.py", line 1166, in _create_direct_connection
    raise ClientConnectorError(req.connection_key, exc) from exc
aiohttp.client_exceptions.ClientConnectorError: Cannot connect to host gateway-us-east1-b.discord.gg:443 ssl:default [getaddrinfo failed]
[23-01-27 17:07:57] [client.py ERROR] Attempting a reconnect in 23.60s
Traceback (most recent call last):
  File "C:\Users\Михаил\PycharmProjects\football_discordBot\venv\lib\site-packages\aiohttp\connector.py", line 1152, in _create_direct_connection
    hosts = await asyncio.shield(host_resolved)
  File "C:\Users\Михаил\PycharmProjects\football_discordBot\venv\lib\site-packages\aiohttp\connector.py", line 874, in _resolve_host
    addrs = await self._resolver.resolve(host, port, family=self._family)
  File "C:\Users\Михаил\PycharmProjects\football_discordBot\venv\lib\site-packages\aiohttp\resolver.py", line 33, in resolve
    infos = await self._loop.getaddrinfo(
  File "C:\Users\Михаил\AppData\Local\Programs\Python\Python310\lib\asyncio\base_events.py", line 860, in getaddrinfo
    return await self.run_in_executor(
  File "C:\Users\Михаил\AppData\Local\Programs\Python\Python310\lib\concurrent\futures\thread.py", line 58, in run
    result = self.fn(*self.args, **self.kwargs)
  File "C:\Users\Михаил\AppData\Local\Programs\Python\Python310\lib\socket.py", line 955, in getaddrinfo
    for res in _socket.getaddrinfo(host, port, family, type, proto, flags):
socket.gaierror: [Errno 11004] getaddrinfo failed

The above exception was the direct cause of the following exception:

Traceback (most recent call last):
  File "C:\Users\Михаил\PycharmProjects\football_discordBot\venv\lib\site-packages\nextcord\client.py", line 708, in connect
    self.ws = await asyncio.wait_for(coro, timeout=60.0)
  File "C:\Users\Михаил\AppData\Local\Programs\Python\Python310\lib\asyncio\tasks.py", line 445, in wait_for
    return fut.result()
  File "C:\Users\Михаил\PycharmProjects\football_discordBot\venv\lib\site-packages\nextcord\gateway.py", line 365, in from_client
    socket = await client.http.ws_connect(gateway)
  File "C:\Users\Михаил\PycharmProjects\football_discordBot\venv\lib\site-packages\nextcord\http.py", line 250, in ws_connect
    return await self.__session.ws_connect(url, **kwargs)
  File "C:\Users\Михаил\PycharmProjects\football_discordBot\venv\lib\site-packages\aiohttp\client.py", line 779, in _ws_connect
    resp = await self.request(
  File "C:\Users\Михаил\PycharmProjects\football_discordBot\venv\lib\site-packages\aiohttp\client.py", line 536, in _request
    conn = await self._connector.connect(
  File "C:\Users\Михаил\PycharmProjects\football_discordBot\venv\lib\site-packages\aiohttp\connector.py", line 540, in connect
    proto = await self._create_connection(req, traces, timeout)
  File "C:\Users\Михаил\PycharmProjects\football_discordBot\venv\lib\site-packages\aiohttp\connector.py", line 901, in _create_connection
    _, proto = await self._create_direct_connection(req, traces, timeout)
  File "C:\Users\Михаил\PycharmProjects\football_discordBot\venv\lib\site-packages\aiohttp\connector.py", line 1166, in _create_direct_connection
    raise ClientConnectorError(req.connection_key, exc) from exc
aiohttp.client_exceptions.ClientConnectorError: Cannot connect to host gateway-us-east1-b.discord.gg:443 ssl:default [getaddrinfo failed]
[23-01-27 17:08:21] [client.py ERROR] Attempting a reconnect in 23.51s
Traceback (most recent call last):
  File "C:\Users\Михаил\PycharmProjects\football_discordBot\venv\lib\site-packages\aiohttp\connector.py", line 1152, in _create_direct_connection
    hosts = await asyncio.shield(host_resolved)
  File "C:\Users\Михаил\PycharmProjects\football_discordBot\venv\lib\site-packages\aiohttp\connector.py", line 874, in _resolve_host
    addrs = await self._resolver.resolve(host, port, family=self._family)
  File "C:\Users\Михаил\PycharmProjects\football_discordBot\venv\lib\site-packages\aiohttp\resolver.py", line 33, in resolve
    infos = await self._loop.getaddrinfo(
  File "C:\Users\Михаил\AppData\Local\Programs\Python\Python310\lib\asyncio\base_events.py", line 860, in getaddrinfo
    return await self.run_in_executor(
  File "C:\Users\Михаил\AppData\Local\Programs\Python\Python310\lib\concurrent\futures\thread.py", line 58, in run
    result = self.fn(*self.args, **self.kwargs)
  File "C:\Users\Михаил\AppData\Local\Programs\Python\Python310\lib\socket.py", line 955, in getaddrinfo
    for res in _socket.getaddrinfo(host, port, family, type, proto, flags):
socket.gaierror: [Errno 11004] getaddrinfo failed

The above exception was the direct cause of the following exception:

Traceback (most recent call last):
  File "C:\Users\Михаил\PycharmProjects\football_discordBot\venv\lib\site-packages\nextcord\client.py", line 708, in connect
    self.ws = await asyncio.wait_for(coro, timeout=60.0)
  File "C:\Users\Михаил\AppData\Local\Programs\Python\Python310\lib\asyncio\tasks.py", line 445, in wait_for
    return fut.result()
  File "C:\Users\Михаил\PycharmProjects\football_discordBot\venv\lib\site-packages\nextcord\gateway.py", line 365, in from_client
    socket = await client.http.ws_connect(gateway)
  File "C:\Users\Михаил\PycharmProjects\football_discordBot\venv\lib\site-packages\nextcord\http.py", line 250, in ws_connect
    return await self.__session.ws_connect(url, **kwargs)
  File "C:\Users\Михаил\PycharmProjects\football_discordBot\venv\lib\site-packages\aiohttp\client.py", line 779, in _ws_connect
    resp = await self.request(
  File "C:\Users\Михаил\PycharmProjects\football_discordBot\venv\lib\site-packages\aiohttp\client.py", line 536, in _request
    conn = await self._connector.connect(
  File "C:\Users\Михаил\PycharmProjects\football_discordBot\venv\lib\site-packages\aiohttp\connector.py", line 540, in connect
    proto = await self._create_connection(req, traces, timeout)
  File "C:\Users\Михаил\PycharmProjects\football_discordBot\venv\lib\site-packages\aiohttp\connector.py", line 901, in _create_connection
    _, proto = await self._create_direct_connection(req, traces, timeout)
  File "C:\Users\Михаил\PycharmProjects\football_discordBot\venv\lib\site-packages\aiohttp\connector.py", line 1166, in _create_direct_connection
    raise ClientConnectorError(req.connection_key, exc) from exc
aiohttp.client_exceptions.ClientConnectorError: Cannot connect to host gateway-us-east1-b.discord.gg:443 ssl:default [getaddrinfo failed]
[23-01-27 17:08:44] [client.py ERROR] Attempting a reconnect in 153.43s
Traceback (most recent call last):
  File "C:\Users\Михаил\PycharmProjects\football_discordBot\venv\lib\site-packages\aiohttp\connector.py", line 1152, in _create_direct_connection
    hosts = await asyncio.shield(host_resolved)
  File "C:\Users\Михаил\PycharmProjects\football_discordBot\venv\lib\site-packages\aiohttp\connector.py", line 874, in _resolve_host
    addrs = await self._resolver.resolve(host, port, family=self._family)
  File "C:\Users\Михаил\PycharmProjects\football_discordBot\venv\lib\site-packages\aiohttp\resolver.py", line 33, in resolve
    infos = await self._loop.getaddrinfo(
  File "C:\Users\Михаил\AppData\Local\Programs\Python\Python310\lib\asyncio\base_events.py", line 860, in getaddrinfo
    return await self.run_in_executor(
  File "C:\Users\Михаил\AppData\Local\Programs\Python\Python310\lib\concurrent\futures\thread.py", line 58, in run
    result = self.fn(*self.args, **self.kwargs)
  File "C:\Users\Михаил\AppData\Local\Programs\Python\Python310\lib\socket.py", line 955, in getaddrinfo
    for res in _socket.getaddrinfo(host, port, family, type, proto, flags):
socket.gaierror: [Errno 11004] getaddrinfo failed

The above exception was the direct cause of the following exception:

Traceback (most recent call last):
  File "C:\Users\Михаил\PycharmProjects\football_discordBot\venv\lib\site-packages\nextcord\client.py", line 708, in connect
    self.ws = await asyncio.wait_for(coro, timeout=60.0)
  File "C:\Users\Михаил\AppData\Local\Programs\Python\Python310\lib\asyncio\tasks.py", line 445, in wait_for
    return fut.result()
  File "C:\Users\Михаил\PycharmProjects\football_discordBot\venv\lib\site-packages\nextcord\gateway.py", line 365, in from_client
    socket = await client.http.ws_connect(gateway)
  File "C:\Users\Михаил\PycharmProjects\football_discordBot\venv\lib\site-packages\nextcord\http.py", line 250, in ws_connect
    return await self.__session.ws_connect(url, **kwargs)
  File "C:\Users\Михаил\PycharmProjects\football_discordBot\venv\lib\site-packages\aiohttp\client.py", line 779, in _ws_connect
    resp = await self.request(
  File "C:\Users\Михаил\PycharmProjects\football_discordBot\venv\lib\site-packages\aiohttp\client.py", line 536, in _request
    conn = await self._connector.connect(
  File "C:\Users\Михаил\PycharmProjects\football_discordBot\venv\lib\site-packages\aiohttp\connector.py", line 540, in connect
    proto = await self._create_connection(req, traces, timeout)
  File "C:\Users\Михаил\PycharmProjects\football_discordBot\venv\lib\site-packages\aiohttp\connector.py", line 901, in _create_connection
    _, proto = await self._create_direct_connection(req, traces, timeout)
  File "C:\Users\Михаил\PycharmProjects\football_discordBot\venv\lib\site-packages\aiohttp\connector.py", line 1166, in _create_direct_connection
    raise ClientConnectorError(req.connection_key, exc) from exc
aiohttp.client_exceptions.ClientConnectorError: Cannot connect to host gateway-us-east1-b.discord.gg:443 ssl:default [getaddrinfo failed]
[23-01-27 17:11:18] [client.py ERROR] Attempting a reconnect in 337.58s
Traceback (most recent call last):
  File "C:\Users\Михаил\PycharmProjects\football_discordBot\venv\lib\site-packages\aiohttp\connector.py", line 1152, in _create_direct_connection
    hosts = await asyncio.shield(host_resolved)
  File "C:\Users\Михаил\PycharmProjects\football_discordBot\venv\lib\site-packages\aiohttp\connector.py", line 874, in _resolve_host
    addrs = await self._resolver.resolve(host, port, family=self._family)
  File "C:\Users\Михаил\PycharmProjects\football_discordBot\venv\lib\site-packages\aiohttp\resolver.py", line 33, in resolve
    infos = await self._loop.getaddrinfo(
  File "C:\Users\Михаил\AppData\Local\Programs\Python\Python310\lib\asyncio\base_events.py", line 860, in getaddrinfo
    return await self.run_in_executor(
  File "C:\Users\Михаил\AppData\Local\Programs\Python\Python310\lib\concurrent\futures\thread.py", line 58, in run
    result = self.fn(*self.args, **self.kwargs)
  File "C:\Users\Михаил\AppData\Local\Programs\Python\Python310\lib\socket.py", line 955, in getaddrinfo
    for res in _socket.getaddrinfo(host, port, family, type, proto, flags):
socket.gaierror: [Errno 11004] getaddrinfo failed

The above exception was the direct cause of the following exception:

Traceback (most recent call last):
  File "C:\Users\Михаил\PycharmProjects\football_discordBot\venv\lib\site-packages\nextcord\client.py", line 708, in connect
    self.ws = await asyncio.wait_for(coro, timeout=60.0)
  File "C:\Users\Михаил\AppData\Local\Programs\Python\Python310\lib\asyncio\tasks.py", line 445, in wait_for
    return fut.result()
  File "C:\Users\Михаил\PycharmProjects\football_discordBot\venv\lib\site-packages\nextcord\gateway.py", line 365, in from_client
    socket = await client.http.ws_connect(gateway)
  File "C:\Users\Михаил\PycharmProjects\football_discordBot\venv\lib\site-packages\nextcord\http.py", line 250, in ws_connect
    return await self.__session.ws_connect(url, **kwargs)
  File "C:\Users\Михаил\PycharmProjects\football_discordBot\venv\lib\site-packages\aiohttp\client.py", line 779, in _ws_connect
    resp = await self.request(
  File "C:\Users\Михаил\PycharmProjects\football_discordBot\venv\lib\site-packages\aiohttp\client.py", line 536, in _request
    conn = await self._connector.connect(
  File "C:\Users\Михаил\PycharmProjects\football_discordBot\venv\lib\site-packages\aiohttp\connector.py", line 540, in connect
    proto = await self._create_connection(req, traces, timeout)
  File "C:\Users\Михаил\PycharmProjects\football_discordBot\venv\lib\site-packages\aiohttp\connector.py", line 901, in _create_connection
    _, proto = await self._create_direct_connection(req, traces, timeout)
  File "C:\Users\Михаил\PycharmProjects\football_discordBot\venv\lib\site-packages\aiohttp\connector.py", line 1166, in _create_direct_connection
    raise ClientConnectorError(req.connection_key, exc) from exc
aiohttp.client_exceptions.ClientConnectorError: Cannot connect to host gateway-us-east1-b.discord.gg:443 ssl:default [getaddrinfo failed]
[23-01-27 18:14:00] [gateway.py WARNING] Shard ID None has stopped responding to the gateway. Closing and restarting.
[23-01-27 18:14:00] [client.py ERROR] Attempting a reconnect in 0.59s
Traceback (most recent call last):
  File "C:\Users\Михаил\PycharmProjects\football_discordBot\venv\lib\site-packages\aiohttp\connector.py", line 1152, in _create_direct_connection
    hosts = await asyncio.shield(host_resolved)
  File "C:\Users\Михаил\PycharmProjects\football_discordBot\venv\lib\site-packages\aiohttp\connector.py", line 874, in _resolve_host
    addrs = await self._resolver.resolve(host, port, family=self._family)
  File "C:\Users\Михаил\PycharmProjects\football_discordBot\venv\lib\site-packages\aiohttp\resolver.py", line 33, in resolve
    infos = await self._loop.getaddrinfo(
  File "C:\Users\Михаил\AppData\Local\Programs\Python\Python310\lib\asyncio\base_events.py", line 860, in getaddrinfo
    return await self.run_in_executor(
  File "C:\Users\Михаил\AppData\Local\Programs\Python\Python310\lib\concurrent\futures\thread.py", line 58, in run
    result = self.fn(*self.args, **self.kwargs)
  File "C:\Users\Михаил\AppData\Local\Programs\Python\Python310\lib\socket.py", line 955, in getaddrinfo
    for res in _socket.getaddrinfo(host, port, family, type, proto, flags):
socket.gaierror: [Errno 11004] getaddrinfo failed

The above exception was the direct cause of the following exception:

Traceback (most recent call last):
  File "C:\Users\Михаил\PycharmProjects\football_discordBot\venv\lib\site-packages\nextcord\client.py", line 708, in connect
    self.ws = await asyncio.wait_for(coro, timeout=60.0)
  File "C:\Users\Михаил\AppData\Local\Programs\Python\Python310\lib\asyncio\tasks.py", line 445, in wait_for
    return fut.result()
  File "C:\Users\Михаил\PycharmProjects\football_discordBot\venv\lib\site-packages\nextcord\gateway.py", line 365, in from_client
    socket = await client.http.ws_connect(gateway)
  File "C:\Users\Михаил\PycharmProjects\football_discordBot\venv\lib\site-packages\nextcord\http.py", line 250, in ws_connect
    return await self.__session.ws_connect(url, **kwargs)
  File "C:\Users\Михаил\PycharmProjects\football_discordBot\venv\lib\site-packages\aiohttp\client.py", line 779, in _ws_connect
    resp = await self.request(
  File "C:\Users\Михаил\PycharmProjects\football_discordBot\venv\lib\site-packages\aiohttp\client.py", line 536, in _request
    conn = await self._connector.connect(
  File "C:\Users\Михаил\PycharmProjects\football_discordBot\venv\lib\site-packages\aiohttp\connector.py", line 540, in connect
    proto = await self._create_connection(req, traces, timeout)
  File "C:\Users\Михаил\PycharmProjects\football_discordBot\venv\lib\site-packages\aiohttp\connector.py", line 901, in _create_connection
    _, proto = await self._create_direct_connection(req, traces, timeout)
  File "C:\Users\Михаил\PycharmProjects\football_discordBot\venv\lib\site-packages\aiohttp\connector.py", line 1166, in _create_direct_connection
    raise ClientConnectorError(req.connection_key, exc) from exc
aiohttp.client_exceptions.ClientConnectorError: Cannot connect to host gateway-us-east1-d.discord.gg:443 ssl:default [getaddrinfo failed]
[23-01-27 18:14:01] [client.py ERROR] Attempting a reconnect in 2.87s
Traceback (most recent call last):
  File "C:\Users\Михаил\PycharmProjects\football_discordBot\venv\lib\site-packages\aiohttp\connector.py", line 1152, in _create_direct_connection
    hosts = await asyncio.shield(host_resolved)
  File "C:\Users\Михаил\PycharmProjects\football_discordBot\venv\lib\site-packages\aiohttp\connector.py", line 874, in _resolve_host
    addrs = await self._resolver.resolve(host, port, family=self._family)
  File "C:\Users\Михаил\PycharmProjects\football_discordBot\venv\lib\site-packages\aiohttp\resolver.py", line 33, in resolve
    infos = await self._loop.getaddrinfo(
  File "C:\Users\Михаил\AppData\Local\Programs\Python\Python310\lib\asyncio\base_events.py", line 860, in getaddrinfo
    return await self.run_in_executor(
  File "C:\Users\Михаил\AppData\Local\Programs\Python\Python310\lib\concurrent\futures\thread.py", line 58, in run
    result = self.fn(*self.args, **self.kwargs)
  File "C:\Users\Михаил\AppData\Local\Programs\Python\Python310\lib\socket.py", line 955, in getaddrinfo
    for res in _socket.getaddrinfo(host, port, family, type, proto, flags):
socket.gaierror: [Errno 11004] getaddrinfo failed

The above exception was the direct cause of the following exception:

Traceback (most recent call last):
  File "C:\Users\Михаил\PycharmProjects\football_discordBot\venv\lib\site-packages\nextcord\client.py", line 708, in connect
    self.ws = await asyncio.wait_for(coro, timeout=60.0)
  File "C:\Users\Михаил\AppData\Local\Programs\Python\Python310\lib\asyncio\tasks.py", line 445, in wait_for
    return fut.result()
  File "C:\Users\Михаил\PycharmProjects\football_discordBot\venv\lib\site-packages\nextcord\gateway.py", line 365, in from_client
    socket = await client.http.ws_connect(gateway)
  File "C:\Users\Михаил\PycharmProjects\football_discordBot\venv\lib\site-packages\nextcord\http.py", line 250, in ws_connect
    return await self.__session.ws_connect(url, **kwargs)
  File "C:\Users\Михаил\PycharmProjects\football_discordBot\venv\lib\site-packages\aiohttp\client.py", line 779, in _ws_connect
    resp = await self.request(
  File "C:\Users\Михаил\PycharmProjects\football_discordBot\venv\lib\site-packages\aiohttp\client.py", line 536, in _request
    conn = await self._connector.connect(
  File "C:\Users\Михаил\PycharmProjects\football_discordBot\venv\lib\site-packages\aiohttp\connector.py", line 540, in connect
    proto = await self._create_connection(req, traces, timeout)
  File "C:\Users\Михаил\PycharmProjects\football_discordBot\venv\lib\site-packages\aiohttp\connector.py", line 901, in _create_connection
    _, proto = await self._create_direct_connection(req, traces, timeout)
  File "C:\Users\Михаил\PycharmProjects\football_discordBot\venv\lib\site-packages\aiohttp\connector.py", line 1166, in _create_direct_connection
    raise ClientConnectorError(req.connection_key, exc) from exc
aiohttp.client_exceptions.ClientConnectorError: Cannot connect to host gateway-us-east1-d.discord.gg:443 ssl:default [getaddrinfo failed]
[23-01-27 18:14:03] [client.py ERROR] Attempting a reconnect in 3.26s
Traceback (most recent call last):
  File "C:\Users\Михаил\PycharmProjects\football_discordBot\venv\lib\site-packages\aiohttp\connector.py", line 1152, in _create_direct_connection
    hosts = await asyncio.shield(host_resolved)
  File "C:\Users\Михаил\PycharmProjects\football_discordBot\venv\lib\site-packages\aiohttp\connector.py", line 874, in _resolve_host
    addrs = await self._resolver.resolve(host, port, family=self._family)
  File "C:\Users\Михаил\PycharmProjects\football_discordBot\venv\lib\site-packages\aiohttp\resolver.py", line 33, in resolve
    infos = await self._loop.getaddrinfo(
  File "C:\Users\Михаил\AppData\Local\Programs\Python\Python310\lib\asyncio\base_events.py", line 860, in getaddrinfo
    return await self.run_in_executor(
  File "C:\Users\Михаил\AppData\Local\Programs\Python\Python310\lib\concurrent\futures\thread.py", line 58, in run
    result = self.fn(*self.args, **self.kwargs)
  File "C:\Users\Михаил\AppData\Local\Programs\Python\Python310\lib\socket.py", line 955, in getaddrinfo
    for res in _socket.getaddrinfo(host, port, family, type, proto, flags):
socket.gaierror: [Errno 11004] getaddrinfo failed

The above exception was the direct cause of the following exception:

Traceback (most recent call last):
  File "C:\Users\Михаил\PycharmProjects\football_discordBot\venv\lib\site-packages\nextcord\client.py", line 708, in connect
    self.ws = await asyncio.wait_for(coro, timeout=60.0)
  File "C:\Users\Михаил\AppData\Local\Programs\Python\Python310\lib\asyncio\tasks.py", line 445, in wait_for
    return fut.result()
  File "C:\Users\Михаил\PycharmProjects\football_discordBot\venv\lib\site-packages\nextcord\gateway.py", line 365, in from_client
    socket = await client.http.ws_connect(gateway)
  File "C:\Users\Михаил\PycharmProjects\football_discordBot\venv\lib\site-packages\nextcord\http.py", line 250, in ws_connect
    return await self.__session.ws_connect(url, **kwargs)
  File "C:\Users\Михаил\PycharmProjects\football_discordBot\venv\lib\site-packages\aiohttp\client.py", line 779, in _ws_connect
    resp = await self.request(
  File "C:\Users\Михаил\PycharmProjects\football_discordBot\venv\lib\site-packages\aiohttp\client.py", line 536, in _request
    conn = await self._connector.connect(
  File "C:\Users\Михаил\PycharmProjects\football_discordBot\venv\lib\site-packages\aiohttp\connector.py", line 540, in connect
    proto = await self._create_connection(req, traces, timeout)
  File "C:\Users\Михаил\PycharmProjects\football_discordBot\venv\lib\site-packages\aiohttp\connector.py", line 901, in _create_connection
    _, proto = await self._create_direct_connection(req, traces, timeout)
  File "C:\Users\Михаил\PycharmProjects\football_discordBot\venv\lib\site-packages\aiohttp\connector.py", line 1166, in _create_direct_connection
    raise ClientConnectorError(req.connection_key, exc) from exc
aiohttp.client_exceptions.ClientConnectorError: Cannot connect to host gateway-us-east1-d.discord.gg:443 ssl:default [getaddrinfo failed]
[23-01-27 18:14:07] [client.py ERROR] Attempting a reconnect in 1.33s
Traceback (most recent call last):
  File "C:\Users\Михаил\PycharmProjects\football_discordBot\venv\lib\site-packages\aiohttp\connector.py", line 1152, in _create_direct_connection
    hosts = await asyncio.shield(host_resolved)
  File "C:\Users\Михаил\PycharmProjects\football_discordBot\venv\lib\site-packages\aiohttp\connector.py", line 874, in _resolve_host
    addrs = await self._resolver.resolve(host, port, family=self._family)
  File "C:\Users\Михаил\PycharmProjects\football_discordBot\venv\lib\site-packages\aiohttp\resolver.py", line 33, in resolve
    infos = await self._loop.getaddrinfo(
  File "C:\Users\Михаил\AppData\Local\Programs\Python\Python310\lib\asyncio\base_events.py", line 860, in getaddrinfo
    return await self.run_in_executor(
  File "C:\Users\Михаил\AppData\Local\Programs\Python\Python310\lib\concurrent\futures\thread.py", line 58, in run
    result = self.fn(*self.args, **self.kwargs)
  File "C:\Users\Михаил\AppData\Local\Programs\Python\Python310\lib\socket.py", line 955, in getaddrinfo
    for res in _socket.getaddrinfo(host, port, family, type, proto, flags):
socket.gaierror: [Errno 11004] getaddrinfo failed

The above exception was the direct cause of the following exception:

Traceback (most recent call last):
  File "C:\Users\Михаил\PycharmProjects\football_discordBot\venv\lib\site-packages\nextcord\client.py", line 708, in connect
    self.ws = await asyncio.wait_for(coro, timeout=60.0)
  File "C:\Users\Михаил\AppData\Local\Programs\Python\Python310\lib\asyncio\tasks.py", line 445, in wait_for
    return fut.result()
  File "C:\Users\Михаил\PycharmProjects\football_discordBot\venv\lib\site-packages\nextcord\gateway.py", line 365, in from_client
    socket = await client.http.ws_connect(gateway)
  File "C:\Users\Михаил\PycharmProjects\football_discordBot\venv\lib\site-packages\nextcord\http.py", line 250, in ws_connect
    return await self.__session.ws_connect(url, **kwargs)
  File "C:\Users\Михаил\PycharmProjects\football_discordBot\venv\lib\site-packages\aiohttp\client.py", line 779, in _ws_connect
    resp = await self.request(
  File "C:\Users\Михаил\PycharmProjects\football_discordBot\venv\lib\site-packages\aiohttp\client.py", line 536, in _request
    conn = await self._connector.connect(
  File "C:\Users\Михаил\PycharmProjects\football_discordBot\venv\lib\site-packages\aiohttp\connector.py", line 540, in connect
    proto = await self._create_connection(req, traces, timeout)
  File "C:\Users\Михаил\PycharmProjects\football_discordBot\venv\lib\site-packages\aiohttp\connector.py", line 901, in _create_connection
    _, proto = await self._create_direct_connection(req, traces, timeout)
  File "C:\Users\Михаил\PycharmProjects\football_discordBot\venv\lib\site-packages\aiohttp\connector.py", line 1166, in _create_direct_connection
    raise ClientConnectorError(req.connection_key, exc) from exc
aiohttp.client_exceptions.ClientConnectorError: Cannot connect to host gateway-us-east1-d.discord.gg:443 ssl:default [getaddrinfo failed]
[23-01-27 18:14:08] [client.py ERROR] Attempting a reconnect in 20.05s
Traceback (most recent call last):
  File "C:\Users\Михаил\PycharmProjects\football_discordBot\venv\lib\site-packages\aiohttp\connector.py", line 1152, in _create_direct_connection
    hosts = await asyncio.shield(host_resolved)
  File "C:\Users\Михаил\PycharmProjects\football_discordBot\venv\lib\site-packages\aiohttp\connector.py", line 874, in _resolve_host
    addrs = await self._resolver.resolve(host, port, family=self._family)
  File "C:\Users\Михаил\PycharmProjects\football_discordBot\venv\lib\site-packages\aiohttp\resolver.py", line 33, in resolve
    infos = await self._loop.getaddrinfo(
  File "C:\Users\Михаил\AppData\Local\Programs\Python\Python310\lib\asyncio\base_events.py", line 860, in getaddrinfo
    return await self.run_in_executor(
  File "C:\Users\Михаил\AppData\Local\Programs\Python\Python310\lib\concurrent\futures\thread.py", line 58, in run
    result = self.fn(*self.args, **self.kwargs)
  File "C:\Users\Михаил\AppData\Local\Programs\Python\Python310\lib\socket.py", line 955, in getaddrinfo
    for res in _socket.getaddrinfo(host, port, family, type, proto, flags):
socket.gaierror: [Errno 11004] getaddrinfo failed

The above exception was the direct cause of the following exception:

Traceback (most recent call last):
  File "C:\Users\Михаил\PycharmProjects\football_discordBot\venv\lib\site-packages\nextcord\client.py", line 708, in connect
    self.ws = await asyncio.wait_for(coro, timeout=60.0)
  File "C:\Users\Михаил\AppData\Local\Programs\Python\Python310\lib\asyncio\tasks.py", line 445, in wait_for
    return fut.result()
  File "C:\Users\Михаил\PycharmProjects\football_discordBot\venv\lib\site-packages\nextcord\gateway.py", line 365, in from_client
    socket = await client.http.ws_connect(gateway)
  File "C:\Users\Михаил\PycharmProjects\football_discordBot\venv\lib\site-packages\nextcord\http.py", line 250, in ws_connect
    return await self.__session.ws_connect(url, **kwargs)
  File "C:\Users\Михаил\PycharmProjects\football_discordBot\venv\lib\site-packages\aiohttp\client.py", line 779, in _ws_connect
    resp = await self.request(
  File "C:\Users\Михаил\PycharmProjects\football_discordBot\venv\lib\site-packages\aiohttp\client.py", line 536, in _request
    conn = await self._connector.connect(
  File "C:\Users\Михаил\PycharmProjects\football_discordBot\venv\lib\site-packages\aiohttp\connector.py", line 540, in connect
    proto = await self._create_connection(req, traces, timeout)
  File "C:\Users\Михаил\PycharmProjects\football_discordBot\venv\lib\site-packages\aiohttp\connector.py", line 901, in _create_connection
    _, proto = await self._create_direct_connection(req, traces, timeout)
  File "C:\Users\Михаил\PycharmProjects\football_discordBot\venv\lib\site-packages\aiohttp\connector.py", line 1166, in _create_direct_connection
    raise ClientConnectorError(req.connection_key, exc) from exc
aiohttp.client_exceptions.ClientConnectorError: Cannot connect to host gateway-us-east1-d.discord.gg:443 ssl:default [getaddrinfo failed]
[23-01-27 18:14:28] [client.py ERROR] Attempting a reconnect in 51.04s
Traceback (most recent call last):
  File "C:\Users\Михаил\PycharmProjects\football_discordBot\venv\lib\site-packages\aiohttp\connector.py", line 1152, in _create_direct_connection
    hosts = await asyncio.shield(host_resolved)
  File "C:\Users\Михаил\PycharmProjects\football_discordBot\venv\lib\site-packages\aiohttp\connector.py", line 874, in _resolve_host
    addrs = await self._resolver.resolve(host, port, family=self._family)
  File "C:\Users\Михаил\PycharmProjects\football_discordBot\venv\lib\site-packages\aiohttp\resolver.py", line 33, in resolve
    infos = await self._loop.getaddrinfo(
  File "C:\Users\Михаил\AppData\Local\Programs\Python\Python310\lib\asyncio\base_events.py", line 860, in getaddrinfo
    return await self.run_in_executor(
  File "C:\Users\Михаил\AppData\Local\Programs\Python\Python310\lib\concurrent\futures\thread.py", line 58, in run
    result = self.fn(*self.args, **self.kwargs)
  File "C:\Users\Михаил\AppData\Local\Programs\Python\Python310\lib\socket.py", line 955, in getaddrinfo
    for res in _socket.getaddrinfo(host, port, family, type, proto, flags):
socket.gaierror: [Errno 11004] getaddrinfo failed

The above exception was the direct cause of the following exception:

Traceback (most recent call last):
  File "C:\Users\Михаил\PycharmProjects\football_discordBot\venv\lib\site-packages\nextcord\client.py", line 708, in connect
    self.ws = await asyncio.wait_for(coro, timeout=60.0)
  File "C:\Users\Михаил\AppData\Local\Programs\Python\Python310\lib\asyncio\tasks.py", line 445, in wait_for
    return fut.result()
  File "C:\Users\Михаил\PycharmProjects\football_discordBot\venv\lib\site-packages\nextcord\gateway.py", line 365, in from_client
    socket = await client.http.ws_connect(gateway)
  File "C:\Users\Михаил\PycharmProjects\football_discordBot\venv\lib\site-packages\nextcord\http.py", line 250, in ws_connect
    return await self.__session.ws_connect(url, **kwargs)
  File "C:\Users\Михаил\PycharmProjects\football_discordBot\venv\lib\site-packages\aiohttp\client.py", line 779, in _ws_connect
    resp = await self.request(
  File "C:\Users\Михаил\PycharmProjects\football_discordBot\venv\lib\site-packages\aiohttp\client.py", line 536, in _request
    conn = await self._connector.connect(
  File "C:\Users\Михаил\PycharmProjects\football_discordBot\venv\lib\site-packages\aiohttp\connector.py", line 540, in connect
    proto = await self._create_connection(req, traces, timeout)
  File "C:\Users\Михаил\PycharmProjects\football_discordBot\venv\lib\site-packages\aiohttp\connector.py", line 901, in _create_connection
    _, proto = await self._create_direct_connection(req, traces, timeout)
  File "C:\Users\Михаил\PycharmProjects\football_discordBot\venv\lib\site-packages\aiohttp\connector.py", line 1166, in _create_direct_connection
    raise ClientConnectorError(req.connection_key, exc) from exc
aiohttp.client_exceptions.ClientConnectorError: Cannot connect to host gateway-us-east1-d.discord.gg:443 ssl:default [getaddrinfo failed]
[23-01-27 18:15:19] [client.py ERROR] Attempting a reconnect in 47.33s
Traceback (most recent call last):
  File "C:\Users\Михаил\PycharmProjects\football_discordBot\venv\lib\site-packages\aiohttp\connector.py", line 1152, in _create_direct_connection
    hosts = await asyncio.shield(host_resolved)
  File "C:\Users\Михаил\PycharmProjects\football_discordBot\venv\lib\site-packages\aiohttp\connector.py", line 874, in _resolve_host
    addrs = await self._resolver.resolve(host, port, family=self._family)
  File "C:\Users\Михаил\PycharmProjects\football_discordBot\venv\lib\site-packages\aiohttp\resolver.py", line 33, in resolve
    infos = await self._loop.getaddrinfo(
  File "C:\Users\Михаил\AppData\Local\Programs\Python\Python310\lib\asyncio\base_events.py", line 860, in getaddrinfo
    return await self.run_in_executor(
  File "C:\Users\Михаил\AppData\Local\Programs\Python\Python310\lib\concurrent\futures\thread.py", line 58, in run
    result = self.fn(*self.args, **self.kwargs)
  File "C:\Users\Михаил\AppData\Local\Programs\Python\Python310\lib\socket.py", line 955, in getaddrinfo
    for res in _socket.getaddrinfo(host, port, family, type, proto, flags):
socket.gaierror: [Errno 11004] getaddrinfo failed

The above exception was the direct cause of the following exception:

Traceback (most recent call last):
  File "C:\Users\Михаил\PycharmProjects\football_discordBot\venv\lib\site-packages\nextcord\client.py", line 708, in connect
    self.ws = await asyncio.wait_for(coro, timeout=60.0)
  File "C:\Users\Михаил\AppData\Local\Programs\Python\Python310\lib\asyncio\tasks.py", line 445, in wait_for
    return fut.result()
  File "C:\Users\Михаил\PycharmProjects\football_discordBot\venv\lib\site-packages\nextcord\gateway.py", line 365, in from_client
    socket = await client.http.ws_connect(gateway)
  File "C:\Users\Михаил\PycharmProjects\football_discordBot\venv\lib\site-packages\nextcord\http.py", line 250, in ws_connect
    return await self.__session.ws_connect(url, **kwargs)
  File "C:\Users\Михаил\PycharmProjects\football_discordBot\venv\lib\site-packages\aiohttp\client.py", line 779, in _ws_connect
    resp = await self.request(
  File "C:\Users\Михаил\PycharmProjects\football_discordBot\venv\lib\site-packages\aiohttp\client.py", line 536, in _request
    conn = await self._connector.connect(
  File "C:\Users\Михаил\PycharmProjects\football_discordBot\venv\lib\site-packages\aiohttp\connector.py", line 540, in connect
    proto = await self._create_connection(req, traces, timeout)
  File "C:\Users\Михаил\PycharmProjects\football_discordBot\venv\lib\site-packages\aiohttp\connector.py", line 901, in _create_connection
    _, proto = await self._create_direct_connection(req, traces, timeout)
  File "C:\Users\Михаил\PycharmProjects\football_discordBot\venv\lib\site-packages\aiohttp\connector.py", line 1166, in _create_direct_connection
    raise ClientConnectorError(req.connection_key, exc) from exc
aiohttp.client_exceptions.ClientConnectorError: Cannot connect to host gateway-us-east1-d.discord.gg:443 ssl:default [getaddrinfo failed]
[23-01-27 18:16:06] [client.py ERROR] Attempting a reconnect in 219.58s
Traceback (most recent call last):
  File "C:\Users\Михаил\PycharmProjects\football_discordBot\venv\lib\site-packages\aiohttp\connector.py", line 1152, in _create_direct_connection
    hosts = await asyncio.shield(host_resolved)
  File "C:\Users\Михаил\PycharmProjects\football_discordBot\venv\lib\site-packages\aiohttp\connector.py", line 874, in _resolve_host
    addrs = await self._resolver.resolve(host, port, family=self._family)
  File "C:\Users\Михаил\PycharmProjects\football_discordBot\venv\lib\site-packages\aiohttp\resolver.py", line 33, in resolve
    infos = await self._loop.getaddrinfo(
  File "C:\Users\Михаил\AppData\Local\Programs\Python\Python310\lib\asyncio\base_events.py", line 860, in getaddrinfo
    return await self.run_in_executor(
  File "C:\Users\Михаил\AppData\Local\Programs\Python\Python310\lib\concurrent\futures\thread.py", line 58, in run
    result = self.fn(*self.args, **self.kwargs)
  File "C:\Users\Михаил\AppData\Local\Programs\Python\Python310\lib\socket.py", line 955, in getaddrinfo
    for res in _socket.getaddrinfo(host, port, family, type, proto, flags):
socket.gaierror: [Errno 11004] getaddrinfo failed

The above exception was the direct cause of the following exception:

Traceback (most recent call last):
  File "C:\Users\Михаил\PycharmProjects\football_discordBot\venv\lib\site-packages\nextcord\client.py", line 708, in connect
    self.ws = await asyncio.wait_for(coro, timeout=60.0)
  File "C:\Users\Михаил\AppData\Local\Programs\Python\Python310\lib\asyncio\tasks.py", line 445, in wait_for
    return fut.result()
  File "C:\Users\Михаил\PycharmProjects\football_discordBot\venv\lib\site-packages\nextcord\gateway.py", line 365, in from_client
    socket = await client.http.ws_connect(gateway)
  File "C:\Users\Михаил\PycharmProjects\football_discordBot\venv\lib\site-packages\nextcord\http.py", line 250, in ws_connect
    return await self.__session.ws_connect(url, **kwargs)
  File "C:\Users\Михаил\PycharmProjects\football_discordBot\venv\lib\site-packages\aiohttp\client.py", line 779, in _ws_connect
    resp = await self.request(
  File "C:\Users\Михаил\PycharmProjects\football_discordBot\venv\lib\site-packages\aiohttp\client.py", line 536, in _request
    conn = await self._connector.connect(
  File "C:\Users\Михаил\PycharmProjects\football_discordBot\venv\lib\site-packages\aiohttp\connector.py", line 540, in connect
    proto = await self._create_connection(req, traces, timeout)
  File "C:\Users\Михаил\PycharmProjects\football_discordBot\venv\lib\site-packages\aiohttp\connector.py", line 901, in _create_connection
    _, proto = await self._create_direct_connection(req, traces, timeout)
  File "C:\Users\Михаил\PycharmProjects\football_discordBot\venv\lib\site-packages\aiohttp\connector.py", line 1166, in _create_direct_connection
    raise ClientConnectorError(req.connection_key, exc) from exc
aiohttp.client_exceptions.ClientConnectorError: Cannot connect to host gateway-us-east1-d.discord.gg:443 ssl:default [getaddrinfo failed]
[23-01-27 18:19:46] [client.py ERROR] Attempting a reconnect in 185.57s
Traceback (most recent call last):
  File "C:\Users\Михаил\PycharmProjects\football_discordBot\venv\lib\site-packages\aiohttp\connector.py", line 1152, in _create_direct_connection
    hosts = await asyncio.shield(host_resolved)
  File "C:\Users\Михаил\PycharmProjects\football_discordBot\venv\lib\site-packages\aiohttp\connector.py", line 874, in _resolve_host
    addrs = await self._resolver.resolve(host, port, family=self._family)
  File "C:\Users\Михаил\PycharmProjects\football_discordBot\venv\lib\site-packages\aiohttp\resolver.py", line 33, in resolve
    infos = await self._loop.getaddrinfo(
  File "C:\Users\Михаил\AppData\Local\Programs\Python\Python310\lib\asyncio\base_events.py", line 860, in getaddrinfo
    return await self.run_in_executor(
  File "C:\Users\Михаил\AppData\Local\Programs\Python\Python310\lib\concurrent\futures\thread.py", line 58, in run
    result = self.fn(*self.args, **self.kwargs)
  File "C:\Users\Михаил\AppData\Local\Programs\Python\Python310\lib\socket.py", line 955, in getaddrinfo
    for res in _socket.getaddrinfo(host, port, family, type, proto, flags):
socket.gaierror: [Errno 11004] getaddrinfo failed

The above exception was the direct cause of the following exception:

Traceback (most recent call last):
  File "C:\Users\Михаил\PycharmProjects\football_discordBot\venv\lib\site-packages\nextcord\client.py", line 708, in connect
    self.ws = await asyncio.wait_for(coro, timeout=60.0)
  File "C:\Users\Михаил\AppData\Local\Programs\Python\Python310\lib\asyncio\tasks.py", line 445, in wait_for
    return fut.result()
  File "C:\Users\Михаил\PycharmProjects\football_discordBot\venv\lib\site-packages\nextcord\gateway.py", line 365, in from_client
    socket = await client.http.ws_connect(gateway)
  File "C:\Users\Михаил\PycharmProjects\football_discordBot\venv\lib\site-packages\nextcord\http.py", line 250, in ws_connect
    return await self.__session.ws_connect(url, **kwargs)
  File "C:\Users\Михаил\PycharmProjects\football_discordBot\venv\lib\site-packages\aiohttp\client.py", line 779, in _ws_connect
    resp = await self.request(
  File "C:\Users\Михаил\PycharmProjects\football_discordBot\venv\lib\site-packages\aiohttp\client.py", line 536, in _request
    conn = await self._connector.connect(
  File "C:\Users\Михаил\PycharmProjects\football_discordBot\venv\lib\site-packages\aiohttp\connector.py", line 540, in connect
    proto = await self._create_connection(req, traces, timeout)
  File "C:\Users\Михаил\PycharmProjects\football_discordBot\venv\lib\site-packages\aiohttp\connector.py", line 901, in _create_connection
    _, proto = await self._create_direct_connection(req, traces, timeout)
  File "C:\Users\Михаил\PycharmProjects\football_discordBot\venv\lib\site-packages\aiohttp\connector.py", line 1166, in _create_direct_connection
    raise ClientConnectorError(req.connection_key, exc) from exc
aiohttp.client_exceptions.ClientConnectorError: Cannot connect to host gateway-us-east1-d.discord.gg:443 ssl:default [getaddrinfo failed]
[23-01-27 18:22:52] [client.py ERROR] Attempting a reconnect in 259.65s
Traceback (most recent call last):
  File "C:\Users\Михаил\PycharmProjects\football_discordBot\venv\lib\site-packages\aiohttp\connector.py", line 1152, in _create_direct_connection
    hosts = await asyncio.shield(host_resolved)
  File "C:\Users\Михаил\PycharmProjects\football_discordBot\venv\lib\site-packages\aiohttp\connector.py", line 874, in _resolve_host
    addrs = await self._resolver.resolve(host, port, family=self._family)
  File "C:\Users\Михаил\PycharmProjects\football_discordBot\venv\lib\site-packages\aiohttp\resolver.py", line 33, in resolve
    infos = await self._loop.getaddrinfo(
  File "C:\Users\Михаил\AppData\Local\Programs\Python\Python310\lib\asyncio\base_events.py", line 860, in getaddrinfo
    return await self.run_in_executor(
  File "C:\Users\Михаил\AppData\Local\Programs\Python\Python310\lib\concurrent\futures\thread.py", line 58, in run
    result = self.fn(*self.args, **self.kwargs)
  File "C:\Users\Михаил\AppData\Local\Programs\Python\Python310\lib\socket.py", line 955, in getaddrinfo
    for res in _socket.getaddrinfo(host, port, family, type, proto, flags):
socket.gaierror: [Errno 11004] getaddrinfo failed

The above exception was the direct cause of the following exception:

Traceback (most recent call last):
  File "C:\Users\Михаил\PycharmProjects\football_discordBot\venv\lib\site-packages\nextcord\client.py", line 708, in connect
    self.ws = await asyncio.wait_for(coro, timeout=60.0)
  File "C:\Users\Михаил\AppData\Local\Programs\Python\Python310\lib\asyncio\tasks.py", line 445, in wait_for
    return fut.result()
  File "C:\Users\Михаил\PycharmProjects\football_discordBot\venv\lib\site-packages\nextcord\gateway.py", line 365, in from_client
    socket = await client.http.ws_connect(gateway)
  File "C:\Users\Михаил\PycharmProjects\football_discordBot\venv\lib\site-packages\nextcord\http.py", line 250, in ws_connect
    return await self.__session.ws_connect(url, **kwargs)
  File "C:\Users\Михаил\PycharmProjects\football_discordBot\venv\lib\site-packages\aiohttp\client.py", line 779, in _ws_connect
    resp = await self.request(
  File "C:\Users\Михаил\PycharmProjects\football_discordBot\venv\lib\site-packages\aiohttp\client.py", line 536, in _request
    conn = await self._connector.connect(
  File "C:\Users\Михаил\PycharmProjects\football_discordBot\venv\lib\site-packages\aiohttp\connector.py", line 540, in connect
    proto = await self._create_connection(req, traces, timeout)
  File "C:\Users\Михаил\PycharmProjects\football_discordBot\venv\lib\site-packages\aiohttp\connector.py", line 901, in _create_connection
    _, proto = await self._create_direct_connection(req, traces, timeout)
  File "C:\Users\Михаил\PycharmProjects\football_discordBot\venv\lib\site-packages\aiohttp\connector.py", line 1166, in _create_direct_connection
    raise ClientConnectorError(req.connection_key, exc) from exc
aiohttp.client_exceptions.ClientConnectorError: Cannot connect to host gateway-us-east1-d.discord.gg:443 ssl:default [getaddrinfo failed]
[23-01-27 18:27:11] [client.py ERROR] Attempting a reconnect in 16.18s
Traceback (most recent call last):
  File "C:\Users\Михаил\PycharmProjects\football_discordBot\venv\lib\site-packages\aiohttp\connector.py", line 1152, in _create_direct_connection
    hosts = await asyncio.shield(host_resolved)
  File "C:\Users\Михаил\PycharmProjects\football_discordBot\venv\lib\site-packages\aiohttp\connector.py", line 874, in _resolve_host
    addrs = await self._resolver.resolve(host, port, family=self._family)
  File "C:\Users\Михаил\PycharmProjects\football_discordBot\venv\lib\site-packages\aiohttp\resolver.py", line 33, in resolve
    infos = await self._loop.getaddrinfo(
  File "C:\Users\Михаил\AppData\Local\Programs\Python\Python310\lib\asyncio\base_events.py", line 860, in getaddrinfo
    return await self.run_in_executor(
  File "C:\Users\Михаил\AppData\Local\Programs\Python\Python310\lib\concurrent\futures\thread.py", line 58, in run
    result = self.fn(*self.args, **self.kwargs)
  File "C:\Users\Михаил\AppData\Local\Programs\Python\Python310\lib\socket.py", line 955, in getaddrinfo
    for res in _socket.getaddrinfo(host, port, family, type, proto, flags):
socket.gaierror: [Errno 11004] getaddrinfo failed

The above exception was the direct cause of the following exception:

Traceback (most recent call last):
  File "C:\Users\Михаил\PycharmProjects\football_discordBot\venv\lib\site-packages\nextcord\client.py", line 708, in connect
    self.ws = await asyncio.wait_for(coro, timeout=60.0)
  File "C:\Users\Михаил\AppData\Local\Programs\Python\Python310\lib\asyncio\tasks.py", line 445, in wait_for
    return fut.result()
  File "C:\Users\Михаил\PycharmProjects\football_discordBot\venv\lib\site-packages\nextcord\gateway.py", line 365, in from_client
    socket = await client.http.ws_connect(gateway)
  File "C:\Users\Михаил\PycharmProjects\football_discordBot\venv\lib\site-packages\nextcord\http.py", line 250, in ws_connect
    return await self.__session.ws_connect(url, **kwargs)
  File "C:\Users\Михаил\PycharmProjects\football_discordBot\venv\lib\site-packages\aiohttp\client.py", line 779, in _ws_connect
    resp = await self.request(
  File "C:\Users\Михаил\PycharmProjects\football_discordBot\venv\lib\site-packages\aiohttp\client.py", line 536, in _request
    conn = await self._connector.connect(
  File "C:\Users\Михаил\PycharmProjects\football_discordBot\venv\lib\site-packages\aiohttp\connector.py", line 540, in connect
    proto = await self._create_connection(req, traces, timeout)
  File "C:\Users\Михаил\PycharmProjects\football_discordBot\venv\lib\site-packages\aiohttp\connector.py", line 901, in _create_connection
    _, proto = await self._create_direct_connection(req, traces, timeout)
  File "C:\Users\Михаил\PycharmProjects\football_discordBot\venv\lib\site-packages\aiohttp\connector.py", line 1166, in _create_direct_connection
    raise ClientConnectorError(req.connection_key, exc) from exc
aiohttp.client_exceptions.ClientConnectorError: Cannot connect to host gateway-us-east1-d.discord.gg:443 ssl:default [getaddrinfo failed]
[23-01-27 18:27:28] [client.py ERROR] Attempting a reconnect in 721.37s
Traceback (most recent call last):
  File "C:\Users\Михаил\PycharmProjects\football_discordBot\venv\lib\site-packages\aiohttp\connector.py", line 1152, in _create_direct_connection
    hosts = await asyncio.shield(host_resolved)
  File "C:\Users\Михаил\PycharmProjects\football_discordBot\venv\lib\site-packages\aiohttp\connector.py", line 874, in _resolve_host
    addrs = await self._resolver.resolve(host, port, family=self._family)
  File "C:\Users\Михаил\PycharmProjects\football_discordBot\venv\lib\site-packages\aiohttp\resolver.py", line 33, in resolve
    infos = await self._loop.getaddrinfo(
  File "C:\Users\Михаил\AppData\Local\Programs\Python\Python310\lib\asyncio\base_events.py", line 860, in getaddrinfo
    return await self.run_in_executor(
  File "C:\Users\Михаил\AppData\Local\Programs\Python\Python310\lib\concurrent\futures\thread.py", line 58, in run
    result = self.fn(*self.args, **self.kwargs)
  File "C:\Users\Михаил\AppData\Local\Programs\Python\Python310\lib\socket.py", line 955, in getaddrinfo
    for res in _socket.getaddrinfo(host, port, family, type, proto, flags):
socket.gaierror: [Errno 11004] getaddrinfo failed

The above exception was the direct cause of the following exception:

Traceback (most recent call last):
  File "C:\Users\Михаил\PycharmProjects\football_discordBot\venv\lib\site-packages\nextcord\client.py", line 708, in connect
    self.ws = await asyncio.wait_for(coro, timeout=60.0)
  File "C:\Users\Михаил\AppData\Local\Programs\Python\Python310\lib\asyncio\tasks.py", line 445, in wait_for
    return fut.result()
  File "C:\Users\Михаил\PycharmProjects\football_discordBot\venv\lib\site-packages\nextcord\gateway.py", line 365, in from_client
    socket = await client.http.ws_connect(gateway)
  File "C:\Users\Михаил\PycharmProjects\football_discordBot\venv\lib\site-packages\nextcord\http.py", line 250, in ws_connect
    return await self.__session.ws_connect(url, **kwargs)
  File "C:\Users\Михаил\PycharmProjects\football_discordBot\venv\lib\site-packages\aiohttp\client.py", line 779, in _ws_connect
    resp = await self.request(
  File "C:\Users\Михаил\PycharmProjects\football_discordBot\venv\lib\site-packages\aiohttp\client.py", line 536, in _request
    conn = await self._connector.connect(
  File "C:\Users\Михаил\PycharmProjects\football_discordBot\venv\lib\site-packages\aiohttp\connector.py", line 540, in connect
    proto = await self._create_connection(req, traces, timeout)
  File "C:\Users\Михаил\PycharmProjects\football_discordBot\venv\lib\site-packages\aiohttp\connector.py", line 901, in _create_connection
    _, proto = await self._create_direct_connection(req, traces, timeout)
  File "C:\Users\Михаил\PycharmProjects\football_discordBot\venv\lib\site-packages\aiohttp\connector.py", line 1166, in _create_direct_connection
    raise ClientConnectorError(req.connection_key, exc) from exc
aiohttp.client_exceptions.ClientConnectorError: Cannot connect to host gateway-us-east1-d.discord.gg:443 ssl:default [getaddrinfo failed]
[23-01-27 18:39:29] [client.py ERROR] Attempting a reconnect in 1014.16s
Traceback (most recent call last):
  File "C:\Users\Михаил\PycharmProjects\football_discordBot\venv\lib\site-packages\aiohttp\connector.py", line 1152, in _create_direct_connection
    hosts = await asyncio.shield(host_resolved)
  File "C:\Users\Михаил\PycharmProjects\football_discordBot\venv\lib\site-packages\aiohttp\connector.py", line 874, in _resolve_host
    addrs = await self._resolver.resolve(host, port, family=self._family)
  File "C:\Users\Михаил\PycharmProjects\football_discordBot\venv\lib\site-packages\aiohttp\resolver.py", line 33, in resolve
    infos = await self._loop.getaddrinfo(
  File "C:\Users\Михаил\AppData\Local\Programs\Python\Python310\lib\asyncio\base_events.py", line 860, in getaddrinfo
    return await self.run_in_executor(
  File "C:\Users\Михаил\AppData\Local\Programs\Python\Python310\lib\concurrent\futures\thread.py", line 58, in run
    result = self.fn(*self.args, **self.kwargs)
  File "C:\Users\Михаил\AppData\Local\Programs\Python\Python310\lib\socket.py", line 955, in getaddrinfo
    for res in _socket.getaddrinfo(host, port, family, type, proto, flags):
socket.gaierror: [Errno 11004] getaddrinfo failed

The above exception was the direct cause of the following exception:

Traceback (most recent call last):
  File "C:\Users\Михаил\PycharmProjects\football_discordBot\venv\lib\site-packages\nextcord\client.py", line 708, in connect
    self.ws = await asyncio.wait_for(coro, timeout=60.0)
  File "C:\Users\Михаил\AppData\Local\Programs\Python\Python310\lib\asyncio\tasks.py", line 445, in wait_for
    return fut.result()
  File "C:\Users\Михаил\PycharmProjects\football_discordBot\venv\lib\site-packages\nextcord\gateway.py", line 365, in from_client
    socket = await client.http.ws_connect(gateway)
  File "C:\Users\Михаил\PycharmProjects\football_discordBot\venv\lib\site-packages\nextcord\http.py", line 250, in ws_connect
    return await self.__session.ws_connect(url, **kwargs)
  File "C:\Users\Михаил\PycharmProjects\football_discordBot\venv\lib\site-packages\aiohttp\client.py", line 779, in _ws_connect
    resp = await self.request(
  File "C:\Users\Михаил\PycharmProjects\football_discordBot\venv\lib\site-packages\aiohttp\client.py", line 536, in _request
    conn = await self._connector.connect(
  File "C:\Users\Михаил\PycharmProjects\football_discordBot\venv\lib\site-packages\aiohttp\connector.py", line 540, in connect
    proto = await self._create_connection(req, traces, timeout)
  File "C:\Users\Михаил\PycharmProjects\football_discordBot\venv\lib\site-packages\aiohttp\connector.py", line 901, in _create_connection
    _, proto = await self._create_direct_connection(req, traces, timeout)
  File "C:\Users\Михаил\PycharmProjects\football_discordBot\venv\lib\site-packages\aiohttp\connector.py", line 1166, in _create_direct_connection
    raise ClientConnectorError(req.connection_key, exc) from exc
aiohttp.client_exceptions.ClientConnectorError: Cannot connect to host gateway-us-east1-d.discord.gg:443 ssl:default [getaddrinfo failed]
[23-01-27 18:56:23] [client.py ERROR] Attempting a reconnect in 191.67s
Traceback (most recent call last):
  File "C:\Users\Михаил\PycharmProjects\football_discordBot\venv\lib\site-packages\aiohttp\connector.py", line 1152, in _create_direct_connection
    hosts = await asyncio.shield(host_resolved)
  File "C:\Users\Михаил\PycharmProjects\football_discordBot\venv\lib\site-packages\aiohttp\connector.py", line 874, in _resolve_host
    addrs = await self._resolver.resolve(host, port, family=self._family)
  File "C:\Users\Михаил\PycharmProjects\football_discordBot\venv\lib\site-packages\aiohttp\resolver.py", line 33, in resolve
    infos = await self._loop.getaddrinfo(
  File "C:\Users\Михаил\AppData\Local\Programs\Python\Python310\lib\asyncio\base_events.py", line 860, in getaddrinfo
    return await self.run_in_executor(
  File "C:\Users\Михаил\AppData\Local\Programs\Python\Python310\lib\concurrent\futures\thread.py", line 58, in run
    result = self.fn(*self.args, **self.kwargs)
  File "C:\Users\Михаил\AppData\Local\Programs\Python\Python310\lib\socket.py", line 955, in getaddrinfo
    for res in _socket.getaddrinfo(host, port, family, type, proto, flags):
socket.gaierror: [Errno 11004] getaddrinfo failed

The above exception was the direct cause of the following exception:

Traceback (most recent call last):
  File "C:\Users\Михаил\PycharmProjects\football_discordBot\venv\lib\site-packages\nextcord\client.py", line 708, in connect
    self.ws = await asyncio.wait_for(coro, timeout=60.0)
  File "C:\Users\Михаил\AppData\Local\Programs\Python\Python310\lib\asyncio\tasks.py", line 445, in wait_for
    return fut.result()
  File "C:\Users\Михаил\PycharmProjects\football_discordBot\venv\lib\site-packages\nextcord\gateway.py", line 365, in from_client
    socket = await client.http.ws_connect(gateway)
  File "C:\Users\Михаил\PycharmProjects\football_discordBot\venv\lib\site-packages\nextcord\http.py", line 250, in ws_connect
    return await self.__session.ws_connect(url, **kwargs)
  File "C:\Users\Михаил\PycharmProjects\football_discordBot\venv\lib\site-packages\aiohttp\client.py", line 779, in _ws_connect
    resp = await self.request(
  File "C:\Users\Михаил\PycharmProjects\football_discordBot\venv\lib\site-packages\aiohttp\client.py", line 536, in _request
    conn = await self._connector.connect(
  File "C:\Users\Михаил\PycharmProjects\football_discordBot\venv\lib\site-packages\aiohttp\connector.py", line 540, in connect
    proto = await self._create_connection(req, traces, timeout)
  File "C:\Users\Михаил\PycharmProjects\football_discordBot\venv\lib\site-packages\aiohttp\connector.py", line 901, in _create_connection
    _, proto = await self._create_direct_connection(req, traces, timeout)
  File "C:\Users\Михаил\PycharmProjects\football_discordBot\venv\lib\site-packages\aiohttp\connector.py", line 1166, in _create_direct_connection
    raise ClientConnectorError(req.connection_key, exc) from exc
aiohttp.client_exceptions.ClientConnectorError: Cannot connect to host gateway-us-east1-d.discord.gg:443 ssl:default [getaddrinfo failed]
[23-01-27 18:59:35] [client.py ERROR] Attempting a reconnect in 1.10s
Traceback (most recent call last):
  File "C:\Users\Михаил\PycharmProjects\football_discordBot\venv\lib\site-packages\aiohttp\connector.py", line 1152, in _create_direct_connection
    hosts = await asyncio.shield(host_resolved)
  File "C:\Users\Михаил\PycharmProjects\football_discordBot\venv\lib\site-packages\aiohttp\connector.py", line 874, in _resolve_host
    addrs = await self._resolver.resolve(host, port, family=self._family)
  File "C:\Users\Михаил\PycharmProjects\football_discordBot\venv\lib\site-packages\aiohttp\resolver.py", line 33, in resolve
    infos = await self._loop.getaddrinfo(
  File "C:\Users\Михаил\AppData\Local\Programs\Python\Python310\lib\asyncio\base_events.py", line 860, in getaddrinfo
    return await self.run_in_executor(
  File "C:\Users\Михаил\AppData\Local\Programs\Python\Python310\lib\concurrent\futures\thread.py", line 58, in run
    result = self.fn(*self.args, **self.kwargs)
  File "C:\Users\Михаил\AppData\Local\Programs\Python\Python310\lib\socket.py", line 955, in getaddrinfo
    for res in _socket.getaddrinfo(host, port, family, type, proto, flags):
socket.gaierror: [Errno 11004] getaddrinfo failed

The above exception was the direct cause of the following exception:

Traceback (most recent call last):
  File "C:\Users\Михаил\PycharmProjects\football_discordBot\venv\lib\site-packages\nextcord\client.py", line 708, in connect
    self.ws = await asyncio.wait_for(coro, timeout=60.0)
  File "C:\Users\Михаил\AppData\Local\Programs\Python\Python310\lib\asyncio\tasks.py", line 445, in wait_for
    return fut.result()
  File "C:\Users\Михаил\PycharmProjects\football_discordBot\venv\lib\site-packages\nextcord\gateway.py", line 365, in from_client
    socket = await client.http.ws_connect(gateway)
  File "C:\Users\Михаил\PycharmProjects\football_discordBot\venv\lib\site-packages\nextcord\http.py", line 250, in ws_connect
    return await self.__session.ws_connect(url, **kwargs)
  File "C:\Users\Михаил\PycharmProjects\football_discordBot\venv\lib\site-packages\aiohttp\client.py", line 779, in _ws_connect
    resp = await self.request(
  File "C:\Users\Михаил\PycharmProjects\football_discordBot\venv\lib\site-packages\aiohttp\client.py", line 536, in _request
    conn = await self._connector.connect(
  File "C:\Users\Михаил\PycharmProjects\football_discordBot\venv\lib\site-packages\aiohttp\connector.py", line 540, in connect
    proto = await self._create_connection(req, traces, timeout)
  File "C:\Users\Михаил\PycharmProjects\football_discordBot\venv\lib\site-packages\aiohttp\connector.py", line 901, in _create_connection
    _, proto = await self._create_direct_connection(req, traces, timeout)
  File "C:\Users\Михаил\PycharmProjects\football_discordBot\venv\lib\site-packages\aiohttp\connector.py", line 1166, in _create_direct_connection
    raise ClientConnectorError(req.connection_key, exc) from exc
aiohttp.client_exceptions.ClientConnectorError: Cannot connect to host gateway-us-east1-d.discord.gg:443 ssl:default [getaddrinfo failed]
[23-01-27 18:59:36] [client.py ERROR] Attempting a reconnect in 1.90s
Traceback (most recent call last):
  File "C:\Users\Михаил\PycharmProjects\football_discordBot\venv\lib\site-packages\aiohttp\connector.py", line 1152, in _create_direct_connection
    hosts = await asyncio.shield(host_resolved)
  File "C:\Users\Михаил\PycharmProjects\football_discordBot\venv\lib\site-packages\aiohttp\connector.py", line 874, in _resolve_host
    addrs = await self._resolver.resolve(host, port, family=self._family)
  File "C:\Users\Михаил\PycharmProjects\football_discordBot\venv\lib\site-packages\aiohttp\resolver.py", line 33, in resolve
    infos = await self._loop.getaddrinfo(
  File "C:\Users\Михаил\AppData\Local\Programs\Python\Python310\lib\asyncio\base_events.py", line 860, in getaddrinfo
    return await self.run_in_executor(
  File "C:\Users\Михаил\AppData\Local\Programs\Python\Python310\lib\concurrent\futures\thread.py", line 58, in run
    result = self.fn(*self.args, **self.kwargs)
  File "C:\Users\Михаил\AppData\Local\Programs\Python\Python310\lib\socket.py", line 955, in getaddrinfo
    for res in _socket.getaddrinfo(host, port, family, type, proto, flags):
socket.gaierror: [Errno 11004] getaddrinfo failed

The above exception was the direct cause of the following exception:

Traceback (most recent call last):
  File "C:\Users\Михаил\PycharmProjects\football_discordBot\venv\lib\site-packages\nextcord\client.py", line 708, in connect
    self.ws = await asyncio.wait_for(coro, timeout=60.0)
  File "C:\Users\Михаил\AppData\Local\Programs\Python\Python310\lib\asyncio\tasks.py", line 445, in wait_for
    return fut.result()
  File "C:\Users\Михаил\PycharmProjects\football_discordBot\venv\lib\site-packages\nextcord\gateway.py", line 365, in from_client
    socket = await client.http.ws_connect(gateway)
  File "C:\Users\Михаил\PycharmProjects\football_discordBot\venv\lib\site-packages\nextcord\http.py", line 250, in ws_connect
    return await self.__session.ws_connect(url, **kwargs)
  File "C:\Users\Михаил\PycharmProjects\football_discordBot\venv\lib\site-packages\aiohttp\client.py", line 779, in _ws_connect
    resp = await self.request(
  File "C:\Users\Михаил\PycharmProjects\football_discordBot\venv\lib\site-packages\aiohttp\client.py", line 536, in _request
    conn = await self._connector.connect(
  File "C:\Users\Михаил\PycharmProjects\football_discordBot\venv\lib\site-packages\aiohttp\connector.py", line 540, in connect
    proto = await self._create_connection(req, traces, timeout)
  File "C:\Users\Михаил\PycharmProjects\football_discordBot\venv\lib\site-packages\aiohttp\connector.py", line 901, in _create_connection
    _, proto = await self._create_direct_connection(req, traces, timeout)
  File "C:\Users\Михаил\PycharmProjects\football_discordBot\venv\lib\site-packages\aiohttp\connector.py", line 1166, in _create_direct_connection
    raise ClientConnectorError(req.connection_key, exc) from exc
aiohttp.client_exceptions.ClientConnectorError: Cannot connect to host gateway-us-east1-d.discord.gg:443 ssl:default [getaddrinfo failed]
[23-01-27 18:59:38] [client.py ERROR] Attempting a reconnect in 825.10s
Traceback (most recent call last):
  File "C:\Users\Михаил\PycharmProjects\football_discordBot\venv\lib\site-packages\aiohttp\connector.py", line 1152, in _create_direct_connection
    hosts = await asyncio.shield(host_resolved)
  File "C:\Users\Михаил\PycharmProjects\football_discordBot\venv\lib\site-packages\aiohttp\connector.py", line 874, in _resolve_host
    addrs = await self._resolver.resolve(host, port, family=self._family)
  File "C:\Users\Михаил\PycharmProjects\football_discordBot\venv\lib\site-packages\aiohttp\resolver.py", line 33, in resolve
    infos = await self._loop.getaddrinfo(
  File "C:\Users\Михаил\AppData\Local\Programs\Python\Python310\lib\asyncio\base_events.py", line 860, in getaddrinfo
    return await self.run_in_executor(
  File "C:\Users\Михаил\AppData\Local\Programs\Python\Python310\lib\concurrent\futures\thread.py", line 58, in run
    result = self.fn(*self.args, **self.kwargs)
  File "C:\Users\Михаил\AppData\Local\Programs\Python\Python310\lib\socket.py", line 955, in getaddrinfo
    for res in _socket.getaddrinfo(host, port, family, type, proto, flags):
socket.gaierror: [Errno 11004] getaddrinfo failed

The above exception was the direct cause of the following exception:

Traceback (most recent call last):
  File "C:\Users\Михаил\PycharmProjects\football_discordBot\venv\lib\site-packages\nextcord\client.py", line 708, in connect
    self.ws = await asyncio.wait_for(coro, timeout=60.0)
  File "C:\Users\Михаил\AppData\Local\Programs\Python\Python310\lib\asyncio\tasks.py", line 445, in wait_for
    return fut.result()
  File "C:\Users\Михаил\PycharmProjects\football_discordBot\venv\lib\site-packages\nextcord\gateway.py", line 365, in from_client
    socket = await client.http.ws_connect(gateway)
  File "C:\Users\Михаил\PycharmProjects\football_discordBot\venv\lib\site-packages\nextcord\http.py", line 250, in ws_connect
    return await self.__session.ws_connect(url, **kwargs)
  File "C:\Users\Михаил\PycharmProjects\football_discordBot\venv\lib\site-packages\aiohttp\client.py", line 779, in _ws_connect
    resp = await self.request(
  File "C:\Users\Михаил\PycharmProjects\football_discordBot\venv\lib\site-packages\aiohttp\client.py", line 536, in _request
    conn = await self._connector.connect(
  File "C:\Users\Михаил\PycharmProjects\football_discordBot\venv\lib\site-packages\aiohttp\connector.py", line 540, in connect
    proto = await self._create_connection(req, traces, timeout)
  File "C:\Users\Михаил\PycharmProjects\football_discordBot\venv\lib\site-packages\aiohttp\connector.py", line 901, in _create_connection
    _, proto = await self._create_direct_connection(req, traces, timeout)
  File "C:\Users\Михаил\PycharmProjects\football_discordBot\venv\lib\site-packages\aiohttp\connector.py", line 1166, in _create_direct_connection
    raise ClientConnectorError(req.connection_key, exc) from exc
aiohttp.client_exceptions.ClientConnectorError: Cannot connect to host gateway-us-east1-d.discord.gg:443 ssl:default [getaddrinfo failed]
[23-01-27 19:13:23] [client.py ERROR] Attempting a reconnect in 68.91s
Traceback (most recent call last):
  File "C:\Users\Михаил\PycharmProjects\football_discordBot\venv\lib\site-packages\aiohttp\connector.py", line 1152, in _create_direct_connection
    hosts = await asyncio.shield(host_resolved)
  File "C:\Users\Михаил\PycharmProjects\football_discordBot\venv\lib\site-packages\aiohttp\connector.py", line 874, in _resolve_host
    addrs = await self._resolver.resolve(host, port, family=self._family)
  File "C:\Users\Михаил\PycharmProjects\football_discordBot\venv\lib\site-packages\aiohttp\resolver.py", line 33, in resolve
    infos = await self._loop.getaddrinfo(
  File "C:\Users\Михаил\AppData\Local\Programs\Python\Python310\lib\asyncio\base_events.py", line 860, in getaddrinfo
    return await self.run_in_executor(
  File "C:\Users\Михаил\AppData\Local\Programs\Python\Python310\lib\concurrent\futures\thread.py", line 58, in run
    result = self.fn(*self.args, **self.kwargs)
  File "C:\Users\Михаил\AppData\Local\Programs\Python\Python310\lib\socket.py", line 955, in getaddrinfo
    for res in _socket.getaddrinfo(host, port, family, type, proto, flags):
socket.gaierror: [Errno 11004] getaddrinfo failed

The above exception was the direct cause of the following exception:

Traceback (most recent call last):
  File "C:\Users\Михаил\PycharmProjects\football_discordBot\venv\lib\site-packages\nextcord\client.py", line 708, in connect
    self.ws = await asyncio.wait_for(coro, timeout=60.0)
  File "C:\Users\Михаил\AppData\Local\Programs\Python\Python310\lib\asyncio\tasks.py", line 445, in wait_for
    return fut.result()
  File "C:\Users\Михаил\PycharmProjects\football_discordBot\venv\lib\site-packages\nextcord\gateway.py", line 365, in from_client
    socket = await client.http.ws_connect(gateway)
  File "C:\Users\Михаил\PycharmProjects\football_discordBot\venv\lib\site-packages\nextcord\http.py", line 250, in ws_connect
    return await self.__session.ws_connect(url, **kwargs)
  File "C:\Users\Михаил\PycharmProjects\football_discordBot\venv\lib\site-packages\aiohttp\client.py", line 779, in _ws_connect
    resp = await self.request(
  File "C:\Users\Михаил\PycharmProjects\football_discordBot\venv\lib\site-packages\aiohttp\client.py", line 536, in _request
    conn = await self._connector.connect(
  File "C:\Users\Михаил\PycharmProjects\football_discordBot\venv\lib\site-packages\aiohttp\connector.py", line 540, in connect
    proto = await self._create_connection(req, traces, timeout)
  File "C:\Users\Михаил\PycharmProjects\football_discordBot\venv\lib\site-packages\aiohttp\connector.py", line 901, in _create_connection
    _, proto = await self._create_direct_connection(req, traces, timeout)
  File "C:\Users\Михаил\PycharmProjects\football_discordBot\venv\lib\site-packages\aiohttp\connector.py", line 1166, in _create_direct_connection
    raise ClientConnectorError(req.connection_key, exc) from exc
aiohttp.client_exceptions.ClientConnectorError: Cannot connect to host gateway-us-east1-d.discord.gg:443 ssl:default [getaddrinfo failed]
[23-01-27 19:14:32] [client.py ERROR] Attempting a reconnect in 797.39s
Traceback (most recent call last):
  File "C:\Users\Михаил\PycharmProjects\football_discordBot\venv\lib\site-packages\aiohttp\connector.py", line 1152, in _create_direct_connection
    hosts = await asyncio.shield(host_resolved)
  File "C:\Users\Михаил\PycharmProjects\football_discordBot\venv\lib\site-packages\aiohttp\connector.py", line 874, in _resolve_host
    addrs = await self._resolver.resolve(host, port, family=self._family)
  File "C:\Users\Михаил\PycharmProjects\football_discordBot\venv\lib\site-packages\aiohttp\resolver.py", line 33, in resolve
    infos = await self._loop.getaddrinfo(
  File "C:\Users\Михаил\AppData\Local\Programs\Python\Python310\lib\asyncio\base_events.py", line 860, in getaddrinfo
    return await self.run_in_executor(
  File "C:\Users\Михаил\AppData\Local\Programs\Python\Python310\lib\concurrent\futures\thread.py", line 58, in run
    result = self.fn(*self.args, **self.kwargs)
  File "C:\Users\Михаил\AppData\Local\Programs\Python\Python310\lib\socket.py", line 955, in getaddrinfo
    for res in _socket.getaddrinfo(host, port, family, type, proto, flags):
socket.gaierror: [Errno 11004] getaddrinfo failed

The above exception was the direct cause of the following exception:

Traceback (most recent call last):
  File "C:\Users\Михаил\PycharmProjects\football_discordBot\venv\lib\site-packages\nextcord\client.py", line 708, in connect
    self.ws = await asyncio.wait_for(coro, timeout=60.0)
  File "C:\Users\Михаил\AppData\Local\Programs\Python\Python310\lib\asyncio\tasks.py", line 445, in wait_for
    return fut.result()
  File "C:\Users\Михаил\PycharmProjects\football_discordBot\venv\lib\site-packages\nextcord\gateway.py", line 365, in from_client
    socket = await client.http.ws_connect(gateway)
  File "C:\Users\Михаил\PycharmProjects\football_discordBot\venv\lib\site-packages\nextcord\http.py", line 250, in ws_connect
    return await self.__session.ws_connect(url, **kwargs)
  File "C:\Users\Михаил\PycharmProjects\football_discordBot\venv\lib\site-packages\aiohttp\client.py", line 779, in _ws_connect
    resp = await self.request(
  File "C:\Users\Михаил\PycharmProjects\football_discordBot\venv\lib\site-packages\aiohttp\client.py", line 536, in _request
    conn = await self._connector.connect(
  File "C:\Users\Михаил\PycharmProjects\football_discordBot\venv\lib\site-packages\aiohttp\connector.py", line 540, in connect
    proto = await self._create_connection(req, traces, timeout)
  File "C:\Users\Михаил\PycharmProjects\football_discordBot\venv\lib\site-packages\aiohttp\connector.py", line 901, in _create_connection
    _, proto = await self._create_direct_connection(req, traces, timeout)
  File "C:\Users\Михаил\PycharmProjects\football_discordBot\venv\lib\site-packages\aiohttp\connector.py", line 1166, in _create_direct_connection
    raise ClientConnectorError(req.connection_key, exc) from exc
aiohttp.client_exceptions.ClientConnectorError: Cannot connect to host gateway-us-east1-d.discord.gg:443 ssl:default [getaddrinfo failed]
[23-01-27 20:22:44] [client.py ERROR] Attempting a reconnect in 0.92s
Traceback (most recent call last):
  File "C:\Users\Михаил\PycharmProjects\football_discordBot\venv\lib\site-packages\aiohttp\connector.py", line 1152, in _create_direct_connection
    hosts = await asyncio.shield(host_resolved)
  File "C:\Users\Михаил\PycharmProjects\football_discordBot\venv\lib\site-packages\aiohttp\connector.py", line 874, in _resolve_host
    addrs = await self._resolver.resolve(host, port, family=self._family)
  File "C:\Users\Михаил\PycharmProjects\football_discordBot\venv\lib\site-packages\aiohttp\resolver.py", line 33, in resolve
    infos = await self._loop.getaddrinfo(
  File "C:\Users\Михаил\AppData\Local\Programs\Python\Python310\lib\asyncio\base_events.py", line 860, in getaddrinfo
    return await self.run_in_executor(
  File "C:\Users\Михаил\AppData\Local\Programs\Python\Python310\lib\concurrent\futures\thread.py", line 58, in run
    result = self.fn(*self.args, **self.kwargs)
  File "C:\Users\Михаил\AppData\Local\Programs\Python\Python310\lib\socket.py", line 955, in getaddrinfo
    for res in _socket.getaddrinfo(host, port, family, type, proto, flags):
socket.gaierror: [Errno 11004] getaddrinfo failed

The above exception was the direct cause of the following exception:

Traceback (most recent call last):
  File "C:\Users\Михаил\PycharmProjects\football_discordBot\venv\lib\site-packages\nextcord\client.py", line 708, in connect
    self.ws = await asyncio.wait_for(coro, timeout=60.0)
  File "C:\Users\Михаил\AppData\Local\Programs\Python\Python310\lib\asyncio\tasks.py", line 445, in wait_for
    return fut.result()
  File "C:\Users\Михаил\PycharmProjects\football_discordBot\venv\lib\site-packages\nextcord\gateway.py", line 365, in from_client
    socket = await client.http.ws_connect(gateway)
  File "C:\Users\Михаил\PycharmProjects\football_discordBot\venv\lib\site-packages\nextcord\http.py", line 250, in ws_connect
    return await self.__session.ws_connect(url, **kwargs)
  File "C:\Users\Михаил\PycharmProjects\football_discordBot\venv\lib\site-packages\aiohttp\client.py", line 779, in _ws_connect
    resp = await self.request(
  File "C:\Users\Михаил\PycharmProjects\football_discordBot\venv\lib\site-packages\aiohttp\client.py", line 536, in _request
    conn = await self._connector.connect(
  File "C:\Users\Михаил\PycharmProjects\football_discordBot\venv\lib\site-packages\aiohttp\connector.py", line 540, in connect
    proto = await self._create_connection(req, traces, timeout)
  File "C:\Users\Михаил\PycharmProjects\football_discordBot\venv\lib\site-packages\aiohttp\connector.py", line 901, in _create_connection
    _, proto = await self._create_direct_connection(req, traces, timeout)
  File "C:\Users\Михаил\PycharmProjects\football_discordBot\venv\lib\site-packages\aiohttp\connector.py", line 1166, in _create_direct_connection
    raise ClientConnectorError(req.connection_key, exc) from exc
aiohttp.client_exceptions.ClientConnectorError: Cannot connect to host gateway-us-east1-d.discord.gg:443 ssl:default [getaddrinfo failed]
[23-01-27 20:22:45] [client.py ERROR] Attempting a reconnect in 2.29s
Traceback (most recent call last):
  File "C:\Users\Михаил\PycharmProjects\football_discordBot\venv\lib\site-packages\aiohttp\connector.py", line 1152, in _create_direct_connection
    hosts = await asyncio.shield(host_resolved)
  File "C:\Users\Михаил\PycharmProjects\football_discordBot\venv\lib\site-packages\aiohttp\connector.py", line 874, in _resolve_host
    addrs = await self._resolver.resolve(host, port, family=self._family)
  File "C:\Users\Михаил\PycharmProjects\football_discordBot\venv\lib\site-packages\aiohttp\resolver.py", line 33, in resolve
    infos = await self._loop.getaddrinfo(
  File "C:\Users\Михаил\AppData\Local\Programs\Python\Python310\lib\asyncio\base_events.py", line 860, in getaddrinfo
    return await self.run_in_executor(
  File "C:\Users\Михаил\AppData\Local\Programs\Python\Python310\lib\concurrent\futures\thread.py", line 58, in run
    result = self.fn(*self.args, **self.kwargs)
  File "C:\Users\Михаил\AppData\Local\Programs\Python\Python310\lib\socket.py", line 955, in getaddrinfo
    for res in _socket.getaddrinfo(host, port, family, type, proto, flags):
socket.gaierror: [Errno 11004] getaddrinfo failed

The above exception was the direct cause of the following exception:

Traceback (most recent call last):
  File "C:\Users\Михаил\PycharmProjects\football_discordBot\venv\lib\site-packages\nextcord\client.py", line 708, in connect
    self.ws = await asyncio.wait_for(coro, timeout=60.0)
  File "C:\Users\Михаил\AppData\Local\Programs\Python\Python310\lib\asyncio\tasks.py", line 445, in wait_for
    return fut.result()
  File "C:\Users\Михаил\PycharmProjects\football_discordBot\venv\lib\site-packages\nextcord\gateway.py", line 365, in from_client
    socket = await client.http.ws_connect(gateway)
  File "C:\Users\Михаил\PycharmProjects\football_discordBot\venv\lib\site-packages\nextcord\http.py", line 250, in ws_connect
    return await self.__session.ws_connect(url, **kwargs)
  File "C:\Users\Михаил\PycharmProjects\football_discordBot\venv\lib\site-packages\aiohttp\client.py", line 779, in _ws_connect
    resp = await self.request(
  File "C:\Users\Михаил\PycharmProjects\football_discordBot\venv\lib\site-packages\aiohttp\client.py", line 536, in _request
    conn = await self._connector.connect(
  File "C:\Users\Михаил\PycharmProjects\football_discordBot\venv\lib\site-packages\aiohttp\connector.py", line 540, in connect
    proto = await self._create_connection(req, traces, timeout)
  File "C:\Users\Михаил\PycharmProjects\football_discordBot\venv\lib\site-packages\aiohttp\connector.py", line 901, in _create_connection
    _, proto = await self._create_direct_connection(req, traces, timeout)
  File "C:\Users\Михаил\PycharmProjects\football_discordBot\venv\lib\site-packages\aiohttp\connector.py", line 1166, in _create_direct_connection
    raise ClientConnectorError(req.connection_key, exc) from exc
aiohttp.client_exceptions.ClientConnectorError: Cannot connect to host gateway-us-east1-d.discord.gg:443 ssl:default [getaddrinfo failed]
[23-01-27 20:22:47] [client.py ERROR] Attempting a reconnect in 2.78s
Traceback (most recent call last):
  File "C:\Users\Михаил\PycharmProjects\football_discordBot\venv\lib\site-packages\aiohttp\connector.py", line 1152, in _create_direct_connection
    hosts = await asyncio.shield(host_resolved)
  File "C:\Users\Михаил\PycharmProjects\football_discordBot\venv\lib\site-packages\aiohttp\connector.py", line 874, in _resolve_host
    addrs = await self._resolver.resolve(host, port, family=self._family)
  File "C:\Users\Михаил\PycharmProjects\football_discordBot\venv\lib\site-packages\aiohttp\resolver.py", line 33, in resolve
    infos = await self._loop.getaddrinfo(
  File "C:\Users\Михаил\AppData\Local\Programs\Python\Python310\lib\asyncio\base_events.py", line 860, in getaddrinfo
    return await self.run_in_executor(
  File "C:\Users\Михаил\AppData\Local\Programs\Python\Python310\lib\concurrent\futures\thread.py", line 58, in run
    result = self.fn(*self.args, **self.kwargs)
  File "C:\Users\Михаил\AppData\Local\Programs\Python\Python310\lib\socket.py", line 955, in getaddrinfo
    for res in _socket.getaddrinfo(host, port, family, type, proto, flags):
socket.gaierror: [Errno 11004] getaddrinfo failed

The above exception was the direct cause of the following exception:

Traceback (most recent call last):
  File "C:\Users\Михаил\PycharmProjects\football_discordBot\venv\lib\site-packages\nextcord\client.py", line 708, in connect
    self.ws = await asyncio.wait_for(coro, timeout=60.0)
  File "C:\Users\Михаил\AppData\Local\Programs\Python\Python310\lib\asyncio\tasks.py", line 445, in wait_for
    return fut.result()
  File "C:\Users\Михаил\PycharmProjects\football_discordBot\venv\lib\site-packages\nextcord\gateway.py", line 365, in from_client
    socket = await client.http.ws_connect(gateway)
  File "C:\Users\Михаил\PycharmProjects\football_discordBot\venv\lib\site-packages\nextcord\http.py", line 250, in ws_connect
    return await self.__session.ws_connect(url, **kwargs)
  File "C:\Users\Михаил\PycharmProjects\football_discordBot\venv\lib\site-packages\aiohttp\client.py", line 779, in _ws_connect
    resp = await self.request(
  File "C:\Users\Михаил\PycharmProjects\football_discordBot\venv\lib\site-packages\aiohttp\client.py", line 536, in _request
    conn = await self._connector.connect(
  File "C:\Users\Михаил\PycharmProjects\football_discordBot\venv\lib\site-packages\aiohttp\connector.py", line 540, in connect
    proto = await self._create_connection(req, traces, timeout)
  File "C:\Users\Михаил\PycharmProjects\football_discordBot\venv\lib\site-packages\aiohttp\connector.py", line 901, in _create_connection
    _, proto = await self._create_direct_connection(req, traces, timeout)
  File "C:\Users\Михаил\PycharmProjects\football_discordBot\venv\lib\site-packages\aiohttp\connector.py", line 1166, in _create_direct_connection
    raise ClientConnectorError(req.connection_key, exc) from exc
aiohttp.client_exceptions.ClientConnectorError: Cannot connect to host gateway-us-east1-d.discord.gg:443 ssl:default [getaddrinfo failed]
[23-01-27 20:22:50] [client.py ERROR] Attempting a reconnect in 5.96s
Traceback (most recent call last):
  File "C:\Users\Михаил\PycharmProjects\football_discordBot\venv\lib\site-packages\aiohttp\connector.py", line 1152, in _create_direct_connection
    hosts = await asyncio.shield(host_resolved)
  File "C:\Users\Михаил\PycharmProjects\football_discordBot\venv\lib\site-packages\aiohttp\connector.py", line 874, in _resolve_host
    addrs = await self._resolver.resolve(host, port, family=self._family)
  File "C:\Users\Михаил\PycharmProjects\football_discordBot\venv\lib\site-packages\aiohttp\resolver.py", line 33, in resolve
    infos = await self._loop.getaddrinfo(
  File "C:\Users\Михаил\AppData\Local\Programs\Python\Python310\lib\asyncio\base_events.py", line 860, in getaddrinfo
    return await self.run_in_executor(
  File "C:\Users\Михаил\AppData\Local\Programs\Python\Python310\lib\concurrent\futures\thread.py", line 58, in run
    result = self.fn(*self.args, **self.kwargs)
  File "C:\Users\Михаил\AppData\Local\Programs\Python\Python310\lib\socket.py", line 955, in getaddrinfo
    for res in _socket.getaddrinfo(host, port, family, type, proto, flags):
socket.gaierror: [Errno 11004] getaddrinfo failed

The above exception was the direct cause of the following exception:

Traceback (most recent call last):
  File "C:\Users\Михаил\PycharmProjects\football_discordBot\venv\lib\site-packages\nextcord\client.py", line 708, in connect
    self.ws = await asyncio.wait_for(coro, timeout=60.0)
  File "C:\Users\Михаил\AppData\Local\Programs\Python\Python310\lib\asyncio\tasks.py", line 445, in wait_for
    return fut.result()
  File "C:\Users\Михаил\PycharmProjects\football_discordBot\venv\lib\site-packages\nextcord\gateway.py", line 365, in from_client
    socket = await client.http.ws_connect(gateway)
  File "C:\Users\Михаил\PycharmProjects\football_discordBot\venv\lib\site-packages\nextcord\http.py", line 250, in ws_connect
    return await self.__session.ws_connect(url, **kwargs)
  File "C:\Users\Михаил\PycharmProjects\football_discordBot\venv\lib\site-packages\aiohttp\client.py", line 779, in _ws_connect
    resp = await self.request(
  File "C:\Users\Михаил\PycharmProjects\football_discordBot\venv\lib\site-packages\aiohttp\client.py", line 536, in _request
    conn = await self._connector.connect(
  File "C:\Users\Михаил\PycharmProjects\football_discordBot\venv\lib\site-packages\aiohttp\connector.py", line 540, in connect
    proto = await self._create_connection(req, traces, timeout)
  File "C:\Users\Михаил\PycharmProjects\football_discordBot\venv\lib\site-packages\aiohttp\connector.py", line 901, in _create_connection
    _, proto = await self._create_direct_connection(req, traces, timeout)
  File "C:\Users\Михаил\PycharmProjects\football_discordBot\venv\lib\site-packages\aiohttp\connector.py", line 1166, in _create_direct_connection
    raise ClientConnectorError(req.connection_key, exc) from exc
aiohttp.client_exceptions.ClientConnectorError: Cannot connect to host gateway-us-east1-d.discord.gg:443 ssl:default [getaddrinfo failed]
[23-01-27 20:22:56] [client.py ERROR] Attempting a reconnect in 9.74s
Traceback (most recent call last):
  File "C:\Users\Михаил\PycharmProjects\football_discordBot\venv\lib\site-packages\aiohttp\connector.py", line 1152, in _create_direct_connection
    hosts = await asyncio.shield(host_resolved)
  File "C:\Users\Михаил\PycharmProjects\football_discordBot\venv\lib\site-packages\aiohttp\connector.py", line 874, in _resolve_host
    addrs = await self._resolver.resolve(host, port, family=self._family)
  File "C:\Users\Михаил\PycharmProjects\football_discordBot\venv\lib\site-packages\aiohttp\resolver.py", line 33, in resolve
    infos = await self._loop.getaddrinfo(
  File "C:\Users\Михаил\AppData\Local\Programs\Python\Python310\lib\asyncio\base_events.py", line 860, in getaddrinfo
    return await self.run_in_executor(
  File "C:\Users\Михаил\AppData\Local\Programs\Python\Python310\lib\concurrent\futures\thread.py", line 58, in run
    result = self.fn(*self.args, **self.kwargs)
  File "C:\Users\Михаил\AppData\Local\Programs\Python\Python310\lib\socket.py", line 955, in getaddrinfo
    for res in _socket.getaddrinfo(host, port, family, type, proto, flags):
socket.gaierror: [Errno 11004] getaddrinfo failed

The above exception was the direct cause of the following exception:

Traceback (most recent call last):
  File "C:\Users\Михаил\PycharmProjects\football_discordBot\venv\lib\site-packages\nextcord\client.py", line 708, in connect
    self.ws = await asyncio.wait_for(coro, timeout=60.0)
  File "C:\Users\Михаил\AppData\Local\Programs\Python\Python310\lib\asyncio\tasks.py", line 445, in wait_for
    return fut.result()
  File "C:\Users\Михаил\PycharmProjects\football_discordBot\venv\lib\site-packages\nextcord\gateway.py", line 365, in from_client
    socket = await client.http.ws_connect(gateway)
  File "C:\Users\Михаил\PycharmProjects\football_discordBot\venv\lib\site-packages\nextcord\http.py", line 250, in ws_connect
    return await self.__session.ws_connect(url, **kwargs)
  File "C:\Users\Михаил\PycharmProjects\football_discordBot\venv\lib\site-packages\aiohttp\client.py", line 779, in _ws_connect
    resp = await self.request(
  File "C:\Users\Михаил\PycharmProjects\football_discordBot\venv\lib\site-packages\aiohttp\client.py", line 536, in _request
    conn = await self._connector.connect(
  File "C:\Users\Михаил\PycharmProjects\football_discordBot\venv\lib\site-packages\aiohttp\connector.py", line 540, in connect
    proto = await self._create_connection(req, traces, timeout)
  File "C:\Users\Михаил\PycharmProjects\football_discordBot\venv\lib\site-packages\aiohttp\connector.py", line 901, in _create_connection
    _, proto = await self._create_direct_connection(req, traces, timeout)
  File "C:\Users\Михаил\PycharmProjects\football_discordBot\venv\lib\site-packages\aiohttp\connector.py", line 1166, in _create_direct_connection
    raise ClientConnectorError(req.connection_key, exc) from exc
aiohttp.client_exceptions.ClientConnectorError: Cannot connect to host gateway-us-east1-d.discord.gg:443 ssl:default [getaddrinfo failed]
[23-01-27 20:23:05] [client.py ERROR] Attempting a reconnect in 40.76s
Traceback (most recent call last):
  File "C:\Users\Михаил\PycharmProjects\football_discordBot\venv\lib\site-packages\aiohttp\connector.py", line 1152, in _create_direct_connection
    hosts = await asyncio.shield(host_resolved)
  File "C:\Users\Михаил\PycharmProjects\football_discordBot\venv\lib\site-packages\aiohttp\connector.py", line 874, in _resolve_host
    addrs = await self._resolver.resolve(host, port, family=self._family)
  File "C:\Users\Михаил\PycharmProjects\football_discordBot\venv\lib\site-packages\aiohttp\resolver.py", line 33, in resolve
    infos = await self._loop.getaddrinfo(
  File "C:\Users\Михаил\AppData\Local\Programs\Python\Python310\lib\asyncio\base_events.py", line 860, in getaddrinfo
    return await self.run_in_executor(
  File "C:\Users\Михаил\AppData\Local\Programs\Python\Python310\lib\concurrent\futures\thread.py", line 58, in run
    result = self.fn(*self.args, **self.kwargs)
  File "C:\Users\Михаил\AppData\Local\Programs\Python\Python310\lib\socket.py", line 955, in getaddrinfo
    for res in _socket.getaddrinfo(host, port, family, type, proto, flags):
socket.gaierror: [Errno 11004] getaddrinfo failed

The above exception was the direct cause of the following exception:

Traceback (most recent call last):
  File "C:\Users\Михаил\PycharmProjects\football_discordBot\venv\lib\site-packages\nextcord\client.py", line 708, in connect
    self.ws = await asyncio.wait_for(coro, timeout=60.0)
  File "C:\Users\Михаил\AppData\Local\Programs\Python\Python310\lib\asyncio\tasks.py", line 445, in wait_for
    return fut.result()
  File "C:\Users\Михаил\PycharmProjects\football_discordBot\venv\lib\site-packages\nextcord\gateway.py", line 365, in from_client
    socket = await client.http.ws_connect(gateway)
  File "C:\Users\Михаил\PycharmProjects\football_discordBot\venv\lib\site-packages\nextcord\http.py", line 250, in ws_connect
    return await self.__session.ws_connect(url, **kwargs)
  File "C:\Users\Михаил\PycharmProjects\football_discordBot\venv\lib\site-packages\aiohttp\client.py", line 779, in _ws_connect
    resp = await self.request(
  File "C:\Users\Михаил\PycharmProjects\football_discordBot\venv\lib\site-packages\aiohttp\client.py", line 536, in _request
    conn = await self._connector.connect(
  File "C:\Users\Михаил\PycharmProjects\football_discordBot\venv\lib\site-packages\aiohttp\connector.py", line 540, in connect
    proto = await self._create_connection(req, traces, timeout)
  File "C:\Users\Михаил\PycharmProjects\football_discordBot\venv\lib\site-packages\aiohttp\connector.py", line 901, in _create_connection
    _, proto = await self._create_direct_connection(req, traces, timeout)
  File "C:\Users\Михаил\PycharmProjects\football_discordBot\venv\lib\site-packages\aiohttp\connector.py", line 1166, in _create_direct_connection
    raise ClientConnectorError(req.connection_key, exc) from exc
aiohttp.client_exceptions.ClientConnectorError: Cannot connect to host gateway-us-east1-d.discord.gg:443 ssl:default [getaddrinfo failed]
[23-01-27 20:26:56] [client.py ERROR] Attempting a reconnect in 87.89s
Traceback (most recent call last):
  File "C:\Users\Михаил\PycharmProjects\football_discordBot\venv\lib\site-packages\aiohttp\connector.py", line 1152, in _create_direct_connection
    hosts = await asyncio.shield(host_resolved)
  File "C:\Users\Михаил\PycharmProjects\football_discordBot\venv\lib\site-packages\aiohttp\connector.py", line 874, in _resolve_host
    addrs = await self._resolver.resolve(host, port, family=self._family)
  File "C:\Users\Михаил\PycharmProjects\football_discordBot\venv\lib\site-packages\aiohttp\resolver.py", line 33, in resolve
    infos = await self._loop.getaddrinfo(
  File "C:\Users\Михаил\AppData\Local\Programs\Python\Python310\lib\asyncio\base_events.py", line 860, in getaddrinfo
    return await self.run_in_executor(
  File "C:\Users\Михаил\AppData\Local\Programs\Python\Python310\lib\concurrent\futures\thread.py", line 58, in run
    result = self.fn(*self.args, **self.kwargs)
  File "C:\Users\Михаил\AppData\Local\Programs\Python\Python310\lib\socket.py", line 955, in getaddrinfo
    for res in _socket.getaddrinfo(host, port, family, type, proto, flags):
socket.gaierror: [Errno 11004] getaddrinfo failed

The above exception was the direct cause of the following exception:

Traceback (most recent call last):
  File "C:\Users\Михаил\PycharmProjects\football_discordBot\venv\lib\site-packages\nextcord\client.py", line 708, in connect
    self.ws = await asyncio.wait_for(coro, timeout=60.0)
  File "C:\Users\Михаил\AppData\Local\Programs\Python\Python310\lib\asyncio\tasks.py", line 445, in wait_for
    return fut.result()
  File "C:\Users\Михаил\PycharmProjects\football_discordBot\venv\lib\site-packages\nextcord\gateway.py", line 365, in from_client
    socket = await client.http.ws_connect(gateway)
  File "C:\Users\Михаил\PycharmProjects\football_discordBot\venv\lib\site-packages\nextcord\http.py", line 250, in ws_connect
    return await self.__session.ws_connect(url, **kwargs)
  File "C:\Users\Михаил\PycharmProjects\football_discordBot\venv\lib\site-packages\aiohttp\client.py", line 779, in _ws_connect
    resp = await self.request(
  File "C:\Users\Михаил\PycharmProjects\football_discordBot\venv\lib\site-packages\aiohttp\client.py", line 536, in _request
    conn = await self._connector.connect(
  File "C:\Users\Михаил\PycharmProjects\football_discordBot\venv\lib\site-packages\aiohttp\connector.py", line 540, in connect
    proto = await self._create_connection(req, traces, timeout)
  File "C:\Users\Михаил\PycharmProjects\football_discordBot\venv\lib\site-packages\aiohttp\connector.py", line 901, in _create_connection
    _, proto = await self._create_direct_connection(req, traces, timeout)
  File "C:\Users\Михаил\PycharmProjects\football_discordBot\venv\lib\site-packages\aiohttp\connector.py", line 1166, in _create_direct_connection
    raise ClientConnectorError(req.connection_key, exc) from exc
aiohttp.client_exceptions.ClientConnectorError: Cannot connect to host gateway-us-east1-b.discord.gg:443 ssl:default [getaddrinfo failed]
[23-01-27 20:28:24] [client.py ERROR] Attempting a reconnect in 52.66s
Traceback (most recent call last):
  File "C:\Users\Михаил\PycharmProjects\football_discordBot\venv\lib\site-packages\aiohttp\connector.py", line 1152, in _create_direct_connection
    hosts = await asyncio.shield(host_resolved)
  File "C:\Users\Михаил\PycharmProjects\football_discordBot\venv\lib\site-packages\aiohttp\connector.py", line 874, in _resolve_host
    addrs = await self._resolver.resolve(host, port, family=self._family)
  File "C:\Users\Михаил\PycharmProjects\football_discordBot\venv\lib\site-packages\aiohttp\resolver.py", line 33, in resolve
    infos = await self._loop.getaddrinfo(
  File "C:\Users\Михаил\AppData\Local\Programs\Python\Python310\lib\asyncio\base_events.py", line 860, in getaddrinfo
    return await self.run_in_executor(
  File "C:\Users\Михаил\AppData\Local\Programs\Python\Python310\lib\concurrent\futures\thread.py", line 58, in run
    result = self.fn(*self.args, **self.kwargs)
  File "C:\Users\Михаил\AppData\Local\Programs\Python\Python310\lib\socket.py", line 955, in getaddrinfo
    for res in _socket.getaddrinfo(host, port, family, type, proto, flags):
socket.gaierror: [Errno 11004] getaddrinfo failed

The above exception was the direct cause of the following exception:

Traceback (most recent call last):
  File "C:\Users\Михаил\PycharmProjects\football_discordBot\venv\lib\site-packages\nextcord\client.py", line 708, in connect
    self.ws = await asyncio.wait_for(coro, timeout=60.0)
  File "C:\Users\Михаил\AppData\Local\Programs\Python\Python310\lib\asyncio\tasks.py", line 445, in wait_for
    return fut.result()
  File "C:\Users\Михаил\PycharmProjects\football_discordBot\venv\lib\site-packages\nextcord\gateway.py", line 365, in from_client
    socket = await client.http.ws_connect(gateway)
  File "C:\Users\Михаил\PycharmProjects\football_discordBot\venv\lib\site-packages\nextcord\http.py", line 250, in ws_connect
    return await self.__session.ws_connect(url, **kwargs)
  File "C:\Users\Михаил\PycharmProjects\football_discordBot\venv\lib\site-packages\aiohttp\client.py", line 779, in _ws_connect
    resp = await self.request(
  File "C:\Users\Михаил\PycharmProjects\football_discordBot\venv\lib\site-packages\aiohttp\client.py", line 536, in _request
    conn = await self._connector.connect(
  File "C:\Users\Михаил\PycharmProjects\football_discordBot\venv\lib\site-packages\aiohttp\connector.py", line 540, in connect
    proto = await self._create_connection(req, traces, timeout)
  File "C:\Users\Михаил\PycharmProjects\football_discordBot\venv\lib\site-packages\aiohttp\connector.py", line 901, in _create_connection
    _, proto = await self._create_direct_connection(req, traces, timeout)
  File "C:\Users\Михаил\PycharmProjects\football_discordBot\venv\lib\site-packages\aiohttp\connector.py", line 1166, in _create_direct_connection
    raise ClientConnectorError(req.connection_key, exc) from exc
aiohttp.client_exceptions.ClientConnectorError: Cannot connect to host gateway-us-east1-b.discord.gg:443 ssl:default [getaddrinfo failed]
[23-01-27 20:29:16] [client.py ERROR] Attempting a reconnect in 273.56s
Traceback (most recent call last):
  File "C:\Users\Михаил\PycharmProjects\football_discordBot\venv\lib\site-packages\aiohttp\connector.py", line 1152, in _create_direct_connection
    hosts = await asyncio.shield(host_resolved)
  File "C:\Users\Михаил\PycharmProjects\football_discordBot\venv\lib\site-packages\aiohttp\connector.py", line 874, in _resolve_host
    addrs = await self._resolver.resolve(host, port, family=self._family)
  File "C:\Users\Михаил\PycharmProjects\football_discordBot\venv\lib\site-packages\aiohttp\resolver.py", line 33, in resolve
    infos = await self._loop.getaddrinfo(
  File "C:\Users\Михаил\AppData\Local\Programs\Python\Python310\lib\asyncio\base_events.py", line 860, in getaddrinfo
    return await self.run_in_executor(
  File "C:\Users\Михаил\AppData\Local\Programs\Python\Python310\lib\concurrent\futures\thread.py", line 58, in run
    result = self.fn(*self.args, **self.kwargs)
  File "C:\Users\Михаил\AppData\Local\Programs\Python\Python310\lib\socket.py", line 955, in getaddrinfo
    for res in _socket.getaddrinfo(host, port, family, type, proto, flags):
socket.gaierror: [Errno 11004] getaddrinfo failed

The above exception was the direct cause of the following exception:

Traceback (most recent call last):
  File "C:\Users\Михаил\PycharmProjects\football_discordBot\venv\lib\site-packages\nextcord\client.py", line 708, in connect
    self.ws = await asyncio.wait_for(coro, timeout=60.0)
  File "C:\Users\Михаил\AppData\Local\Programs\Python\Python310\lib\asyncio\tasks.py", line 445, in wait_for
    return fut.result()
  File "C:\Users\Михаил\PycharmProjects\football_discordBot\venv\lib\site-packages\nextcord\gateway.py", line 365, in from_client
    socket = await client.http.ws_connect(gateway)
  File "C:\Users\Михаил\PycharmProjects\football_discordBot\venv\lib\site-packages\nextcord\http.py", line 250, in ws_connect
    return await self.__session.ws_connect(url, **kwargs)
  File "C:\Users\Михаил\PycharmProjects\football_discordBot\venv\lib\site-packages\aiohttp\client.py", line 779, in _ws_connect
    resp = await self.request(
  File "C:\Users\Михаил\PycharmProjects\football_discordBot\venv\lib\site-packages\aiohttp\client.py", line 536, in _request
    conn = await self._connector.connect(
  File "C:\Users\Михаил\PycharmProjects\football_discordBot\venv\lib\site-packages\aiohttp\connector.py", line 540, in connect
    proto = await self._create_connection(req, traces, timeout)
  File "C:\Users\Михаил\PycharmProjects\football_discordBot\venv\lib\site-packages\aiohttp\connector.py", line 901, in _create_connection
    _, proto = await self._create_direct_connection(req, traces, timeout)
  File "C:\Users\Михаил\PycharmProjects\football_discordBot\venv\lib\site-packages\aiohttp\connector.py", line 1166, in _create_direct_connection
    raise ClientConnectorError(req.connection_key, exc) from exc
aiohttp.client_exceptions.ClientConnectorError: Cannot connect to host gateway-us-east1-b.discord.gg:443 ssl:default [getaddrinfo failed]
[23-01-27 20:33:50] [client.py ERROR] Attempting a reconnect in 735.34s
Traceback (most recent call last):
  File "C:\Users\Михаил\PycharmProjects\football_discordBot\venv\lib\site-packages\aiohttp\connector.py", line 1152, in _create_direct_connection
    hosts = await asyncio.shield(host_resolved)
  File "C:\Users\Михаил\PycharmProjects\football_discordBot\venv\lib\site-packages\aiohttp\connector.py", line 874, in _resolve_host
    addrs = await self._resolver.resolve(host, port, family=self._family)
  File "C:\Users\Михаил\PycharmProjects\football_discordBot\venv\lib\site-packages\aiohttp\resolver.py", line 33, in resolve
    infos = await self._loop.getaddrinfo(
  File "C:\Users\Михаил\AppData\Local\Programs\Python\Python310\lib\asyncio\base_events.py", line 860, in getaddrinfo
    return await self.run_in_executor(
  File "C:\Users\Михаил\AppData\Local\Programs\Python\Python310\lib\concurrent\futures\thread.py", line 58, in run
    result = self.fn(*self.args, **self.kwargs)
  File "C:\Users\Михаил\AppData\Local\Programs\Python\Python310\lib\socket.py", line 955, in getaddrinfo
    for res in _socket.getaddrinfo(host, port, family, type, proto, flags):
socket.gaierror: [Errno 11004] getaddrinfo failed

The above exception was the direct cause of the following exception:

Traceback (most recent call last):
  File "C:\Users\Михаил\PycharmProjects\football_discordBot\venv\lib\site-packages\nextcord\client.py", line 708, in connect
    self.ws = await asyncio.wait_for(coro, timeout=60.0)
  File "C:\Users\Михаил\AppData\Local\Programs\Python\Python310\lib\asyncio\tasks.py", line 445, in wait_for
    return fut.result()
  File "C:\Users\Михаил\PycharmProjects\football_discordBot\venv\lib\site-packages\nextcord\gateway.py", line 365, in from_client
    socket = await client.http.ws_connect(gateway)
  File "C:\Users\Михаил\PycharmProjects\football_discordBot\venv\lib\site-packages\nextcord\http.py", line 250, in ws_connect
    return await self.__session.ws_connect(url, **kwargs)
  File "C:\Users\Михаил\PycharmProjects\football_discordBot\venv\lib\site-packages\aiohttp\client.py", line 779, in _ws_connect
    resp = await self.request(
  File "C:\Users\Михаил\PycharmProjects\football_discordBot\venv\lib\site-packages\aiohttp\client.py", line 536, in _request
    conn = await self._connector.connect(
  File "C:\Users\Михаил\PycharmProjects\football_discordBot\venv\lib\site-packages\aiohttp\connector.py", line 540, in connect
    proto = await self._create_connection(req, traces, timeout)
  File "C:\Users\Михаил\PycharmProjects\football_discordBot\venv\lib\site-packages\aiohttp\connector.py", line 901, in _create_connection
    _, proto = await self._create_direct_connection(req, traces, timeout)
  File "C:\Users\Михаил\PycharmProjects\football_discordBot\venv\lib\site-packages\aiohttp\connector.py", line 1166, in _create_direct_connection
    raise ClientConnectorError(req.connection_key, exc) from exc
aiohttp.client_exceptions.ClientConnectorError: Cannot connect to host gateway-us-east1-b.discord.gg:443 ssl:default [getaddrinfo failed]
